{"ts":1778927760427,"data":"{\"topic\":\"orderbook.1000.XRPUSDT\",\"type\":\"delta\",\"ts\":1778927760303,\"data\":{\"s\":\"XRPUSDT\",\"b\":[[\"1.4026\",\"56232.4\"],[\"1.4025\",\"46502.9\"],[\"1.4021\",\"36939.6\"],[\"1.4016\",\"73180.3\"],[\"1.3882\",\"1418.6\"],[\"1.3866\",\"20037.8\"]],\"a\":[[\"1.4044\",\"23713.1\"],[\"1.4046\",\"62780.5\"],[\"1.4219\",\"19362.9\"],[\"1.4236\",\"1019.2\"],[\"1.4326\",\"36014.6\"],[\"1.4328\",\"142.5\"]],\"u\":9831587,\"seq\":241267353438},\"cts\":1778927760299}"}
{"ts":1778927760628,"data":"{\"topic\":\"orderbook.1000.XRPUSDT\",\"type\":\"delta\",\"ts\":1778927760504,\"data\":{\"s\":\"XRPUSDT\",\"b\":[[\"1.4029\",\"40996.2\"],[\"1.4026\",\"54899.4\"],[\"1.4025\",\"47835.0\"],[\"1.4021\",\"36928.8\"],[\"1.4012\",\"239717.1\"],[\"1.4009\",\"53390.0\"],[\"1.3898\",\"513.0\"],[\"1.3896\",\"5812.8\"],[\"1.3883\",\"2254.4\"],[\"1.3880\",\"8156.8\"],[\"1.3808\",\"11644.6\"],[\"1.3807\",\"275.1\"]],\"a\":[[\"1.4044\",\"21973.1\"],[\"1.4051\",\"72990.7\"],[\"1.4054\",\"70007.8\"],[\"1.4055\",\"60765.9\"],[\"1.4056\",\"59658.0\"],[\"1.4077\",\"54622.9\"],[\"1.4079\",\"42355.3\"],[\"1.4080\",\"63643.3\"],[\"1.4113\",\"38297.1\"],[\"1.4116\",\"50744.1\"],[\"1.4217\",\"9670.7\"],[\"1.4233\",\"25808.7\"],[\"1.4234\",\"434.3\"],[\"1.4251\",\"42400.2\"],[\"1.4323\",\"6955.1\"]],\"u\":9831588,\"seq\":241267353916},\"cts\":1778927760490}"}
{"ts":1778927760827,"data":"{\"topic\":\"orderbook.1000.XRPUSDT\",\"type\":\"delta\",\"ts\":1778927760703,\"data\":{\"s\":\"XRPUSDT\",\"b\":[[\"1.4029\",\"41043.7\"],[\"1.4026\",\"56236.0\"],[\"1.4025\",\"46499.3\"],[\"1.4021\",\"36932.4\"]],\"a\":[],\"u\":9831589,\"seq\":241267354202},\"cts\":1778927760693}"}
{"ts":1778927761028,"data":"{\"topic\":\"orderbook.1000.XRPUSDT\",\"type\":\"delta\",\"ts\":1778927760903,\"data\":{\"s\":\"XRPUSDT\",\"b\":[[\"1.4040\",\"43129.7\"],[\"1.4036\",\"38921.0\"],[\"1.4035\",\"43357.7\"],[\"1.4034\",\"37743.5\"],[\"1.4030\",\"43298.5\"],[\"1.4026\",\"54899.4\"],[\"1.4025\",\"47834.7\"],[\"1.4001\",\"162380.6\"],[\"1.3999\",\"23143.7\"],[\"1.3916\",\"6508.7\"],[\"1.3800\",\"305554.9\"],[\"1.3684\",\"1084.0\"],[\"1.3655\",\"20225.8\"],[\"1.3500\",\"87620.4\"]],\"a\":[[\"1.4054\",\"66447.4\"],[\"1.4060\",\"66829.7\"],[\"1.4068\",\"80693.2\"],[\"1.4070\",\"335063.9\"],[\"1.4077\",\"55473.9\"],[\"1.4079\",\"41504.3\"],[\"1.4114\",\"35513.4\"],[\"1.4117\",\"27642.2\"]],\"u\":9831590,\"seq\":241267354539},\"cts\":1778927760896}"}
{"ts":1778927761227,"data":"{\"topic\":\"orderbook.1000.XRPUSDT\",\"type\":\"delta\",\"ts\":1778927761103,\"data\":{\"s\":\"XRPUSDT\",\"b\":[[\"1.4035\",\"43386.2\"],[\"1.4034\",\"37519.2\"],[\"1.4025\",\"47819.0\"],[\"1.4010\",\"80857.8\"],[\"1.4009\",\"53434.9\"],[\"1.3999\",\"23147.3\"]],\"a\":[[\"1.4044\",\"21981.0\"],[\"1.4046\",\"62829.5\"],[\"1.4048\",\"79705.9\"],[\"1.4054\",\"64734.4\"],[\"1.4056\",\"59686.5\"],[\"1.4057\",\"50021.1\"],[\"1.4106\",\"31033.1\"]],\"u\":9831591,\"seq\":241267354717},\"cts\":1778927761099}"}
{"ts":1778927761428,"data":"{\"topic\":\"orderbook.1000.XRPUSDT\",\"type\":\"delta\",\"ts\":1778927761303,\"data\":{\"s\":\"XRPUSDT\",\"b\":[[\"1.4043\",\"36743.3\"],[\"1.3999\",\"23143.7\"],[\"1.3911\",\"988.3\"],[\"1.3901\",\"2617.4\"],[\"1.3899\",\"6349.7\"],[\"1.3892\",\"1529.3\"],[\"1.3885\",\"11168.8\"],[\"1.3884\",\"1799.3\"],[\"1.3870\",\"20893.3\"],[\"1.3864\",\"3219.5\"],[\"1.3863\",\"7593.1\"],[\"1.3860\",\"42022.5\"],[\"1.3855\",\"7484.5\"],[\"1.3850\",\"129662.7\"],[\"1.3845\",\"15469.8\"],[\"1.3805\",\"2315.7\"],[\"1.3789\",\"9014.3\"]],\"a\":[[\"1.4054\",\"69986.9\"],[\"1.4075\",\"327736.8\"],[\"1.4087\",\"46712.1\"],[\"1.4096\",\"62023.8\"],[\"1.4199\",\"983.6\"],[\"1.4205\",\"73486.9\"],[\"1.4215\",\"2444.8\"],[\"1.4217\",\"9290.9\"],[\"1.4222\",\"8412.3\"],[\"1.4230\",\"5499.5\"],[\"1.4231\",\"426.6\"],[\"1.4232\",\"511.6\"],[\"1.4244\",\"1468.7\"],[\"1.4248\",\"38912.2\"],[\"1.4251\",\"41747.7\"],[\"1.4252\",\"23176.5\"],[\"1.4253\",\"397.9\"],[\"1.4261\",\"123.3\"],[\"1.4269\",\"18118.3\"],[\"1.4286\",\"7941.0\"],[\"1.4324\",\"7085.9\"]],\"u\":9831592,\"seq\":241267354910},\"cts\":1778927761302}"}
{"ts":1778927761627,"data":"{\"topic\":\"orderbook.1000.XRPUSDT\",\"type\":\"delta\",\"ts\":1778927761503,\"data\":{\"s\":\"XRPUSDT\",\"b\":[[\"1.4043\",\"36754.4\"],[\"1.4042\",\"49633.9\"],[\"1.4040\",\"42836.1\"],[\"1.4034\",\"41083.7\"],[\"1.4033\",\"42007.5\"],[\"1.4032\",\"37075.6\"],[\"1.4029\",\"40878.2\"],[\"1.4026\",\"61282.6\"],[\"1.4025\",\"41437.3\"],[\"1.4018\",\"107455.0\"],[\"1.4017\",\"136395.5\"],[\"1.4013\",\"55288.3\"],[\"1.4012\",\"152106.3\"],[\"1.4009\",\"48177.4\"],[\"1.3914\",\"13896.2\"],[\"1.3885\",\"11528.9\"],[\"1.3864\",\"2858.9\"],[\"1.3798\",\"8563.1\"],[\"1.3730\",\"5769.0\"],[\"1.3682\",\"2357.4\"],[\"1.3653\",\"19833.4\"],[\"1.3562\",\"11505.9\"]],\"a\":[[\"1.4044\",\"20290.1\"],[\"1.4045\",\"27698.6\"],[\"1.4046\",\"36081.0\"],[\"1.4047\",\"53875.1\"],[\"1.4049\",\"86383.4\"],[\"1.4050\",\"81313.2\"],[\"1.4051\",\"74138.6\"],[\"1.4052\",\"67404.1\"],[\"1.4053\",\"62997.8\"],[\"1.4054\",\"61174.0\"],[\"1.4056\",\"59423.4\"],[\"1.4060\",\"66758.8\"],[\"1.4067\",\"70928.3\"],[\"1.4068\",\"53106.8\"],[\"1.4070\",\"247473.1\"],[\"1.4072\",\"71763.9\"],[\"1.4075\",\"415332.1\"],[\"1.4076\",\"113265.0\"],[\"1.4077\",\"55184.3\"],[\"1.4078\",\"326559.3\"],[\"1.4079\",\"65291.8\"],[\"1.4080\",\"39855.8\"],[\"1.4083\",\"42101.9\"],[\"1.4106\",\"31040.2\"],[\"1.4113\",\"62084.6\"],[\"1.4116\",\"26956.6\"],[\"1.4230\",\"5850.8\"],[\"1.4253\",\"47.1\"]],\"u\":9831593,\"seq\":241267355292},\"cts\":1778927761501}"}
{"ts":1778927761828,"data":"{\"topic\":\"orderbook.1000.XRPUSDT\",\"type\":\"delta\",\"ts\":1778927761703,\"data\":{\"s\":\"XRPUSDT\",\"b\":[[\"1.4043\",\"47954.4\"],[\"1.4037\",\"31079.1\"],[\"1.4036\",\"38564.8\"],[\"1.4035\",\"50514.2\"],[\"1.4029\",\"41043.7\"],[\"1.4021\",\"36936.0\"]],\"a\":[[\"1.4044\",\"13237.1\"],[\"1.4046\",\"21647.4\"],[\"1.4047\",\"78013.5\"],[\"1.4048\",\"72585.2\"],[\"1.4049\",\"93503.7\"],[\"1.4060\",\"58694.0\"],[\"1.4061\",\"47075.1\"],[\"1.4062\",\"118762.0\"],[\"1.4087\",\"46797.3\"],[\"1.4091\",\"260726.3\"]],\"u\":9831594,\"seq\":241267355502},\"cts\":1778927761702}"}
{"ts":1778927762027,"data":"{\"topic\":\"orderbook.1000.XRPUSDT\",\"type\":\"delta\",\"ts\":1778927761903,\"data\":{\"s\":\"XRPUSDT\",\"b\":[[\"1.4042\",\"49668.5\"],[\"1.4041\",\"59074.4\"],[\"1.4040\",\"42816.3\"],[\"1.4039\",\"42804.7\"],[\"1.4014\",\"193490.6\"]],\"a\":[[\"1.4046\",\"36098.6\"],[\"1.4047\",\"70779.8\"],[\"1.4052\",\"70963.8\"],[\"1.4053\",\"59438.2\"],[\"1.4061\",\"75565.6\"],[\"1.4062\",\"90271.5\"],[\"1.4072\",\"46771.8\"],[\"1.4073\",\"57215.1\"],[\"1.4076\",\"113350.3\"],[\"1.4079\",\"65149.7\"],[\"1.4083\",\"41959.9\"]],\"u\":9831595,\"seq\":241267355615},\"cts\":1778927761896}"}
{"ts":1778927762227,"data":"{\"topic\":\"orderbook.1000.XRPUSDT\",\"type\":\"delta\",\"ts\":1778927762103,\"data\":{\"s\":\"XRPUSDT\",\"b\":[[\"1.4035\",\"61337.1\"],[\"1.4034\",\"37519.2\"],[\"1.4033\",\"45572.0\"],[\"1.4014\",\"271031.6\"]],\"a\":[[\"1.4044\",\"223.1\"],[\"1.4045\",\"21026.0\"],[\"1.4054\",\"64734.4\"],[\"1.4056\",\"58678.1\"],[\"1.4057\",\"50025.6\"],[\"1.4061\",\"47075.1\"],[\"1.4062\",\"118762.0\"],[\"1.4071\",\"65230.3\"],[\"1.4073\",\"78396.8\"],[\"1.4074\",\"211551.0\"],[\"1.4075\",\"415246.8\"],[\"1.4079\",\"41220.1\"],[\"1.4082\",\"57819.1\"],[\"1.4087\",\"46939.3\"],[\"1.4113\",\"38297.1\"],[\"1.4119\",\"63987.3\"],[\"1.4217\",\"9284.8\"]],\"u\":9831596,\"seq\":241267355743},\"cts\":1778927762099}"}
{"ts":1778927762427,"data":"{\"topic\":\"orderbook.1000.XRPUSDT\",\"type\":\"delta\",\"ts\":1778927762303,\"data\":{\"s\":\"XRPUSDT\",\"b\":[[\"1.4043\",\"44881.8\"],[\"1.4040\",\"44240.4\"],[\"1.4027\",\"33135.9\"],[\"1.4026\",\"61279.0\"],[\"1.4012\",\"150616.3\"],[\"1.3988\",\"34825.8\"],[\"1.3987\",\"41927.1\"],[\"1.3975\",\"62832.1\"],[\"1.3974\",\"61666.2\"],[\"1.3851\",\"20928.9\"]],\"a\":[[\"1.4044\",\"258.0\"],[\"1.4045\",\"21097.2\"],[\"1.4046\",\"62855.2\"],[\"1.4052\",\"70762.9\"],[\"1.4056\",\"53046.7\"],[\"1.4057\",\"50021.1\"],[\"1.4073\",\"57215.1\"],[\"1.4074\",\"211756.4\"],[\"1.4087\",\"47024.5\"],[\"1.4091\",\"260863.7\"],[\"1.4092\",\"62480.5\"],[\"1.4095\",\"35094.5\"],[\"1.4101\",\"88281.8\"],[\"1.4104\",\"46560.9\"],[\"1.4216\",\"102.2\"],[\"1.4223\",\"18049.9\"],[\"1.4296\",\"16797.4\"],[\"1.4377\",\"17742.5\"]],\"u\":9831597,\"seq\":241267355997},\"cts\":1778927762301}"}
{"ts":1778927762628,"data":"{\"topic\":\"orderbook.1000.XRPUSDT\",\"type\":\"delta\",\"ts\":1778927762503,\"data\":{\"s\":\"XRPUSDT\",\"b\":[[\"1.4043\",\"42674.9\"],[\"1.4041\",\"59056.0\"],[\"1.4014\",\"193490.6\"],[\"1.4001\",\"23106.2\"],[\"1.3987\",\"41923.5\"],[\"1.3985\",\"41130.2\"],[\"1.3979\",\"423579.2\"],[\"1.3974\",\"61662.6\"],[\"1.3973\",\"34867.7\"],[\"1.3470\",\"1260.7\"],[\"1.3416\",\"64.4\"]],\"a\":[[\"1.4055\",\"60697.2\"],[\"1.4073\",\"57219.6\"],[\"1.4074\",\"137400.4\"],[\"1.4085\",\"38022.8\"],[\"1.4086\",\"72143.5\"],[\"1.4091\",\"261090.8\"],[\"1.4104\",\"46646.0\"],[\"1.4108\",\"435114.8\"],[\"1.4109\",\"90528.8\"],[\"1.4235\",\"4999.5\"],[\"1.4239\",\"910.6\"],[\"1.4247\",\"14534.7\"],[\"1.4249\",\"13.8\"],[\"1.4376\",\"25917.3\"]],\"u\":9831598,\"seq\":241267356146},\"cts\":1778927762487}"}
{"ts":1778927762828,"data":"{\"topic\":\"orderbook.1000.XRPUSDT\",\"type\":\"delta\",\"ts\":1778927762704,\"data\":{\"s\":\"XRPUSDT\",\"b\":[[\"1.4043\",\"42674.6\"],[\"1.4020\",\"69924.3\"],[\"1.4016\",\"73153.2\"],[\"1.3985\",\"41126.6\"],[\"1.3983\",\"26844.3\"],[\"1.3979\",\"302087.2\"],[\"1.3973\",\"34864.1\"],[\"1.3969\",\"40405.2\"],[\"1.3805\",\"867.0\"]],\"a\":[[\"1.4109\",\"34880.2\"]],\"u\":9831599,\"seq\":241267356229},\"cts\":1778927762690}"}
{"ts":1778927763028,"data":"{\"topic\":\"orderbook.1000.XRPUSDT\",\"type\":\"delta\",\"ts\":1778927762903,\"data\":{\"s\":\"XRPUSDT\",\"b\":[[\"1.4042\",\"49661.3\"],[\"1.4041\",\"59043.9\"],[\"1.4035\",\"55704.1\"],[\"1.4029\",\"40996.2\"],[\"1.4027\",\"33132.3\"],[\"1.4026\",\"61282.6\"],[\"1.4013\",\"62531.1\"],[\"1.4011\",\"257513.3\"],[\"1.4010\",\"80861.4\"],[\"1.3989\",\"37784.2\"],[\"1.3983\",\"26840.7\"],[\"1.3976\",\"28065.4\"],[\"1.3969\",\"40401.6\"]],\"a\":[[\"1.4044\",\"269.3\"],[\"1.4080\",\"63643.3\"],[\"1.4082\",\"34031.6\"],[\"1.4097\",\"360959.7\"],[\"1.4117\",\"51429.7\"],[\"1.4119\",\"40199.8\"]],\"u\":9831600,\"seq\":241267356507},\"cts\":1778927762900}"}
{"ts":1778927763229,"data":"{\"topic\":\"orderbook.1000.XRPUSDT\",\"type\":\"delta\",\"ts\":1778927763105,\"data\":{\"s\":\"XRPUSDT\",\"b\":[[\"1.4042\",\"49242.8\"],[\"1.4040\",\"44676.4\"],[\"1.4034\",\"41083.6\"],[\"1.4033\",\"42007.5\"],[\"1.4028\",\"48968.5\"],[\"1.4027\",\"33135.9\"],[\"1.4026\",\"61279.0\"],[\"1.4011\",\"257516.9\"],[\"1.4010\",\"80857.8\"],[\"1.3989\",\"37780.6\"],[\"1.3983\",\"26844.3\"],[\"1.3976\",\"28061.8\"],[\"1.3971\",\"61038.4\"]],\"a\":[[\"1.4049\",\"93939.7\"],[\"1.4051\",\"73702.6\"],[\"1.4109\",\"34875.7\"],[\"1.4110\",\"43749.9\"]],\"u\":9831601,\"seq\":241267356608},\"cts\":1778927763096}"}
{"ts":1778927763427,"data":"{\"topic\":\"orderbook.1000.XRPUSDT\",\"type\":\"delta\",\"ts\":1778927763303,\"data\":{\"s\":\"XRPUSDT\",\"b\":[[\"1.4043\",\"42681.6\"],[\"1.4040\",\"44893.1\"],[\"1.3989\",\"37784.2\"],[\"1.3983\",\"26840.7\"],[\"1.3976\",\"28065.4\"],[\"1.3971\",\"61034.8\"],[\"1.3734\",\"3268.3\"],[\"1.3622\",\"13587.1\"]],\"a\":[[\"1.4044\",\"479.0\"],[\"1.4054\",\"61174.0\"],[\"1.4080\",\"39855.8\"],[\"1.4082\",\"57819.1\"],[\"1.4117\",\"27642.2\"],[\"1.4119\",\"63987.3\"]],\"u\":9831602,\"seq\":241267356749},\"cts\":1778927763299}"}
{"ts":1778927763627,"data":"{\"topic\":\"orderbook.1000.XRPUSDT\",\"type\":\"delta\",\"ts\":1778927763503,\"data\":{\"s\":\"XRPUSDT\",\"b\":[[\"1.4043\",\"42675.8\"],[\"1.4040\",\"43252.3\"],[\"1.4035\",\"43386.2\"],[\"1.4033\",\"45572.0\"],[\"1.4014\",\"271031.7\"],[\"1.4009\",\"53902.1\"],[\"1.4001\",\"162380.7\"],[\"1.3989\",\"37780.6\"],[\"1.3983\",\"26844.3\"],[\"1.3979\",\"423579.3\"],[\"1.3976\",\"28061.8\"],[\"1.3969\",\"40405.2\"],[\"1.3550\",\"9707.9\"]],\"a\":[[\"1.4044\",\"22001.8\"],[\"1.4045\",\"28049.4\"],[\"1.4054\",\"72994.0\"],[\"1.4056\",\"63869.6\"],[\"1.4074\",\"211762.7\"],[\"1.4077\",\"49253.3\"],[\"1.4087\",\"185451.2\"],[\"1.4109\",\"83632.9\"]],\"u\":9831603,\"seq\":241267356940},\"cts\":1778927763498}"}
{"ts":1778927763828,"data":"{\"topic\":\"orderbook.1000.XRPUSDT\",\"type\":\"delta\",\"ts\":1778927763703,\"data\":{\"s\":\"XRPUSDT\",\"b\":[[\"1.4042\",\"49225.3\"],[\"1.4040\",\"43109.9\"],[\"1.4027\",\"33132.3\"],[\"1.4026\",\"61282.6\"],[\"1.4014\",\"193490.6\"],[\"1.4001\",\"23106.2\"],[\"1.3989\",\"37784.2\"],[\"1.3983\",\"26840.7\"],[\"1.3979\",\"302087.2\"],[\"1.3973\",\"34867.7\"],[\"1.3969\",\"40401.6\"]],\"a\":[[\"1.4044\",\"13479.0\"],[\"1.4054\",\"64734.4\"],[\"1.4061\",\"75565.6\"],[\"1.4062\",\"90271.5\"],[\"1.4072\",\"46776.3\"],[\"1.4073\",\"57215.1\"],[\"1.4074\",\"137400.4\"],[\"1.4077\",\"55388.5\"],[\"1.4087\",\"47024.5\"],[\"1.4091\",\"261095.3\"],[\"1.4092\",\"62476.0\"],[\"1.4109\",\"34880.2\"],[\"1.4110\",\"43745.4\"]],\"u\":9831604,\"seq\":241267357273},\"cts\":1778927763694}"}
{"ts":1778927764027,"data":"{\"topic\":\"orderbook.1000.XRPUSDT\",\"type\":\"delta\",\"ts\":1778927763903,\"data\":{\"s\":\"XRPUSDT\",\"b\":[[\"1.4042\",\"49231.5\"],[\"1.4019\",\"84811.8\"],[\"1.4018\",\"134788.8\"],[\"1.4011\",\"240610.5\"],[\"1.4010\",\"53524.9\"],[\"1.3989\",\"37780.6\"],[\"1.3983\",\"26844.3\"],[\"1.3973\",\"34864.1\"],[\"1.3969\",\"40405.2\"]],\"a\":[[\"1.4044\",\"20949.9\"],[\"1.4060\",\"66758.8\"],[\"1.4091\",\"261090.8\"],[\"1.4092\",\"62480.5\"],[\"1.4279\",\"16655.6\"]],\"u\":9831605,\"seq\":241267357574},\"cts\":1778927763899}"}
{"ts":1778927764227,"data":"{\"topic\":\"orderbook.1000.XRPUSDT\",\"type\":\"delta\",\"ts\":1778927764103,\"data\":{\"s\":\"XRPUSDT\",\"b\":[[\"1.4043\",\"31475.8\"],[\"1.4011\",\"240614.1\"],[\"1.4010\",\"53521.3\"]],\"a\":[[\"1.4044\",\"13920.5\"],[\"1.4057\",\"49953.7\"],[\"1.4059\",\"73900.6\"],[\"1.4077\",\"49253.3\"],[\"1.4079\",\"65007.6\"],[\"1.4082\",\"34031.6\"],[\"1.4114\",\"59300.9\"],[\"1.4119\",\"40199.8\"]],\"u\":9831606,\"seq\":241267357678},\"cts\":1778927764102}"}
{"ts":1778927764427,"data":"{\"topic\":\"orderbook.1000.XRPUSDT\",\"type\":\"delta\",\"ts\":1778927764303,\"data\":{\"s\":\"XRPUSDT\",\"b\":[[\"1.4043\",\"31466.8\"],[\"1.4014\",\"271031.7\"],[\"1.4001\",\"162380.7\"],[\"1.3988\",\"34829.4\"],[\"1.3983\",\"26840.7\"],[\"1.3979\",\"423579.3\"],[\"1.3975\",\"62835.7\"],[\"1.3969\",\"40401.6\"]],\"a\":[[\"1.4044\",\"22045.2\"],[\"1.4054\",\"68043.3\"],[\"1.4073\",\"78484.0\"],[\"1.4074\",\"211857.9\"],[\"1.4087\",\"185451.5\"],[\"1.4109\",\"107813.0\"]],\"u\":9831607,\"seq\":241267357822},\"cts\":1778927764298}"}
{"ts":1778927764628,"data":"{\"topic\":\"orderbook.1000.XRPUSDT\",\"type\":\"delta\",\"ts\":1778927764503,\"data\":{\"s\":\"XRPUSDT\",\"b\":[[\"1.4043\",\"31472.6\"],[\"1.4035\",\"48808.9\"],[\"1.4021\",\"36939.6\"],[\"1.4014\",\"193490.6\"],[\"1.4009\",\"48177.4\"],[\"1.4001\",\"23106.2\"],[\"1.3990\",\"20341.9\"],[\"1.3979\",\"302087.2\"],[\"1.3950\",\"156058.1\"]],\"a\":[[\"1.4044\",\"920.5\"],[\"1.4045\",\"41049.4\"],[\"1.4049\",\"93939.8\"],[\"1.4051\",\"74104.7\"],[\"1.4054\",\"64734.4\"],[\"1.4056\",\"58186.2\"],[\"1.4072\",\"46771.8\"],[\"1.4073\",\"57219.6\"],[\"1.4074\",\"137400.4\"],[\"1.4077\",\"56191.3\"],[\"1.4087\",\"47024.5\"],[\"1.4091\",\"261095.3\"],[\"1.4092\",\"62476.0\"],[\"1.4109\",\"34880.2\"],[\"1.4674\",\"142.7\"]],\"u\":9831608,\"seq\":241267357985},\"cts\":1778927764501}"}
{"ts":1778927764828,"data":"{\"topic\":\"orderbook.1000.XRPUSDT\",\"type\":\"delta\",\"ts\":1778927764703,\"data\":{\"s\":\"XRPUSDT\",\"b\":[[\"1.4043\",\"38672.6\"],[\"1.4035\",\"43386.2\"],[\"1.4021\",\"36928.8\"],[\"1.4014\",\"271031.7\"],[\"1.4009\",\"53491.6\"],[\"1.4001\",\"162380.8\"],[\"1.3999\",\"23147.3\"],[\"1.3979\",\"423579.4\"],[\"1.3539\",\"983.7\"]],\"a\":[[\"1.4044\",\"8788.0\"],[\"1.4054\",\"61174.0\"],[\"1.4056\",\"63869.6\"],[\"1.4073\",\"57216.0\"],[\"1.4074\",\"211858.2\"],[\"1.4079\",\"41220.1\"],[\"1.4082\",\"57819.1\"],[\"1.4087\",\"185455.5\"],[\"1.4091\",\"261090.8\"],[\"1.4092\",\"62480.5\"],[\"1.4109\",\"96833.1\"],[\"1.4114\",\"35513.4\"],[\"1.4119\",\"63987.3\"]],\"u\":9831609,\"seq\":241267358157},\"cts\":1778927764702}"}
