{"ts":1778927726210,"data":"{\"topic\":\"orderbook.1000.XRPUSDT\",\"type\":\"snapshot\",\"ts\":1778927724903,\"data\":{\"s\":\"XRPUSDT\",\"b\":[[\"1.4043\",\"7939.1\"],[\"1.4042\",\"39521.0\"],[\"1.4041\",\"68314.5\"],[\"1.4040\",\"75404.0\"],[\"1.4039\",\"48488.9\"],[\"1.4038\",\"47977.0\"],[\"1.4037\",\"57165.2\"],[\"1.4036\",\"59510.9\"],[\"1.4035\",\"72191.1\"],[\"1.4034\",\"73180.3\"],[\"1.4033\",\"50180.0\"],[\"1.4032\",\"42347.6\"],[\"1.4031\",\"33593.5\"],[\"1.4030\",\"33759.8\"],[\"1.4029\",\"50707.0\"],[\"1.4028\",\"50734.1\"],[\"1.4027\",\"34191.2\"],[\"1.4026\",\"41052.2\"],[\"1.4025\",\"52694.7\"],[\"1.4024\",\"42778.1\"],[\"1.4023\",\"59104.1\"],[\"1.4022\",\"34469.5\"],[\"1.4021\",\"59131.1\"],[\"1.4020\",\"81222.9\"],[\"1.4019\",\"38624.0\"],[\"1.4018\",\"74935.8\"],[\"1.4017\",\"206277.9\"],[\"1.4016\",\"157368.4\"],[\"1.4015\",\"90733.1\"],[\"1.4014\",\"116856.0\"],[\"1.4013\",\"108124.0\"],[\"1.4012\",\"202118.4\"],[\"1.4011\",\"79424.4\"],[\"1.4010\",\"109370.7\"],[\"1.4009\",\"239572.2\"],[\"1.4008\",\"61244.4\"],[\"1.4007\",\"45524.5\"],[\"1.4006\",\"33461.1\"],[\"1.4005\",\"37211.3\"],[\"1.4004\",\"69520.6\"],[\"1.4003\",\"81536.2\"],[\"1.4002\",\"41786.3\"],[\"1.4001\",\"159533.8\"],[\"1.4000\",\"32638.7\"],[\"1.3999\",\"523714.7\"],[\"1.3998\",\"39052.8\"],[\"1.3997\",\"29616.9\"],[\"1.3996\",\"55575.3\"],[\"1.3995\",\"198878.7\"],[\"1.3994\",\"43410.4\"],[\"1.3993\",\"39429.9\"],[\"1.3992\",\"28588.4\"],[\"1.3991\",\"25300.8\"],[\"1.3990\",\"20695.4\"],[\"1.3989\",\"46328.2\"],[\"1.3988\",\"234341.3\"],[\"1.3987\",\"41923.5\"],[\"1.3986\",\"213507.1\"],[\"1.3985\",\"387686.5\"],[\"1.3984\",\"39368.0\"],[\"1.3983\",\"25414.6\"],[\"1.3982\",\"427149.0\"],[\"1.3981\",\"359249.3\"],[\"1.3980\",\"30305.7\"],[\"1.3979\",\"497827.1\"],[\"1.3978\",\"39330.6\"],[\"1.3977\",\"422951.6\"],[\"1.3976\",\"28044.2\"],[\"1.3975\",\"87438.8\"],[\"1.3974\",\"39470.2\"],[\"1.3973\",\"33470.7\"],[\"1.3972\",\"283619.0\"],[\"1.3971\",\"61035.0\"],[\"1.3970\",\"205701.5\"],[\"1.3969\",\"33421.3\"],[\"1.3968\",\"41107.6\"],[\"1.3967\",\"33369.3\"],[\"1.3966\",\"86277.1\"],[\"1.3965\",\"60496.2\"],[\"1.3964\",\"41785.6\"],[\"1.3963\",\"31359.4\"],[\"1.3962\",\"35887.3\"],[\"1.3961\",\"7143.6\"],[\"1.3960\",\"11363.7\"],[\"1.3959\",\"386324.5\"],[\"1.3958\",\"8865.2\"],[\"1.3957\",\"33599.1\"],[\"1.3956\",\"6546.3\"],[\"1.3955\",\"77830.0\"],[\"1.3954\",\"97977.1\"],[\"1.3953\",\"4440.4\"],[\"1.3952\",\"442652.7\"],[\"1.3951\",\"613.0\"],[\"1.3950\",\"156053.1\"],[\"1.3949\",\"4541.6\"],[\"1.3948\",\"23919.2\"],[\"1.3947\",\"5706.1\"],[\"1.3946\",\"3032.2\"],[\"1.3945\",\"15647.1\"],[\"1.3944\",\"5910.1\"],[\"1.3943\",\"43031.7\"],[\"1.3942\",\"1593.3\"],[\"1.3941\",\"2095.7\"],[\"1.3940\",\"9202.1\"],[\"1.3939\",\"5495.8\"],[\"1.3938\",\"3096.3\"],[\"1.3937\",\"1480.1\"],[\"1.3936\",\"3601.8\"],[\"1.3935\",\"8581.3\"],[\"1.3934\",\"1105.6\"],[\"1.3933\",\"32647.1\"],[\"1.3932\",\"3778.4\"],[\"1.3931\",\"4165.2\"],[\"1.3930\",\"19874.6\"],[\"1.3929\",\"3549.3\"],[\"1.3928\",\"10287.8\"],[\"1.3927\",\"603.4\"],[\"1.3926\",\"24830.1\"],[\"1.3925\",\"1406.5\"],[\"1.3924\",\"5178.4\"],[\"1.3923\",\"105728.1\"],[\"1.3922\",\"3172.4\"],[\"1.3921\",\"12680.4\"],[\"1.3920\",\"12629.5\"],[\"1.3919\",\"1428.9\"],[\"1.3918\",\"1098.8\"],[\"1.3917\",\"9174.7\"],[\"1.3916\",\"112934.8\"],[\"1.3915\",\"1343.2\"],[\"1.3914\",\"12758.6\"],[\"1.3913\",\"4639.4\"],[\"1.3912\",\"290832.5\"],[\"1.3911\",\"736.8\"],[\"1.3910\",\"10439.4\"],[\"1.3909\",\"10408.3\"],[\"1.3908\",\"5320.2\"],[\"1.3907\",\"11045.3\"],[\"1.3906\",\"578.9\"],[\"1.3905\",\"637.4\"],[\"1.3904\",\"1981.0\"],[\"1.3903\",\"2292.3\"],[\"1.3902\",\"2007.8\"],[\"1.3901\",\"2624.5\"],[\"1.3900\",\"117811.9\"],[\"1.3899\",\"5990.0\"],[\"1.3898\",\"225.2\"],[\"1.3897\",\"818.5\"],[\"1.3896\",\"6064.7\"],[\"1.3895\",\"1983.7\"],[\"1.3894\",\"1219.7\"],[\"1.3893\",\"10906.0\"],[\"1.3892\",\"1529.3\"],[\"1.3891\",\"2661.2\"],[\"1.3890\",\"158640.5\"],[\"1.3889\",\"4830.5\"],[\"1.3888\",\"3211.5\"],[\"1.3887\",\"1035.3\"],[\"1.3886\",\"15335.0\"],[\"1.3885\",\"10812.4\"],[\"1.3884\",\"617.8\"],[\"1.3883\",\"2254.4\"],[\"1.3882\",\"1058.5\"],[\"1.3881\",\"19771.0\"],[\"1.3880\",\"8156.8\"],[\"1.3879\",\"9509.8\"],[\"1.3878\",\"2309.9\"],[\"1.3877\",\"917.1\"],[\"1.3876\",\"37039.0\"],[\"1.3875\",\"265337.4\"],[\"1.3874\",\"29034.9\"],[\"1.3873\",\"18388.8\"],[\"1.3872\",\"21107.8\"],[\"1.3871\",\"7180.9\"],[\"1.3870\",\"20568.9\"],[\"1.3869\",\"1435.2\"],[\"1.3868\",\"6804.4\"],[\"1.3867\",\"610.8\"],[\"1.3866\",\"20037.8\"],[\"1.3865\",\"8265.6\"],[\"1.3864\",\"2858.9\"],[\"1.3863\",\"9094.4\"],[\"1.3862\",\"40063.8\"],[\"1.3861\",\"2001.6\"],[\"1.3860\",\"41589.6\"],[\"1.3859\",\"1619.4\"],[\"1.3858\",\"329.9\"],[\"1.3857\",\"16096.8\"],[\"1.3856\",\"93.8\"],[\"1.3855\",\"7484.5\"],[\"1.3854\",\"415.5\"],[\"1.3853\",\"169.1\"],[\"1.3852\",\"32409.8\"],[\"1.3851\",\"20928.9\"],[\"1.3850\",\"129662.7\"],[\"1.3849\",\"6547.3\"],[\"1.3848\",\"1658.2\"],[\"1.3847\",\"16683.8\"],[\"1.3846\",\"2042.9\"],[\"1.3845\",\"15469.8\"],[\"1.3844\",\"23866.4\"],[\"1.3843\",\"25190.8\"],[\"1.3842\",\"40921.9\"],[\"1.3841\",\"3979.7\"],[\"1.3840\",\"36834.9\"],[\"1.3839\",\"4049.3\"],[\"1.3838\",\"22849.1\"],[\"1.3837\",\"9975.5\"],[\"1.3836\",\"26330.0\"],[\"1.3835\",\"16560.8\"],[\"1.3834\",\"6271.0\"],[\"1.3833\",\"20098.7\"],[\"1.3832\",\"687.6\"],[\"1.3831\",\"17156.2\"],[\"1.3830\",\"501266.6\"],[\"1.3829\",\"7133.7\"],[\"1.3828\",\"8312.8\"],[\"1.3827\",\"1849.7\"],[\"1.3826\",\"17647.9\"],[\"1.3825\",\"12207.6\"],[\"1.3824\",\"34787.4\"],[\"1.3823\",\"7320.8\"],[\"1.3822\",\"1469.2\"],[\"1.3821\",\"1325.5\"],[\"1.3820\",\"11569.5\"],[\"1.3819\",\"693.4\"],[\"1.3818\",\"907.3\"],[\"1.3817\",\"3226.0\"],[\"1.3816\",\"11674.6\"],[\"1.3815\",\"27604.6\"],[\"1.3814\",\"7694.5\"],[\"1.3813\",\"218.5\"],[\"1.3812\",\"7246.6\"],[\"1.3811\",\"1096.3\"],[\"1.3810\",\"27625.0\"],[\"1.3809\",\"365.2\"],[\"1.3808\",\"11282.5\"],[\"1.3807\",\"637.2\"],[\"1.3806\",\"1693.5\"],[\"1.3805\",\"541.1\"],[\"1.3804\",\"1345.1\"],[\"1.3803\",\"7902.5\"],[\"1.3802\",\"408.6\"],[\"1.3801\",\"9286.1\"],[\"1.3800\",\"306904.5\"],[\"1.3799\",\"397.7\"],[\"1.3798\",\"6941.7\"],[\"1.3797\",\"1896.3\"],[\"1.3796\",\"11471.4\"],[\"1.3795\",\"20435.4\"],[\"1.3794\",\"1273.6\"],[\"1.3793\",\"2686.4\"],[\"1.3792\",\"999.3\"],[\"1.3791\",\"6650.1\"],[\"1.3790\",\"22906.5\"],[\"1.3789\",\"9014.3\"],[\"1.3788\",\"2325.5\"],[\"1.3787\",\"13115.9\"],[\"1.3786\",\"1175.7\"],[\"1.3785\",\"8352.0\"],[\"1.3784\",\"9363.9\"],[\"1.3783\",\"13100.2\"],[\"1.3782\",\"52462.4\"],[\"1.3781\",\"3329.5\"],[\"1.3780\",\"48930.6\"],[\"1.3779\",\"381.7\"],[\"1.3778\",\"1234.2\"],[\"1.3777\",\"12412.9\"],[\"1.3776\",\"745.8\"],[\"1.3775\",\"1147.8\"],[\"1.3774\",\"24176.1\"],[\"1.3773\",\"419.5\"],[\"1.3772\",\"31216.6\"],[\"1.3771\",\"4378.6\"],[\"1.3770\",\"6245.4\"],[\"1.3769\",\"1583.6\"],[\"1.3768\",\"18604.4\"],[\"1.3767\",\"244.7\"],[\"1.3766\",\"8799.8\"],[\"1.3765\",\"8991.9\"],[\"1.3764\",\"536.8\"],[\"1.3763\",\"138.9\"],[\"1.3762\",\"35165.9\"],[\"1.3761\",\"1899.7\"],[\"1.3760\",\"36633.0\"],[\"1.3759\",\"48424.5\"],[\"1.3758\",\"277.9\"],[\"1.3757\",\"623.6\"],[\"1.3756\",\"1179.8\"],[\"1.3755\",\"18686.3\"],[\"1.3754\",\"329.5\"],[\"1.3753\",\"573.3\"],[\"1.3752\",\"9677.8\"],[\"1.3751\",\"42056.6\"],[\"1.3750\",\"22241.3\"],[\"1.3749\",\"9006.7\"],[\"1.3748\",\"5311.5\"],[\"1.3747\",\"476.1\"],[\"1.3746\",\"218.3\"],[\"1.3745\",\"137.2\"],[\"1.3744\",\"601.5\"],[\"1.3743\",\"8939.2\"],[\"1.3742\",\"2029.2\"],[\"1.3741\",\"2979.4\"],[\"1.3740\",\"4847.4\"],[\"1.3739\",\"563.8\"],[\"1.3738\",\"24366.8\"],[\"1.3737\",\"601.7\"],[\"1.3736\",\"4845.4\"],[\"1.3735\",\"9138.2\"],[\"1.3734\",\"1088.5\"],[\"1.3733\",\"7575.9\"],[\"1.3732\",\"251.0\"],[\"1.3731\",\"23190.4\"],[\"1.3730\",\"18857.0\"],[\"1.3729\",\"347.3\"],[\"1.3728\",\"8632.6\"],[\"1.3727\",\"8149.7\"],[\"1.3726\",\"18349.0\"],[\"1.3725\",\"18884.7\"],[\"1.3724\",\"3815.0\"],[\"1.3723\",\"12324.9\"],[\"1.3722\",\"550.8\"],[\"1.3721\",\"713.6\"],[\"1.3720\",\"12341.4\"],[\"1.3719\",\"5206.9\"],[\"1.3718\",\"636.6\"],[\"1.3717\",\"23985.6\"],[\"1.3716\",\"7344.6\"],[\"1.3715\",\"76242.6\"],[\"1.3714\",\"7558.1\"],[\"1.3713\",\"18548.0\"],[\"1.3712\",\"12907.3\"],[\"1.3711\",\"396.7\"],[\"1.3710\",\"9633.3\"],[\"1.3709\",\"9773.2\"],[\"1.3708\",\"2383.9\"],[\"1.3707\",\"8341.3\"],[\"1.3706\",\"16121.7\"],[\"1.3705\",\"7145.1\"],[\"1.3704\",\"11239.6\"],[\"1.3703\",\"29596.0\"],[\"1.3702\",\"1086.9\"],[\"1.3701\",\"3576.2\"],[\"1.3700\",\"77576.1\"],[\"1.3699\",\"25301.4\"],[\"1.3698\",\"22541.5\"],[\"1.3697\",\"18137.1\"],[\"1.3696\",\"7319.5\"],[\"1.3695\",\"25915.6\"],[\"1.3694\",\"7161.8\"],[\"1.3693\",\"1307.9\"],[\"1.3692\",\"12309.6\"],[\"1.3691\",\"54828.4\"],[\"1.3690\",\"4053.1\"],[\"1.3689\",\"20485.2\"],[\"1.3688\",\"3105.5\"],[\"1.3687\",\"211.9\"],[\"1.3686\",\"500.0\"],[\"1.3685\",\"24110.0\"],[\"1.3684\",\"2707.6\"],[\"1.3683\",\"324.0\"],[\"1.3682\",\"791.9\"],[\"1.3681\",\"631.5\"],[\"1.3680\",\"14373.4\"],[\"1.3679\",\"17143.1\"],[\"1.3678\",\"507.5\"],[\"1.3677\",\"7904.2\"],[\"1.3676\",\"4371.7\"],[\"1.3675\",\"8278.3\"],[\"1.3674\",\"354.5\"],[\"1.3673\",\"20606.2\"],[\"1.3672\",\"1408.5\"],[\"1.3671\",\"8138.8\"],[\"1.3670\",\"46483.5\"],[\"1.3669\",\"15841.6\"],[\"1.3668\",\"693.7\"],[\"1.3667\",\"2157.5\"],[\"1.3666\",\"16827.7\"],[\"1.3665\",\"13522.3\"],[\"1.3664\",\"12103.0\"],[\"1.3663\",\"156.3\"],[\"1.3662\",\"13563.0\"],[\"1.3661\",\"1936.6\"],[\"1.3660\",\"8504.0\"],[\"1.3659\",\"4723.5\"],[\"1.3658\",\"32873.7\"],[\"1.3657\",\"26022.8\"],[\"1.3656\",\"5217.5\"],[\"1.3655\",\"21845.5\"],[\"1.3654\",\"140.5\"],[\"1.3653\",\"18213.5\"],[\"1.3652\",\"2239.2\"],[\"1.3651\",\"13666.4\"],[\"1.3650\",\"23191.6\"],[\"1.3649\",\"29373.4\"],[\"1.3648\",\"4648.2\"],[\"1.3647\",\"17366.6\"],[\"1.3646\",\"3085.7\"],[\"1.3645\",\"183.3\"],[\"1.3644\",\"393.8\"],[\"1.3643\",\"3163.9\"],[\"1.3642\",\"16603.7\"],[\"1.3641\",\"2366.9\"],[\"1.3640\",\"9931.6\"],[\"1.3639\",\"1127.5\"],[\"1.3638\",\"117047.4\"],[\"1.3637\",\"605.9\"],[\"1.3636\",\"1860.1\"],[\"1.3635\",\"32832.2\"],[\"1.3634\",\"657.7\"],[\"1.3633\",\"9863.3\"],[\"1.3632\",\"23151.6\"],[\"1.3631\",\"348.9\"],[\"1.3630\",\"5236.1\"],[\"1.3629\",\"18886.4\"],[\"1.3628\",\"392.2\"],[\"1.3627\",\"1422.7\"],[\"1.3626\",\"311.3\"],[\"1.3625\",\"7594.9\"],[\"1.3624\",\"119.2\"],[\"1.3623\",\"7085.8\"],[\"1.3622\",\"11389.4\"],[\"1.3621\",\"12200.2\"],[\"1.3620\",\"7673.8\"],[\"1.3619\",\"676.0\"],[\"1.3618\",\"34752.7\"],[\"1.3617\",\"18684.1\"],[\"1.3616\",\"14203.8\"],[\"1.3615\",\"3385.0\"],[\"1.3614\",\"5986.1\"],[\"1.3613\",\"79.9\"],[\"1.3612\",\"474.5\"],[\"1.3611\",\"2436.0\"],[\"1.3610\",\"3203.4\"],[\"1.3609\",\"29979.7\"],[\"1.3608\",\"192.5\"],[\"1.3607\",\"7930.4\"],[\"1.3606\",\"61189.5\"],[\"1.3605\",\"306.5\"],[\"1.3604\",\"7600.5\"],[\"1.3603\",\"1142.5\"],[\"1.3602\",\"32719.0\"],[\"1.3601\",\"68.9\"],[\"1.3600\",\"32621.1\"],[\"1.3599\",\"129.9\"],[\"1.3598\",\"328.7\"],[\"1.3597\",\"1210.8\"],[\"1.3596\",\"4204.3\"],[\"1.3595\",\"538.6\"],[\"1.3594\",\"231.1\"],[\"1.3593\",\"7650.3\"],[\"1.3592\",\"19038.9\"],[\"1.3591\",\"2522.7\"],[\"1.3590\",\"3724.6\"],[\"1.3589\",\"1530.1\"],[\"1.3588\",\"1485.2\"],[\"1.3587\",\"411.3\"],[\"1.3586\",\"2532.5\"],[\"1.3585\",\"30944.8\"],[\"1.3584\",\"2627.3\"],[\"1.3583\",\"16825.1\"],[\"1.3582\",\"885.1\"],[\"1.3581\",\"3469.2\"],[\"1.3580\",\"11980.6\"],[\"1.3579\",\"10088.0\"],[\"1.3578\",\"120.9\"],[\"1.3577\",\"13395.6\"],[\"1.3576\",\"311.6\"],[\"1.3575\",\"2042.2\"],[\"1.3574\",\"260.5\"],[\"1.3573\",\"716.3\"],[\"1.3572\",\"2868.2\"],[\"1.3571\",\"19073.9\"],[\"1.3570\",\"2658.3\"],[\"1.3569\",\"377.1\"],[\"1.3568\",\"131.9\"],[\"1.3567\",\"17050.0\"],[\"1.3566\",\"832.1\"],[\"1.3565\",\"1327.7\"],[\"1.3564\",\"11274.1\"],[\"1.3563\",\"4141.4\"],[\"1.3562\",\"13713.3\"],[\"1.3561\",\"169.9\"],[\"1.3560\",\"2459.7\"],[\"1.3559\",\"41.5\"],[\"1.3558\",\"1044.0\"],[\"1.3557\",\"130.6\"],[\"1.3556\",\"11472.4\"],[\"1.3555\",\"27935.6\"],[\"1.3554\",\"376.5\"],[\"1.3553\",\"131.4\"],[\"1.3552\",\"5461.7\"],[\"1.3551\",\"2249.2\"],[\"1.3550\",\"13390.6\"],[\"1.3549\",\"3639.5\"],[\"1.3548\",\"49391.2\"],[\"1.3547\",\"44.8\"],[\"1.3546\",\"44.8\"],[\"1.3545\",\"126.9\"],[\"1.3544\",\"109.2\"],[\"1.3543\",\"142.4\"],[\"1.3542\",\"679.2\"],[\"1.3541\",\"2397.2\"],[\"1.3540\",\"2982.7\"],[\"1.3539\",\"983.7\"],[\"1.3538\",\"1009.4\"],[\"1.3537\",\"23312.7\"],[\"1.3536\",\"494.3\"],[\"1.3535\",\"14419.5\"],[\"1.3534\",\"1231.6\"],[\"1.3533\",\"1572.0\"],[\"1.3532\",\"1416.8\"],[\"1.3531\",\"6750.1\"],[\"1.3530\",\"21046.4\"],[\"1.3529\",\"5770.7\"],[\"1.3528\",\"1166.4\"],[\"1.3527\",\"2630.0\"],[\"1.3526\",\"70.3\"],[\"1.3525\",\"1025.1\"],[\"1.3524\",\"1531.0\"],[\"1.3523\",\"1308.0\"],[\"1.3522\",\"438.8\"],[\"1.3521\",\"14073.2\"],[\"1.3520\",\"6595.7\"],[\"1.3519\",\"846.5\"],[\"1.3518\",\"161243.9\"],[\"1.3517\",\"7979.8\"],[\"1.3516\",\"1065.0\"],[\"1.3515\",\"3029.7\"],[\"1.3514\",\"274.8\"],[\"1.3513\",\"327.9\"],[\"1.3512\",\"1298.6\"],[\"1.3511\",\"1199.2\"],[\"1.3510\",\"2328.0\"],[\"1.3509\",\"244.0\"],[\"1.3508\",\"1617.1\"],[\"1.3507\",\"711.5\"],[\"1.3506\",\"286.8\"],[\"1.3505\",\"37.3\"],[\"1.3504\",\"163.9\"],[\"1.3503\",\"178.7\"],[\"1.3502\",\"1196.4\"],[\"1.3501\",\"385.4\"],[\"1.3500\",\"87630.4\"],[\"1.3499\",\"2592.7\"],[\"1.3498\",\"3035.4\"],[\"1.3497\",\"739.0\"],[\"1.3496\",\"7424.3\"],[\"1.3495\",\"14196.5\"],[\"1.3494\",\"105.7\"],[\"1.3493\",\"253.3\"],[\"1.3492\",\"1514.3\"],[\"1.3491\",\"250.3\"],[\"1.3490\",\"521.9\"],[\"1.3489\",\"441.9\"],[\"1.3488\",\"6097.2\"],[\"1.3487\",\"996.8\"],[\"1.3486\",\"2692.5\"],[\"1.3485\",\"60.0\"],[\"1.3484\",\"1118.5\"],[\"1.3483\",\"628.1\"],[\"1.3482\",\"958.8\"],[\"1.3481\",\"12.1\"],[\"1.3480\",\"323.1\"],[\"1.3479\",\"9169.4\"],[\"1.3478\",\"3994.6\"],[\"1.3477\",\"925.7\"],[\"1.3476\",\"1584.5\"],[\"1.3475\",\"381.8\"],[\"1.3474\",\"92.5\"],[\"1.3473\",\"1829.1\"],[\"1.3472\",\"73.4\"],[\"1.3471\",\"239.2\"],[\"1.3470\",\"1074.6\"],[\"1.3469\",\"14820.5\"],[\"1.3468\",\"550.7\"],[\"1.3467\",\"264.6\"],[\"1.3466\",\"80.7\"],[\"1.3465\",\"301.6\"],[\"1.3464\",\"223.7\"],[\"1.3463\",\"1192.1\"],[\"1.3462\",\"610.6\"],[\"1.3461\",\"95.4\"],[\"1.3460\",\"427.8\"],[\"1.3459\",\"153.8\"],[\"1.3458\",\"1570.7\"],[\"1.3457\",\"235.4\"],[\"1.3456\",\"757.5\"],[\"1.3455\",\"688.5\"],[\"1.3454\",\"1350.0\"],[\"1.3453\",\"238.6\"],[\"1.3452\",\"2035.2\"],[\"1.3451\",\"9605.1\"],[\"1.3450\",\"5117.9\"],[\"1.3449\",\"78.2\"],[\"1.3448\",\"4980.5\"],[\"1.3447\",\"188.3\"],[\"1.3446\",\"763.7\"],[\"1.3445\",\"277.3\"],[\"1.3444\",\"8828.6\"],[\"1.3443\",\"1981.3\"],[\"1.3442\",\"5945.3\"],[\"1.3441\",\"5992.2\"],[\"1.3440\",\"2280.2\"],[\"1.3439\",\"547.0\"],[\"1.3438\",\"735.6\"],[\"1.3437\",\"343.2\"],[\"1.3436\",\"1193.2\"],[\"1.3435\",\"239.8\"],[\"1.3434\",\"1388.7\"],[\"1.3433\",\"936.3\"],[\"1.3432\",\"968.5\"],[\"1.3431\",\"176.8\"],[\"1.3430\",\"3255.8\"],[\"1.3429\",\"1134.1\"],[\"1.3428\",\"2230.6\"],[\"1.3427\",\"1088.4\"],[\"1.3426\",\"147.0\"],[\"1.3425\",\"682.3\"],[\"1.3424\",\"159.9\"],[\"1.3423\",\"55.9\"],[\"1.3422\",\"433.8\"],[\"1.3421\",\"5255.9\"],[\"1.3420\",\"36518.9\"],[\"1.3419\",\"1408.5\"],[\"1.3418\",\"243.7\"],[\"1.3417\",\"2191.8\"],[\"1.3416\",\"251.2\"],[\"1.3415\",\"448.6\"],[\"1.3414\",\"296.5\"],[\"1.3413\",\"716.4\"],[\"1.3412\",\"1205.3\"],[\"1.3411\",\"181.2\"],[\"1.3410\",\"524.3\"],[\"1.3409\",\"194.2\"],[\"1.3408\",\"5261.9\"],[\"1.3407\",\"163.4\"],[\"1.3406\",\"1753.6\"],[\"1.3405\",\"1057.8\"],[\"1.3404\",\"146.4\"],[\"1.3403\",\"152.5\"],[\"1.3402\",\"539.7\"],[\"1.3401\",\"1360.1\"],[\"1.3400\",\"5270500.2\"],[\"1.3399\",\"10296.6\"],[\"1.3398\",\"871.3\"],[\"1.3397\",\"912.3\"],[\"1.3396\",\"2899.9\"],[\"1.3395\",\"770.3\"],[\"1.3394\",\"207.0\"],[\"1.3393\",\"201.7\"],[\"1.3392\",\"259.4\"],[\"1.3391\",\"367.8\"],[\"1.3390\",\"293.3\"],[\"1.3389\",\"792.9\"],[\"1.3388\",\"573.4\"],[\"1.3387\",\"6561.6\"],[\"1.3386\",\"174.4\"],[\"1.3385\",\"2919.1\"],[\"1.3384\",\"451.8\"],[\"1.3383\",\"1056.3\"],[\"1.3382\",\"283.2\"],[\"1.3381\",\"321597.2\"],[\"1.3380\",\"3314.3\"],[\"1.3379\",\"965.8\"],[\"1.3378\",\"27.2\"],[\"1.3377\",\"197.9\"],[\"1.3376\",\"2302.0\"],[\"1.3375\",\"491.3\"],[\"1.3374\",\"91.5\"],[\"1.3373\",\"527.8\"],[\"1.3372\",\"2889.5\"],[\"1.3371\",\"642.6\"],[\"1.3370\",\"58.2\"],[\"1.3369\",\"59.1\"],[\"1.3368\",\"148.5\"],[\"1.3367\",\"1903.0\"],[\"1.3366\",\"423.5\"],[\"1.3365\",\"1376.2\"],[\"1.3364\",\"141.7\"],[\"1.3363\",\"38.1\"],[\"1.3362\",\"399.7\"],[\"1.3361\",\"112.3\"],[\"1.3360\",\"1230.6\"],[\"1.3359\",\"236.0\"],[\"1.3358\",\"140.3\"],[\"1.3357\",\"2191.4\"],[\"1.3356\",\"1126.7\"],[\"1.3355\",\"2006.3\"],[\"1.3354\",\"401.8\"],[\"1.3353\",\"82.0\"],[\"1.3352\",\"83.6\"],[\"1.3351\",\"314.4\"],[\"1.3350\",\"2540.7\"],[\"1.3349\",\"226.3\"],[\"1.3348\",\"121.9\"],[\"1.3347\",\"12.1\"],[\"1.3346\",\"619.9\"],[\"1.3345\",\"262.0\"],[\"1.3344\",\"485.1\"],[\"1.3343\",\"944.8\"],[\"1.3342\",\"192.7\"],[\"1.3341\",\"235.6\"],[\"1.3340\",\"222.3\"],[\"1.3339\",\"1141.1\"],[\"1.3338\",\"1350.9\"],[\"1.3337\",\"56.2\"],[\"1.3336\",\"2625.2\"],[\"1.3335\",\"85.3\"],[\"1.3334\",\"2130.5\"],[\"1.3333\",\"156.7\"],[\"1.3332\",\"244.5\"],[\"1.3331\",\"405.1\"],[\"1.3330\",\"1371.4\"],[\"1.3329\",\"3106.6\"],[\"1.3328\",\"134.1\"],[\"1.3327\",\"604.5\"],[\"1.3326\",\"1013.4\"],[\"1.3325\",\"87.5\"],[\"1.3324\",\"44.8\"],[\"1.3323\",\"135.1\"],[\"1.3322\",\"72.6\"],[\"1.3321\",\"122.8\"],[\"1.3320\",\"478.2\"],[\"1.3319\",\"122.6\"],[\"1.3318\",\"131.1\"],[\"1.3317\",\"26.2\"],[\"1.3316\",\"149.6\"],[\"1.3315\",\"4322.0\"],[\"1.3314\",\"1967.4\"],[\"1.3313\",\"163.7\"],[\"1.3312\",\"134.0\"],[\"1.3311\",\"89.1\"],[\"1.3310\",\"939.2\"],[\"1.3309\",\"7.8\"],[\"1.3308\",\"45387.1\"],[\"1.3307\",\"959.0\"],[\"1.3306\",\"51.9\"],[\"1.3305\",\"470.2\"],[\"1.3304\",\"25.2\"],[\"1.3303\",\"56.7\"],[\"1.3302\",\"150.4\"],[\"1.3301\",\"67.2\"],[\"1.3300\",\"16934.5\"],[\"1.3299\",\"1208.1\"],[\"1.3298\",\"63.3\"],[\"1.3297\",\"174.5\"],[\"1.3296\",\"170.8\"],[\"1.3295\",\"1276.7\"],[\"1.3294\",\"319.6\"],[\"1.3293\",\"681.8\"],[\"1.3292\",\"1210.6\"],[\"1.3291\",\"448.9\"],[\"1.3290\",\"561.7\"],[\"1.3289\",\"1039.5\"],[\"1.3288\",\"156.2\"],[\"1.3287\",\"1459.3\"],[\"1.3286\",\"892.7\"],[\"1.3285\",\"47.3\"],[\"1.3284\",\"949.8\"],[\"1.3283\",\"2201.6\"],[\"1.3282\",\"5318.4\"],[\"1.3281\",\"85.0\"],[\"1.3280\",\"573.0\"],[\"1.3279\",\"404.2\"],[\"1.3278\",\"338.9\"],[\"1.3277\",\"549.0\"],[\"1.3276\",\"281.2\"],[\"1.3275\",\"500.4\"],[\"1.3274\",\"1007.3\"],[\"1.3273\",\"419.5\"],[\"1.3272\",\"3150.7\"],[\"1.3271\",\"5819.1\"],[\"1.3270\",\"5156.1\"],[\"1.3269\",\"308.3\"],[\"1.3268\",\"832.2\"],[\"1.3267\",\"63.0\"],[\"1.3266\",\"1030.7\"],[\"1.3265\",\"4543.2\"],[\"1.3264\",\"219.1\"],[\"1.3263\",\"67.0\"],[\"1.3262\",\"87.8\"],[\"1.3261\",\"376.8\"],[\"1.3260\",\"666.0\"],[\"1.3259\",\"36.3\"],[\"1.3258\",\"3411.5\"],[\"1.3257\",\"474.8\"],[\"1.3256\",\"342.9\"],[\"1.3255\",\"33.1\"],[\"1.3254\",\"328.3\"],[\"1.3253\",\"687.6\"],[\"1.3252\",\"330.4\"],[\"1.3251\",\"3815.3\"],[\"1.3250\",\"7038.9\"],[\"1.3249\",\"2719.1\"],[\"1.3248\",\"2673.0\"],[\"1.3247\",\"1825.6\"],[\"1.3246\",\"2367.7\"],[\"1.3245\",\"590.4\"],[\"1.3244\",\"442.6\"],[\"1.3243\",\"569.3\"],[\"1.3242\",\"226.1\"],[\"1.3241\",\"7.7\"],[\"1.3240\",\"172.3\"],[\"1.3239\",\"96.5\"],[\"1.3238\",\"414.0\"],[\"1.3237\",\"86.9\"],[\"1.3236\",\"229.1\"],[\"1.3235\",\"259.9\"],[\"1.3234\",\"75.3\"],[\"1.3233\",\"208.3\"],[\"1.3232\",\"43.3\"],[\"1.3231\",\"1204.4\"],[\"1.3230\",\"3347.4\"],[\"1.3229\",\"6213.6\"],[\"1.3228\",\"2067.3\"],[\"1.3227\",\"307.6\"],[\"1.3226\",\"912.3\"],[\"1.3225\",\"540.8\"],[\"1.3224\",\"796.7\"],[\"1.3223\",\"33.1\"],[\"1.3222\",\"428.7\"],[\"1.3221\",\"1087.0\"],[\"1.3220\",\"191.4\"],[\"1.3219\",\"133.8\"],[\"1.3218\",\"1461.3\"],[\"1.3217\",\"881.8\"],[\"1.3216\",\"114.9\"],[\"1.3215\",\"2135.7\"],[\"1.3214\",\"634.2\"],[\"1.3213\",\"4380.8\"],[\"1.3212\",\"10.7\"],[\"1.3211\",\"603.6\"],[\"1.3210\",\"127.3\"],[\"1.3209\",\"49.8\"],[\"1.3208\",\"193.8\"],[\"1.3207\",\"17002.0\"],[\"1.3206\",\"902.8\"],[\"1.3205\",\"869.8\"],[\"1.3204\",\"834.9\"],[\"1.3203\",\"212.0\"],[\"1.3202\",\"2136.8\"],[\"1.3201\",\"151.6\"],[\"1.3200\",\"49496.7\"],[\"1.3199\",\"66.0\"],[\"1.3198\",\"785.1\"],[\"1.3197\",\"2093.8\"],[\"1.3196\",\"2759.0\"],[\"1.3195\",\"2.6\"],[\"1.3194\",\"530.1\"],[\"1.3193\",\"342.3\"],[\"1.3192\",\"1146.0\"],[\"1.3191\",\"81.4\"],[\"1.3190\",\"1644.7\"],[\"1.3189\",\"120.4\"],[\"1.3188\",\"1541.3\"],[\"1.3187\",\"34.9\"],[\"1.3186\",\"1142.3\"],[\"1.3185\",\"3179.6\"],[\"1.3184\",\"180.1\"],[\"1.3183\",\"181.7\"],[\"1.3182\",\"4557.8\"],[\"1.3181\",\"7.4\"],[\"1.3180\",\"7111.0\"],[\"1.3179\",\"125170.6\"],[\"1.3178\",\"289.9\"],[\"1.3177\",\"115.8\"],[\"1.3176\",\"4765.0\"],[\"1.3175\",\"447.3\"],[\"1.3174\",\"43.8\"],[\"1.3173\",\"1212.2\"],[\"1.3172\",\"4279.9\"],[\"1.3171\",\"290.3\"],[\"1.3170\",\"11460.3\"],[\"1.3169\",\"288.3\"],[\"1.3168\",\"119.4\"],[\"1.3167\",\"2240.7\"],[\"1.3166\",\"815.5\"],[\"1.3165\",\"86.4\"],[\"1.3164\",\"857.3\"],[\"1.3163\",\"2458.0\"],[\"1.3162\",\"920.8\"],[\"1.3161\",\"1689.9\"],[\"1.3160\",\"285.7\"],[\"1.3159\",\"744.8\"],[\"1.3158\",\"34.3\"],[\"1.3157\",\"360.2\"],[\"1.3156\",\"517.8\"],[\"1.3155\",\"11.2\"],[\"1.3154\",\"1267.9\"],[\"1.3153\",\"793.9\"],[\"1.3152\",\"278.9\"],[\"1.3151\",\"1005.6\"],[\"1.3150\",\"3938.7\"],[\"1.3149\",\"16.7\"],[\"1.3148\",\"166.2\"],[\"1.3147\",\"674.2\"],[\"1.3146\",\"3824.1\"],[\"1.3145\",\"978.5\"],[\"1.3144\",\"315.4\"],[\"1.3143\",\"173.5\"],[\"1.3142\",\"6029.2\"],[\"1.3141\",\"23.9\"],[\"1.3140\",\"573.8\"],[\"1.3139\",\"6.2\"],[\"1.3138\",\"670.6\"],[\"1.3137\",\"738.4\"],[\"1.3136\",\"230.9\"],[\"1.3135\",\"7.1\"],[\"1.3134\",\"399.8\"],[\"1.3133\",\"16.5\"],[\"1.3132\",\"79.6\"],[\"1.3131\",\"783.4\"],[\"1.3130\",\"904.0\"],[\"1.3129\",\"1222.5\"],[\"1.3128\",\"1138.4\"],[\"1.3127\",\"232.8\"],[\"1.3126\",\"173.2\"],[\"1.3125\",\"80.3\"],[\"1.3124\",\"6920.8\"],[\"1.3123\",\"217.1\"],[\"1.3122\",\"74.1\"],[\"1.3121\",\"293.2\"],[\"1.3120\",\"1921.0\"],[\"1.3119\",\"321.0\"],[\"1.3118\",\"92.2\"],[\"1.3117\",\"885.7\"],[\"1.3116\",\"4093.9\"],[\"1.3115\",\"454.0\"],[\"1.3114\",\"89.3\"],[\"1.3113\",\"869.7\"],[\"1.3112\",\"117.6\"],[\"1.3111\",\"328.5\"],[\"1.3110\",\"570.3\"],[\"1.3109\",\"452.2\"],[\"1.3108\",\"474.5\"],[\"1.3107\",\"27.4\"],[\"1.3106\",\"691.6\"],[\"1.3105\",\"104.8\"],[\"1.3104\",\"139.2\"],[\"1.3103\",\"279.4\"],[\"1.3102\",\"5.3\"],[\"1.3101\",\"318.8\"],[\"1.3100\",\"17338.1\"],[\"1.3099\",\"2068.2\"],[\"1.3098\",\"436.4\"],[\"1.3097\",\"49.5\"],[\"1.3096\",\"1007.8\"],[\"1.3095\",\"510.1\"],[\"1.3094\",\"581.7\"],[\"1.3093\",\"2899.0\"],[\"1.3092\",\"5026.1\"],[\"1.3091\",\"518.9\"],[\"1.3090\",\"332.0\"],[\"1.3089\",\"512.4\"],[\"1.3088\",\"11.0\"],[\"1.3087\",\"1427.0\"],[\"1.3086\",\"45.4\"],[\"1.3085\",\"12572.0\"],[\"1.3084\",\"2221.0\"],[\"1.3083\",\"71.7\"],[\"1.3082\",\"172.8\"],[\"1.3081\",\"88.2\"],[\"1.3080\",\"199.4\"],[\"1.3079\",\"320.1\"],[\"1.3078\",\"1133.2\"],[\"1.3077\",\"138.7\"],[\"1.3076\",\"42.6\"],[\"1.3075\",\"1235.1\"],[\"1.3074\",\"58.7\"],[\"1.3073\",\"259.9\"],[\"1.3072\",\"1059.8\"],[\"1.3071\",\"78.2\"],[\"1.3070\",\"80.2\"],[\"1.3069\",\"1007.7\"],[\"1.3068\",\"5.4\"],[\"1.3067\",\"48.2\"],[\"1.3066\",\"217.6\"],[\"1.3065\",\"157.3\"],[\"1.3064\",\"441.1\"],[\"1.3063\",\"173.9\"],[\"1.3062\",\"8.5\"],[\"1.3061\",\"52.6\"],[\"1.3060\",\"1098.2\"],[\"1.3059\",\"1884.0\"],[\"1.3058\",\"2797.0\"],[\"1.3057\",\"311.5\"],[\"1.3056\",\"2019.7\"],[\"1.3055\",\"11.8\"],[\"1.3054\",\"66.3\"],[\"1.3053\",\"35.8\"],[\"1.3052\",\"89.7\"],[\"1.3051\",\"5.8\"],[\"1.3050\",\"2581.1\"],[\"1.3049\",\"29.6\"],[\"1.3048\",\"303.9\"],[\"1.3047\",\"383.0\"],[\"1.3046\",\"4.7\"],[\"1.3045\",\"762.8\"],[\"1.3044\",\"152.5\"]],\"a\":[[\"1.4044\",\"37281.8\"],[\"1.4045\",\"24708.9\"],[\"1.4046\",\"74541.4\"],[\"1.4047\",\"59485.6\"],[\"1.4048\",\"53042.3\"],[\"1.4049\",\"46286.6\"],[\"1.4050\",\"68120.0\"],[\"1.4051\",\"80743.0\"],[\"1.4052\",\"79513.8\"],[\"1.4053\",\"59699.4\"],[\"1.4054\",\"72359.1\"],[\"1.4055\",\"72498.0\"],[\"1.4056\",\"84040.5\"],[\"1.4057\",\"60140.2\"],[\"1.4058\",\"55965.3\"],[\"1.4059\",\"62854.7\"],[\"1.4060\",\"101618.1\"],[\"1.4061\",\"106725.9\"],[\"1.4062\",\"137182.2\"],[\"1.4063\",\"118775.6\"],[\"1.4064\",\"60004.9\"],[\"1.4065\",\"90714.9\"],[\"1.4066\",\"54741.7\"],[\"1.4067\",\"122876.9\"],[\"1.4068\",\"239752.8\"],[\"1.4069\",\"61724.6\"],[\"1.4070\",\"46149.1\"],[\"1.4071\",\"70489.4\"],[\"1.4072\",\"35348.9\"],[\"1.4073\",\"173138.2\"],[\"1.4074\",\"250154.8\"],[\"1.4075\",\"477418.3\"],[\"1.4076\",\"36084.4\"],[\"1.4077\",\"172362.5\"],[\"1.4078\",\"60611.0\"],[\"1.4079\",\"183200.1\"],[\"1.4080\",\"54468.0\"],[\"1.4081\",\"278842.4\"],[\"1.4082\",\"37151.2\"],[\"1.4083\",\"31463.9\"],[\"1.4084\",\"53086.2\"],[\"1.4085\",\"38959.4\"],[\"1.4086\",\"210579.7\"],[\"1.4087\",\"34354.0\"],[\"1.4088\",\"75554.4\"],[\"1.4089\",\"27231.6\"],[\"1.4090\",\"32242.0\"],[\"1.4091\",\"56191.4\"],[\"1.4092\",\"62496.3\"],[\"1.4093\",\"47595.5\"],[\"1.4094\",\"75209.9\"],[\"1.4095\",\"29721.6\"],[\"1.4096\",\"56903.2\"],[\"1.4097\",\"362197.4\"],[\"1.4098\",\"26937.4\"],[\"1.4099\",\"212555.6\"],[\"1.4100\",\"363695.4\"],[\"1.4101\",\"385141.9\"],[\"1.4102\",\"34152.8\"],[\"1.4103\",\"28811.3\"],[\"1.4104\",\"436088.7\"],[\"1.4105\",\"52858.2\"],[\"1.4106\",\"43202.8\"],[\"1.4107\",\"440401.5\"],[\"1.4108\",\"27903.6\"],[\"1.4109\",\"97025.7\"],[\"1.4110\",\"53715.4\"],[\"1.4111\",\"245732.3\"],[\"1.4112\",\"247399.9\"],[\"1.4113\",\"37088.2\"],[\"1.4114\",\"35517.0\"],[\"1.4115\",\"52108.8\"],[\"1.4116\",\"26956.6\"],[\"1.4117\",\"27638.6\"],[\"1.4118\",\"27111.0\"],[\"1.4119\",\"40389.3\"],[\"1.4120\",\"387265.8\"],[\"1.4121\",\"100145.9\"],[\"1.4122\",\"58384.9\"],[\"1.4123\",\"34024.0\"],[\"1.4124\",\"283254.4\"],[\"1.4125\",\"45909.2\"],[\"1.4126\",\"8000.2\"],[\"1.4127\",\"4223.2\"],[\"1.4128\",\"2209.9\"],[\"1.4129\",\"21833.1\"],[\"1.4130\",\"2005.8\"],[\"1.4131\",\"7523.6\"],[\"1.4132\",\"814.1\"],[\"1.4133\",\"1104.7\"],[\"1.4134\",\"643.0\"],[\"1.4135\",\"4601.8\"],[\"1.4136\",\"3152.3\"],[\"1.4137\",\"4979.2\"],[\"1.4138\",\"394.7\"],[\"1.4139\",\"359657.4\"],[\"1.4140\",\"6407.4\"],[\"1.4141\",\"196814.4\"],[\"1.4142\",\"73.9\"],[\"1.4143\",\"1967.5\"],[\"1.4144\",\"367.2\"],[\"1.4145\",\"8348.6\"],[\"1.4146\",\"9392.6\"],[\"1.4147\",\"38148.3\"],[\"1.4148\",\"9003.1\"],[\"1.4149\",\"26332.5\"],[\"1.4150\",\"12834.8\"],[\"1.4151\",\"9779.1\"],[\"1.4152\",\"92470.7\"],[\"1.4153\",\"8894.6\"],[\"1.4154\",\"10401.6\"],[\"1.4155\",\"8291.3\"],[\"1.4156\",\"14539.2\"],[\"1.4157\",\"8634.6\"],[\"1.4158\",\"7994.2\"],[\"1.4159\",\"8541.3\"],[\"1.4160\",\"94311.3\"],[\"1.4161\",\"20279.9\"],[\"1.4162\",\"7853.9\"],[\"1.4163\",\"765.6\"],[\"1.4164\",\"288179.6\"],[\"1.4165\",\"56.0\"],[\"1.4166\",\"310.5\"],[\"1.4167\",\"8350.6\"],[\"1.4168\",\"1829.4\"],[\"1.4169\",\"2975.5\"],[\"1.4170\",\"5418.6\"],[\"1.4171\",\"4755.4\"],[\"1.4172\",\"54.7\"],[\"1.4173\",\"53.7\"],[\"1.4174\",\"6000.2\"],[\"1.4175\",\"953.7\"],[\"1.4176\",\"5321.0\"],[\"1.4177\",\"376.8\"],[\"1.4178\",\"132.5\"],[\"1.4179\",\"5155.0\"],[\"1.4180\",\"11270.8\"],[\"1.4181\",\"4282.0\"],[\"1.4182\",\"7641.4\"],[\"1.4183\",\"4095.7\"],[\"1.4184\",\"6504.9\"],[\"1.4185\",\"7207.2\"],[\"1.4186\",\"7323.6\"],[\"1.4187\",\"318.5\"],[\"1.4188\",\"17950.3\"],[\"1.4189\",\"10683.1\"],[\"1.4190\",\"84912.0\"],[\"1.4191\",\"463.8\"],[\"1.4192\",\"836.3\"],[\"1.4193\",\"2224.5\"],[\"1.4194\",\"125.2\"],[\"1.4195\",\"99.2\"],[\"1.4196\",\"1961.6\"],[\"1.4197\",\"91.6\"],[\"1.4198\",\"183964.7\"],[\"1.4199\",\"561.1\"],[\"1.4200\",\"13750.2\"],[\"1.4201\",\"45906.8\"],[\"1.4202\",\"5636.5\"],[\"1.4203\",\"8979.0\"],[\"1.4204\",\"22689.7\"],[\"1.4205\",\"73240.6\"],[\"1.4206\",\"749.1\"],[\"1.4207\",\"2285.4\"],[\"1.4208\",\"212.0\"],[\"1.4209\",\"10667.7\"],[\"1.4210\",\"21962.2\"],[\"1.4211\",\"937.1\"],[\"1.4212\",\"3631.4\"],[\"1.4213\",\"18619.4\"],[\"1.4214\",\"1231.7\"],[\"1.4215\",\"2444.8\"],[\"1.4216\",\"96.1\"],[\"1.4217\",\"8667.7\"],[\"1.4218\",\"189.1\"],[\"1.4219\",\"19011.3\"],[\"1.4220\",\"15652.1\"],[\"1.4221\",\"1551.7\"],[\"1.4222\",\"8412.3\"],[\"1.4223\",\"18049.9\"],[\"1.4224\",\"7302.5\"],[\"1.4225\",\"921.8\"],[\"1.4226\",\"5949.8\"],[\"1.4227\",\"3114.2\"],[\"1.4228\",\"9103.9\"],[\"1.4229\",\"49684.4\"],[\"1.4230\",\"5148.2\"],[\"1.4231\",\"110.4\"],[\"1.4232\",\"195.5\"],[\"1.4233\",\"25492.6\"],[\"1.4234\",\"434.3\"],[\"1.4235\",\"4736.1\"],[\"1.4236\",\"1019.2\"],[\"1.4237\",\"19036.4\"],[\"1.4238\",\"10572.7\"],[\"1.4239\",\"208.4\"],[\"1.4240\",\"33155.0\"],[\"1.4241\",\"817.6\"],[\"1.4242\",\"300.8\"],[\"1.4243\",\"34204.8\"],[\"1.4244\",\"8138.1\"],[\"1.4245\",\"34319.7\"],[\"1.4246\",\"1165.6\"],[\"1.4247\",\"14271.5\"],[\"1.4248\",\"38912.2\"],[\"1.4249\",\"13.8\"],[\"1.4250\",\"21523.8\"],[\"1.4251\",\"41747.7\"],[\"1.4252\",\"23176.5\"],[\"1.4253\",\"47.1\"],[\"1.4254\",\"10284.4\"],[\"1.4255\",\"26329.5\"],[\"1.4256\",\"1996.3\"],[\"1.4257\",\"17849.3\"],[\"1.4258\",\"8949.4\"],[\"1.4259\",\"12032.8\"],[\"1.4260\",\"11813.7\"],[\"1.4261\",\"123.3\"],[\"1.4262\",\"13035.8\"],[\"1.4263\",\"3689.2\"],[\"1.4264\",\"21970.7\"],[\"1.4265\",\"14192.1\"],[\"1.4266\",\"22637.9\"],[\"1.4267\",\"26054.2\"],[\"1.4268\",\"396.9\"],[\"1.4269\",\"17803.0\"],[\"1.4270\",\"27218.0\"],[\"1.4271\",\"51363.7\"],[\"1.4272\",\"8133.8\"],[\"1.4273\",\"28120.8\"],[\"1.4274\",\"371.6\"],[\"1.4275\",\"19872.8\"],[\"1.4276\",\"39514.4\"],[\"1.4277\",\"4568.2\"],[\"1.4278\",\"3768.8\"],[\"1.4279\",\"16612.9\"],[\"1.4280\",\"11806.6\"],[\"1.4281\",\"17691.9\"],[\"1.4282\",\"106.9\"],[\"1.4283\",\"6383.8\"],[\"1.4284\",\"7234.9\"],[\"1.4285\",\"20123.6\"],[\"1.4286\",\"7944.5\"],[\"1.4287\",\"30545.2\"],[\"1.4288\",\"5967.2\"],[\"1.4289\",\"28047.0\"],[\"1.4290\",\"6011.2\"],[\"1.4291\",\"512.9\"],[\"1.4292\",\"1441.7\"],[\"1.4293\",\"17758.6\"],[\"1.4294\",\"29856.6\"],[\"1.4295\",\"1132.9\"],[\"1.4296\",\"16482.7\"],[\"1.4297\",\"10239.6\"],[\"1.4298\",\"10561.6\"],[\"1.4299\",\"166.1\"],[\"1.4300\",\"93410.3\"],[\"1.4301\",\"20662.2\"],[\"1.4302\",\"7643.2\"],[\"1.4303\",\"19164.1\"],[\"1.4304\",\"16329.9\"],[\"1.4305\",\"225.7\"],[\"1.4306\",\"20484.9\"],[\"1.4307\",\"465.5\"],[\"1.4308\",\"8487.2\"],[\"1.4309\",\"8767.7\"],[\"1.4310\",\"16220.7\"],[\"1.4311\",\"39783.0\"],[\"1.4312\",\"233.4\"],[\"1.4313\",\"11149.6\"],[\"1.4314\",\"17559.8\"],[\"1.4315\",\"654.2\"],[\"1.4316\",\"70.3\"],[\"1.4317\",\"35029.2\"],[\"1.4318\",\"16210.2\"],[\"1.4319\",\"5288.7\"],[\"1.4320\",\"8444.5\"],[\"1.4321\",\"14496.1\"],[\"1.4322\",\"23884.6\"],[\"1.4323\",\"6951.6\"],[\"1.4324\",\"7082.4\"],[\"1.4325\",\"256.7\"],[\"1.4326\",\"35637.7\"],[\"1.4327\",\"1576.5\"],[\"1.4328\",\"142.5\"],[\"1.4329\",\"133.0\"],[\"1.4330\",\"4355.2\"],[\"1.4331\",\"646.0\"],[\"1.4332\",\"797.0\"],[\"1.4333\",\"270.3\"],[\"1.4334\",\"2615.5\"],[\"1.4335\",\"14521.8\"],[\"1.4336\",\"236.6\"],[\"1.4337\",\"1814.5\"],[\"1.4338\",\"5211.4\"],[\"1.4339\",\"7087.6\"],[\"1.4340\",\"4364.2\"],[\"1.4341\",\"17572.5\"],[\"1.4342\",\"95.9\"],[\"1.4343\",\"335.1\"],[\"1.4344\",\"582.1\"],[\"1.4345\",\"1663.4\"],[\"1.4346\",\"3945.5\"],[\"1.4347\",\"698.0\"],[\"1.4348\",\"5490.7\"],[\"1.4349\",\"350.3\"],[\"1.4350\",\"4909.3\"],[\"1.4351\",\"164.6\"],[\"1.4352\",\"1289.1\"],[\"1.4353\",\"340.5\"],[\"1.4354\",\"696.9\"],[\"1.4355\",\"70.5\"],[\"1.4356\",\"788.7\"],[\"1.4357\",\"225.1\"],[\"1.4358\",\"1459.1\"],[\"1.4359\",\"265.2\"],[\"1.4360\",\"4282.4\"],[\"1.4361\",\"321.8\"],[\"1.4362\",\"123.2\"],[\"1.4363\",\"277.7\"],[\"1.4364\",\"2766.3\"],[\"1.4365\",\"105.0\"],[\"1.4366\",\"181.7\"],[\"1.4367\",\"1905.6\"],[\"1.4368\",\"199.2\"],[\"1.4369\",\"10152.9\"],[\"1.4370\",\"7979.0\"],[\"1.4371\",\"70.2\"],[\"1.4372\",\"413.3\"],[\"1.4373\",\"10612.5\"],[\"1.4374\",\"1803.9\"],[\"1.4375\",\"139.7\"],[\"1.4376\",\"25899.5\"],[\"1.4377\",\"17760.3\"],[\"1.4378\",\"2823.2\"],[\"1.4379\",\"4580.4\"],[\"1.4380\",\"28883.6\"],[\"1.4381\",\"17.4\"],[\"1.4382\",\"1206.5\"],[\"1.4383\",\"425.5\"],[\"1.4384\",\"149.8\"],[\"1.4385\",\"7314.8\"],[\"1.4386\",\"7185.4\"],[\"1.4387\",\"7340.4\"],[\"1.4388\",\"982.0\"],[\"1.4389\",\"1658.2\"],[\"1.4390\",\"4292.7\"],[\"1.4391\",\"12727.9\"],[\"1.4392\",\"422.1\"],[\"1.4393\",\"85.6\"],[\"1.4394\",\"8895.0\"],[\"1.4395\",\"743.3\"],[\"1.4396\",\"5035.1\"],[\"1.4397\",\"41.0\"],[\"1.4398\",\"5340.1\"],[\"1.4399\",\"1539.7\"],[\"1.4400\",\"10909.1\"],[\"1.4401\",\"1576.8\"],[\"1.4402\",\"374.5\"],[\"1.4403\",\"293.1\"],[\"1.4404\",\"444.0\"],[\"1.4405\",\"14797.0\"],[\"1.4406\",\"646.8\"],[\"1.4407\",\"380.7\"],[\"1.4408\",\"17415.9\"],[\"1.4409\",\"4181.0\"],[\"1.4410\",\"4856.9\"],[\"1.4411\",\"625.1\"],[\"1.4412\",\"767.8\"],[\"1.4413\",\"3944.6\"],[\"1.4414\",\"13353.3\"],[\"1.4415\",\"10463.4\"],[\"1.4416\",\"3996.9\"],[\"1.4417\",\"2413.4\"],[\"1.4418\",\"57.6\"],[\"1.4419\",\"30593.2\"],[\"1.4420\",\"14501.3\"],[\"1.4421\",\"38303.4\"],[\"1.4422\",\"15364.9\"],[\"1.4423\",\"1029.4\"],[\"1.4424\",\"124.4\"],[\"1.4425\",\"1497.7\"],[\"1.4426\",\"2128.7\"],[\"1.4427\",\"6975.8\"],[\"1.4428\",\"5127.5\"],[\"1.4429\",\"234.4\"],[\"1.4430\",\"4195.6\"],[\"1.4431\",\"324.1\"],[\"1.4432\",\"14397.9\"],[\"1.4433\",\"35353.2\"],[\"1.4434\",\"35.0\"],[\"1.4435\",\"3660.6\"],[\"1.4436\",\"13862.7\"],[\"1.4437\",\"198.9\"],[\"1.4438\",\"392.1\"],[\"1.4439\",\"214.2\"],[\"1.4440\",\"4362.2\"],[\"1.4441\",\"4431.8\"],[\"1.4442\",\"5032.0\"],[\"1.4443\",\"4191.6\"],[\"1.4444\",\"6911.8\"],[\"1.4445\",\"271.6\"],[\"1.4446\",\"1417.3\"],[\"1.4447\",\"59939.3\"],[\"1.4448\",\"589.3\"],[\"1.4449\",\"43543.3\"],[\"1.4450\",\"6861.2\"],[\"1.4451\",\"574.1\"],[\"1.4452\",\"235.1\"],[\"1.4453\",\"282.9\"],[\"1.4454\",\"3065.1\"],[\"1.4455\",\"247.3\"],[\"1.4456\",\"444.6\"],[\"1.4457\",\"7041.4\"],[\"1.4458\",\"5806.2\"],[\"1.4459\",\"1006.6\"],[\"1.4460\",\"28751.4\"],[\"1.4461\",\"15688.3\"],[\"1.4462\",\"187.8\"],[\"1.4463\",\"1295.0\"],[\"1.4464\",\"2457.4\"],[\"1.4465\",\"2440.9\"],[\"1.4466\",\"3079.6\"],[\"1.4467\",\"10747.0\"],[\"1.4468\",\"7449.9\"],[\"1.4469\",\"540.3\"],[\"1.4470\",\"4308.6\"],[\"1.4471\",\"1354.9\"],[\"1.4472\",\"62.8\"],[\"1.4473\",\"4703.8\"],[\"1.4474\",\"97.0\"],[\"1.4475\",\"7385.3\"],[\"1.4476\",\"94.1\"],[\"1.4477\",\"3813.5\"],[\"1.4478\",\"35.4\"],[\"1.4479\",\"207.2\"],[\"1.4480\",\"6575.6\"],[\"1.4481\",\"68.0\"],[\"1.4482\",\"25583.6\"],[\"1.4483\",\"2053.6\"],[\"1.4484\",\"478.2\"],[\"1.4485\",\"256.6\"],[\"1.4486\",\"90.0\"],[\"1.4487\",\"186.9\"],[\"1.4488\",\"6955.8\"],[\"1.4489\",\"6720.9\"],[\"1.4490\",\"5727.8\"],[\"1.4491\",\"59.9\"],[\"1.4492\",\"384.7\"],[\"1.4493\",\"19017.7\"],[\"1.4494\",\"909.2\"],[\"1.4495\",\"3515.5\"],[\"1.4496\",\"167.1\"],[\"1.4497\",\"293.1\"],[\"1.4498\",\"5265.1\"],[\"1.4499\",\"16192.1\"],[\"1.4500\",\"65727.4\"],[\"1.4501\",\"387.6\"],[\"1.4502\",\"20714.8\"],[\"1.4503\",\"226.7\"],[\"1.4504\",\"3273.2\"],[\"1.4505\",\"127.7\"],[\"1.4506\",\"165.9\"],[\"1.4507\",\"653.4\"],[\"1.4508\",\"1637.1\"],[\"1.4509\",\"620.0\"],[\"1.4510\",\"55107.0\"],[\"1.4511\",\"1273.6\"],[\"1.4512\",\"11337.5\"],[\"1.4513\",\"489.0\"],[\"1.4514\",\"806.5\"],[\"1.4515\",\"780.4\"],[\"1.4516\",\"226.7\"],[\"1.4517\",\"52.3\"],[\"1.4518\",\"357.1\"],[\"1.4519\",\"1682.3\"],[\"1.4520\",\"6197.5\"],[\"1.4521\",\"379.1\"],[\"1.4522\",\"86242.0\"],[\"1.4523\",\"1098.5\"],[\"1.4524\",\"43.1\"],[\"1.4525\",\"1817.6\"],[\"1.4526\",\"234.5\"],[\"1.4527\",\"91.8\"],[\"1.4528\",\"1101.7\"],[\"1.4529\",\"650.1\"],[\"1.4530\",\"8342.7\"],[\"1.4531\",\"946.6\"],[\"1.4532\",\"152.0\"],[\"1.4533\",\"3555.8\"],[\"1.4534\",\"2436.1\"],[\"1.4535\",\"5236.0\"],[\"1.4536\",\"223.9\"],[\"1.4537\",\"319.3\"],[\"1.4538\",\"4210.4\"],[\"1.4539\",\"122.8\"],[\"1.4540\",\"4936.6\"],[\"1.4541\",\"38709.0\"],[\"1.4542\",\"841.4\"],[\"1.4543\",\"228.3\"],[\"1.4544\",\"83167.1\"],[\"1.4545\",\"2494.5\"],[\"1.4546\",\"284.7\"],[\"1.4547\",\"265.5\"],[\"1.4548\",\"456.8\"],[\"1.4549\",\"185.1\"],[\"1.4550\",\"4782.9\"],[\"1.4551\",\"768.5\"],[\"1.4552\",\"2005.8\"],[\"1.4553\",\"302.6\"],[\"1.4554\",\"106.6\"],[\"1.4555\",\"2609.1\"],[\"1.4556\",\"310.3\"],[\"1.4557\",\"1553.8\"],[\"1.4558\",\"1715.7\"],[\"1.4559\",\"317.2\"],[\"1.4560\",\"5845.8\"],[\"1.4561\",\"278.8\"],[\"1.4562\",\"1833.7\"],[\"1.4563\",\"653.6\"],[\"1.4564\",\"361.2\"],[\"1.4565\",\"416.7\"],[\"1.4566\",\"39.9\"],[\"1.4567\",\"289.3\"],[\"1.4568\",\"7064.8\"],[\"1.4569\",\"1115.5\"],[\"1.4570\",\"7449.8\"],[\"1.4571\",\"1815.9\"],[\"1.4572\",\"227.7\"],[\"1.4573\",\"369.9\"],[\"1.4574\",\"32690.5\"],[\"1.4575\",\"876.5\"],[\"1.4576\",\"2321.1\"],[\"1.4577\",\"4511.0\"],[\"1.4578\",\"68.2\"],[\"1.4579\",\"161.9\"],[\"1.4580\",\"5279.3\"],[\"1.4581\",\"270.3\"],[\"1.4582\",\"459.8\"],[\"1.4583\",\"782.2\"],[\"1.4584\",\"2191.9\"],[\"1.4585\",\"3471.7\"],[\"1.4586\",\"213.8\"],[\"1.4587\",\"108.4\"],[\"1.4588\",\"223.7\"],[\"1.4589\",\"134.1\"],[\"1.4590\",\"5616.9\"],[\"1.4591\",\"686.9\"],[\"1.4592\",\"535.2\"],[\"1.4593\",\"43.2\"],[\"1.4594\",\"204.3\"],[\"1.4595\",\"127.3\"],[\"1.4596\",\"348.2\"],[\"1.4597\",\"1053.3\"],[\"1.4598\",\"608.0\"],[\"1.4599\",\"1386.7\"],[\"1.4600\",\"22430.4\"],[\"1.4601\",\"308.6\"],[\"1.4602\",\"162.7\"],[\"1.4603\",\"5089.2\"],[\"1.4604\",\"96.8\"],[\"1.4605\",\"106.8\"],[\"1.4606\",\"197.9\"],[\"1.4607\",\"314.1\"],[\"1.4608\",\"1094.0\"],[\"1.4609\",\"383.1\"],[\"1.4610\",\"4330.9\"],[\"1.4611\",\"2524.2\"],[\"1.4612\",\"121.2\"],[\"1.4613\",\"109.3\"],[\"1.4614\",\"2915.1\"],[\"1.4615\",\"589.6\"],[\"1.4616\",\"108.6\"],[\"1.4617\",\"340.6\"],[\"1.4618\",\"747.5\"],[\"1.4619\",\"282.1\"],[\"1.4620\",\"4410.2\"],[\"1.4621\",\"75.6\"],[\"1.4622\",\"223.8\"],[\"1.4623\",\"2996.4\"],[\"1.4624\",\"448.2\"],[\"1.4625\",\"244.1\"],[\"1.4626\",\"180.8\"],[\"1.4627\",\"8462.4\"],[\"1.4628\",\"2255.4\"],[\"1.4629\",\"402.2\"],[\"1.4630\",\"5490.7\"],[\"1.4631\",\"23430.7\"],[\"1.4632\",\"380.5\"],[\"1.4633\",\"201.2\"],[\"1.4634\",\"1331.8\"],[\"1.4635\",\"3081.3\"],[\"1.4636\",\"465.5\"],[\"1.4637\",\"96.8\"],[\"1.4638\",\"1054.4\"],[\"1.4639\",\"74.5\"],[\"1.4640\",\"4471.5\"],[\"1.4641\",\"1271.9\"],[\"1.4642\",\"49.0\"],[\"1.4643\",\"481.0\"],[\"1.4644\",\"4191.6\"],[\"1.4645\",\"7128.7\"],[\"1.4646\",\"209.4\"],[\"1.4647\",\"636.2\"],[\"1.4648\",\"1114.6\"],[\"1.4649\",\"237.0\"],[\"1.4650\",\"4990.2\"],[\"1.4651\",\"2613.4\"],[\"1.4652\",\"931.7\"],[\"1.4653\",\"223.5\"],[\"1.4654\",\"3266.2\"],[\"1.4655\",\"696.2\"],[\"1.4656\",\"1747.3\"],[\"1.4657\",\"113.7\"],[\"1.4658\",\"102.7\"],[\"1.4659\",\"159.2\"],[\"1.4660\",\"15381.1\"],[\"1.4661\",\"849.9\"],[\"1.4662\",\"6971.3\"],[\"1.4663\",\"812.5\"],[\"1.4664\",\"61.5\"],[\"1.4665\",\"111.1\"],[\"1.4666\",\"184.2\"],[\"1.4667\",\"2253.1\"],[\"1.4668\",\"5672.3\"],[\"1.4669\",\"340.2\"],[\"1.4670\",\"5184.8\"],[\"1.4671\",\"556.9\"],[\"1.4672\",\"402.0\"],[\"1.4673\",\"116.0\"],[\"1.4674\",\"142.7\"],[\"1.4675\",\"147.1\"],[\"1.4676\",\"11129.6\"],[\"1.4677\",\"570.7\"],[\"1.4678\",\"282.0\"],[\"1.4679\",\"536.8\"],[\"1.4680\",\"5108.4\"],[\"1.4681\",\"940.2\"],[\"1.4682\",\"881.7\"],[\"1.4683\",\"646.8\"],[\"1.4684\",\"334.9\"],[\"1.4685\",\"1524.0\"],[\"1.4686\",\"137.1\"],[\"1.4687\",\"138.5\"],[\"1.4688\",\"1283.2\"],[\"1.4689\",\"1960.6\"],[\"1.4690\",\"4389.3\"],[\"1.4691\",\"223.6\"],[\"1.4692\",\"516.7\"],[\"1.4693\",\"505.1\"],[\"1.4694\",\"1511.5\"],[\"1.4695\",\"4855.1\"],[\"1.4696\",\"858.7\"],[\"1.4697\",\"1781.5\"],[\"1.4698\",\"406.4\"],[\"1.4699\",\"754.2\"],[\"1.4700\",\"74633.6\"],[\"1.4701\",\"1768.7\"],[\"1.4702\",\"1547.6\"],[\"1.4703\",\"1193.9\"],[\"1.4704\",\"224.3\"],[\"1.4705\",\"34.6\"],[\"1.4706\",\"196.2\"],[\"1.4707\",\"265.7\"],[\"1.4708\",\"7473.8\"],[\"1.4709\",\"11866.0\"],[\"1.4710\",\"12137.9\"],[\"1.4711\",\"202.0\"],[\"1.4712\",\"92.6\"],[\"1.4713\",\"413.1\"],[\"1.4714\",\"3093.9\"],[\"1.4715\",\"1333.8\"],[\"1.4716\",\"148.4\"],[\"1.4717\",\"914.5\"],[\"1.4718\",\"261.4\"],[\"1.4719\",\"131.0\"],[\"1.4720\",\"4977.5\"],[\"1.4721\",\"110.0\"],[\"1.4722\",\"71.9\"],[\"1.4723\",\"62.3\"],[\"1.4724\",\"177.4\"],[\"1.4725\",\"517.1\"],[\"1.4726\",\"115.7\"],[\"1.4727\",\"257.4\"],[\"1.4728\",\"277.7\"],[\"1.4729\",\"5178.9\"],[\"1.4730\",\"4714.0\"],[\"1.4731\",\"1499.6\"],[\"1.4732\",\"204.5\"],[\"1.4733\",\"963.0\"],[\"1.4734\",\"992.3\"],[\"1.4735\",\"171.2\"],[\"1.4736\",\"366.2\"],[\"1.4737\",\"1818.0\"],[\"1.4738\",\"703.8\"],[\"1.4739\",\"364.4\"],[\"1.4740\",\"4306.3\"],[\"1.4741\",\"418.9\"],[\"1.4742\",\"843.5\"],[\"1.4743\",\"2346.0\"],[\"1.4744\",\"1568.4\"],[\"1.4745\",\"177.6\"],[\"1.4746\",\"531.3\"],[\"1.4747\",\"54.9\"],[\"1.4748\",\"553.8\"],[\"1.4749\",\"178.2\"],[\"1.4750\",\"7336.9\"],[\"1.4751\",\"1513.9\"],[\"1.4752\",\"158.4\"],[\"1.4753\",\"10430.5\"],[\"1.4754\",\"182.2\"],[\"1.4755\",\"50.3\"],[\"1.4756\",\"1785.1\"],[\"1.4757\",\"141.3\"],[\"1.4758\",\"275.1\"],[\"1.4759\",\"358.6\"],[\"1.4760\",\"22438.9\"],[\"1.4761\",\"1595.8\"],[\"1.4762\",\"1135.2\"],[\"1.4763\",\"1102.9\"],[\"1.4764\",\"642.0\"],[\"1.4765\",\"102.6\"],[\"1.4766\",\"341.0\"],[\"1.4767\",\"166.7\"],[\"1.4768\",\"810.7\"],[\"1.4769\",\"6426.8\"],[\"1.4770\",\"10519.1\"],[\"1.4771\",\"46.5\"],[\"1.4772\",\"1603.2\"],[\"1.4773\",\"842.8\"],[\"1.4774\",\"1739.7\"],[\"1.4775\",\"1240.4\"],[\"1.4776\",\"752.8\"],[\"1.4777\",\"129.9\"],[\"1.4778\",\"107.2\"],[\"1.4779\",\"145.4\"],[\"1.4780\",\"5434.6\"],[\"1.4781\",\"825.2\"],[\"1.4782\",\"256.4\"],[\"1.4783\",\"1139.8\"],[\"1.4784\",\"88.8\"],[\"1.4785\",\"1073.9\"],[\"1.4786\",\"88.7\"],[\"1.4787\",\"421.7\"],[\"1.4788\",\"236.9\"],[\"1.4789\",\"202.9\"],[\"1.4790\",\"11448.2\"],[\"1.4791\",\"604.9\"],[\"1.4792\",\"717.3\"],[\"1.4793\",\"132.4\"],[\"1.4794\",\"434.1\"],[\"1.4795\",\"72.7\"],[\"1.4796\",\"438.9\"],[\"1.4797\",\"80.6\"],[\"1.4798\",\"125.5\"],[\"1.4799\",\"5274.6\"],[\"1.4800\",\"22005.3\"],[\"1.4801\",\"1622.2\"],[\"1.4802\",\"121.2\"],[\"1.4803\",\"398.6\"],[\"1.4804\",\"557.9\"],[\"1.4805\",\"364.9\"],[\"1.4806\",\"322.8\"],[\"1.4807\",\"222.5\"],[\"1.4808\",\"534.1\"],[\"1.4809\",\"79.3\"],[\"1.4810\",\"4457.8\"],[\"1.4811\",\"664.0\"],[\"1.4812\",\"321.9\"],[\"1.4813\",\"305.2\"],[\"1.4814\",\"448.7\"],[\"1.4815\",\"305.2\"],[\"1.4816\",\"3657.8\"],[\"1.4817\",\"298.0\"],[\"1.4818\",\"124.6\"],[\"1.4819\",\"411.9\"],[\"1.4820\",\"4483.0\"],[\"1.4821\",\"1735.5\"],[\"1.4822\",\"447.0\"],[\"1.4823\",\"321.6\"],[\"1.4824\",\"909.5\"],[\"1.4825\",\"366.6\"],[\"1.4826\",\"88.7\"],[\"1.4827\",\"1715.3\"],[\"1.4828\",\"237.4\"],[\"1.4829\",\"213.5\"],[\"1.4830\",\"5298.6\"],[\"1.4831\",\"1958.9\"],[\"1.4832\",\"1269.0\"],[\"1.4833\",\"199.0\"],[\"1.4834\",\"2624.7\"],[\"1.4835\",\"543.6\"],[\"1.4836\",\"274.8\"],[\"1.4837\",\"324.2\"],[\"1.4838\",\"197.4\"],[\"1.4839\",\"113.0\"],[\"1.4840\",\"5937.9\"],[\"1.4841\",\"273.5\"],[\"1.4842\",\"48.2\"],[\"1.4843\",\"207.4\"],[\"1.4844\",\"103.4\"],[\"1.4845\",\"238.6\"],[\"1.4846\",\"845.2\"],[\"1.4847\",\"256.8\"],[\"1.4848\",\"1714.2\"],[\"1.4849\",\"6884.8\"],[\"1.4850\",\"6408.3\"],[\"1.4851\",\"126.6\"],[\"1.4852\",\"66.8\"],[\"1.4853\",\"324.4\"],[\"1.4854\",\"1459.8\"],[\"1.4855\",\"52.2\"],[\"1.4856\",\"47.0\"],[\"1.4857\",\"90.9\"],[\"1.4858\",\"4787.8\"],[\"1.4859\",\"2780.3\"],[\"1.4860\",\"4269.4\"],[\"1.4861\",\"119.0\"],[\"1.4862\",\"235.0\"],[\"1.4863\",\"203.5\"],[\"1.4864\",\"1311.7\"],[\"1.4865\",\"4473.7\"],[\"1.4866\",\"468.9\"],[\"1.4867\",\"524.5\"],[\"1.4868\",\"618.8\"],[\"1.4869\",\"612.1\"],[\"1.4870\",\"4339.1\"],[\"1.4871\",\"1008.8\"],[\"1.4872\",\"6713.8\"],[\"1.4873\",\"1353.9\"],[\"1.4874\",\"179.1\"],[\"1.4875\",\"695.5\"],[\"1.4876\",\"27.1\"],[\"1.4877\",\"431.4\"],[\"1.4878\",\"778.2\"],[\"1.4879\",\"54.1\"],[\"1.4880\",\"4678.3\"],[\"1.4881\",\"1014.8\"],[\"1.4882\",\"322.1\"],[\"1.4883\",\"703.9\"],[\"1.4884\",\"673.2\"],[\"1.4885\",\"2032.0\"],[\"1.4886\",\"398.2\"],[\"1.4887\",\"110.4\"],[\"1.4888\",\"9047.1\"],[\"1.4889\",\"441.7\"],[\"1.4890\",\"4458.1\"],[\"1.4891\",\"1593.8\"],[\"1.4892\",\"79.5\"],[\"1.4893\",\"67.8\"],[\"1.4894\",\"538.5\"],[\"1.4895\",\"163.2\"],[\"1.4896\",\"512.7\"],[\"1.4897\",\"154.2\"],[\"1.4898\",\"1161.0\"],[\"1.4899\",\"367.0\"],[\"1.4900\",\"58984.0\"],[\"1.4901\",\"221.7\"],[\"1.4902\",\"316.0\"],[\"1.4903\",\"93.5\"],[\"1.4904\",\"286.7\"],[\"1.4905\",\"387.5\"],[\"1.4906\",\"10258.9\"],[\"1.4907\",\"120.3\"],[\"1.4908\",\"220.6\"],[\"1.4909\",\"796.1\"],[\"1.4910\",\"4837.2\"],[\"1.4911\",\"229.6\"],[\"1.4912\",\"193.4\"],[\"1.4913\",\"320.2\"],[\"1.4914\",\"4002.9\"],[\"1.4915\",\"57.5\"],[\"1.4916\",\"15294.0\"],[\"1.4917\",\"3387.8\"],[\"1.4918\",\"165.7\"],[\"1.4919\",\"670.8\"],[\"1.4920\",\"10878.8\"],[\"1.4921\",\"1726.0\"],[\"1.4922\",\"198.7\"],[\"1.4923\",\"381.0\"],[\"1.4924\",\"258.9\"],[\"1.4925\",\"277.5\"],[\"1.4926\",\"174.4\"],[\"1.4927\",\"101.5\"],[\"1.4928\",\"268.7\"],[\"1.4929\",\"1276.9\"],[\"1.4930\",\"4109.6\"],[\"1.4931\",\"1184.3\"],[\"1.4932\",\"564.0\"],[\"1.4933\",\"284.5\"],[\"1.4934\",\"1552.3\"],[\"1.4935\",\"1355.4\"],[\"1.4936\",\"80.0\"],[\"1.4937\",\"1292.7\"],[\"1.4938\",\"227.3\"],[\"1.4939\",\"293.6\"],[\"1.4940\",\"6450.5\"],[\"1.4941\",\"486.6\"],[\"1.4942\",\"641.8\"],[\"1.4943\",\"32.2\"],[\"1.4944\",\"2081.7\"],[\"1.4945\",\"277.1\"],[\"1.4946\",\"2176.8\"],[\"1.4947\",\"184.0\"],[\"1.4948\",\"45.5\"],[\"1.4949\",\"10164.7\"],[\"1.4950\",\"4793.4\"],[\"1.4951\",\"297.6\"],[\"1.4952\",\"35.1\"],[\"1.4953\",\"78.4\"],[\"1.4954\",\"124.3\"],[\"1.4955\",\"388.8\"],[\"1.4956\",\"57.8\"],[\"1.4957\",\"196.2\"],[\"1.4958\",\"184.4\"],[\"1.4959\",\"2096.1\"],[\"1.4960\",\"6021.9\"],[\"1.4961\",\"1436.6\"],[\"1.4962\",\"116.1\"],[\"1.4963\",\"243.0\"],[\"1.4964\",\"207.1\"],[\"1.4965\",\"63.1\"],[\"1.4966\",\"2178.0\"],[\"1.4967\",\"528.8\"],[\"1.4968\",\"248.3\"],[\"1.4969\",\"87.0\"],[\"1.4970\",\"4918.3\"],[\"1.4971\",\"141.6\"],[\"1.4972\",\"149.2\"],[\"1.4973\",\"160.0\"],[\"1.4974\",\"42.1\"],[\"1.4975\",\"1693.9\"],[\"1.4976\",\"61.1\"],[\"1.4977\",\"243.7\"],[\"1.4978\",\"5006.9\"],[\"1.4979\",\"276.0\"],[\"1.4980\",\"6543.0\"],[\"1.4981\",\"980.2\"],[\"1.4982\",\"1140.5\"],[\"1.4983\",\"155.9\"],[\"1.4984\",\"124.9\"],[\"1.4985\",\"2015.7\"],[\"1.4986\",\"252.9\"],[\"1.4987\",\"118.9\"],[\"1.4988\",\"28.5\"],[\"1.4989\",\"212.7\"],[\"1.4990\",\"6627.2\"],[\"1.4991\",\"763.3\"],[\"1.4992\",\"243.1\"],[\"1.4993\",\"52.3\"],[\"1.4994\",\"166.2\"],[\"1.4995\",\"55.8\"],[\"1.4996\",\"124.1\"],[\"1.4997\",\"141.4\"],[\"1.4998\",\"63.9\"],[\"1.4999\",\"121.9\"],[\"1.5000\",\"72821.9\"],[\"1.5001\",\"1157.4\"],[\"1.5002\",\"513.3\"],[\"1.5003\",\"108.7\"],[\"1.5004\",\"1472.9\"],[\"1.5005\",\"58.6\"],[\"1.5006\",\"305.9\"],[\"1.5007\",\"1081.3\"],[\"1.5008\",\"482.3\"],[\"1.5009\",\"98.0\"],[\"1.5010\",\"4315.3\"],[\"1.5011\",\"121.9\"],[\"1.5012\",\"60.6\"],[\"1.5013\",\"1881.8\"],[\"1.5014\",\"74.2\"],[\"1.5015\",\"193.9\"],[\"1.5016\",\"142.5\"],[\"1.5017\",\"645.4\"],[\"1.5018\",\"597.9\"],[\"1.5019\",\"35.1\"],[\"1.5020\",\"4964.5\"],[\"1.5021\",\"527.1\"],[\"1.5022\",\"65.9\"],[\"1.5023\",\"159.7\"],[\"1.5024\",\"461.5\"],[\"1.5025\",\"143.2\"],[\"1.5026\",\"3305.7\"],[\"1.5027\",\"184.9\"],[\"1.5028\",\"116.9\"],[\"1.5029\",\"134.9\"],[\"1.5030\",\"8800.8\"],[\"1.5031\",\"2065.4\"],[\"1.5032\",\"124.0\"],[\"1.5033\",\"2009.9\"],[\"1.5034\",\"377.4\"],[\"1.5035\",\"166.3\"],[\"1.5036\",\"23.3\"],[\"1.5037\",\"137.8\"],[\"1.5038\",\"51.1\"],[\"1.5039\",\"460.4\"],[\"1.5040\",\"5013.4\"],[\"1.5041\",\"101.4\"],[\"1.5042\",\"78.8\"],[\"1.5043\",\"411.3\"]],\"u\":9831410,\"seq\":241267302900},\"cts\":1778927724900}"}
{"ts":1778927726213,"data":"{\"topic\":\"orderbook.1000.XRPUSDT\",\"type\":\"delta\",\"ts\":1778927725103,\"data\":{\"s\":\"XRPUSDT\",\"b\":[[\"1.4043\",\"8152.7\"],[\"1.4042\",\"28303.5\"],[\"1.4040\",\"75393.2\"],[\"1.4035\",\"72547.3\"],[\"1.4034\",\"72824.1\"],[\"1.4024\",\"40612.6\"],[\"1.4023\",\"61264.3\"],[\"1.4011\",\"60200.6\"],[\"1.4010\",\"128553.5\"],[\"1.4005\",\"35909.4\"],[\"1.4004\",\"70676.9\"],[\"1.3989\",\"46324.6\"],[\"1.3987\",\"41927.1\"],[\"1.3937\",\"1403.1\"]],\"a\":[[\"1.4044\",\"37392.5\"],[\"1.4045\",\"30412.1\"],[\"1.4046\",\"81650.4\"],[\"1.4047\",\"59210.8\"],[\"1.4048\",\"46633.7\"],[\"1.4049\",\"54187.2\"],[\"1.4050\",\"67475.5\"],[\"1.4051\",\"77183.0\"],[\"1.4053\",\"59632.0\"],[\"1.4054\",\"75852.1\"],[\"1.4058\",\"56106.6\"],[\"1.4060\",\"130108.6\"],[\"1.4061\",\"106225.9\"],[\"1.4062\",\"80201.1\"],[\"1.4063\",\"118779.2\"],[\"1.4084\",\"53937.6\"],[\"1.4085\",\"38108.0\"],[\"1.4106\",\"43195.7\"]],\"u\":9831411,\"seq\":241267303364},\"cts\":1778927725098}"}
{"ts":1778927726215,"data":"{\"topic\":\"orderbook.1000.XRPUSDT\",\"type\":\"delta\",\"ts\":1778927725303,\"data\":{\"s\":\"XRPUSDT\",\"b\":[[\"1.4043\",\"11840.1\"],[\"1.4042\",\"28299.8\"],[\"1.4029\",\"49334.3\"],[\"1.4028\",\"50737.7\"],[\"1.4004\",\"46889.4\"],[\"1.4001\",\"183321.3\"],[\"1.3965\",\"36708.7\"],[\"1.3960\",\"35151.2\"],[\"1.3769\",\"1525.5\"]],\"a\":[[\"1.4044\",\"37386.7\"],[\"1.4047\",\"54581.2\"],[\"1.4048\",\"43030.6\"],[\"1.4060\",\"91802.8\"],[\"1.4061\",\"106796.5\"],[\"1.4062\",\"137182.2\"],[\"1.4078\",\"84398.5\"],[\"1.4080\",\"30680.5\"],[\"1.4082\",\"37136.8\"],[\"1.4106\",\"43202.8\"],[\"1.4112\",\"271187.4\"],[\"1.4115\",\"28321.3\"],[\"1.4378\",\"46.8\"]],\"u\":9831412,\"seq\":241267303602},\"cts\":1778927725300}"}
{"ts":1778927726217,"data":"{\"topic\":\"orderbook.1000.XRPUSDT\",\"type\":\"delta\",\"ts\":1778927725503,\"data\":{\"s\":\"XRPUSDT\",\"b\":[[\"1.4043\",\"0\"],[\"1.4042\",\"0\"],[\"1.4041\",\"0\"],[\"1.4040\",\"0\"],[\"1.4039\",\"57.6\"],[\"1.4038\",\"4562.2\"],[\"1.4037\",\"38904.2\"],[\"1.4036\",\"65304.3\"],[\"1.4035\",\"74783.7\"],[\"1.4034\",\"69105.4\"],[\"1.4033\",\"34457.0\"],[\"1.4032\",\"36275.7\"],[\"1.4031\",\"31086.4\"],[\"1.4030\",\"35166.4\"],[\"1.4029\",\"38600.1\"],[\"1.4028\",\"43516.0\"],[\"1.4027\",\"37757.3\"],[\"1.4026\",\"43307.5\"],[\"1.4025\",\"58467.3\"],[\"1.4024\",\"44732.9\"],[\"1.4023\",\"55881.0\"],[\"1.4022\",\"49233.2\"],[\"1.4021\",\"43116.5\"],[\"1.4020\",\"43920.6\"],[\"1.4019\",\"52660.5\"],[\"1.4017\",\"183128.0\"],[\"1.4016\",\"139818.5\"],[\"1.4013\",\"132253.9\"],[\"1.4012\",\"205910.8\"],[\"1.4011\",\"61601.4\"],[\"1.4010\",\"109374.4\"],[\"1.4008\",\"91145.0\"],[\"1.4007\",\"39737.3\"],[\"1.4006\",\"41281.5\"],[\"1.4005\",\"46715.4\"],[\"1.4004\",\"45733.1\"],[\"1.4002\",\"44078.3\"],[\"1.3985\",\"39037.3\"],[\"1.3972\",\"283622.6\"],[\"1.3967\",\"33376.5\"],[\"1.3966\",\"86284.3\"],[\"1.3961\",\"17286.3\"],[\"1.3960\",\"45293.9\"],[\"1.3959\",\"396467.2\"],[\"1.3782\",\"49565.1\"],[\"1.3763\",\"1955.3\"],[\"1.3670\",\"46490.8\"],[\"1.3621\",\"14035.6\"],[\"1.3551\",\"2286.0\"],[\"1.3043\",\"57.8\"],[\"1.3042\",\"53.2\"],[\"1.3041\",\"371.4\"],[\"1.3040\",\"372.5\"]],\"a\":[[\"1.4040\",\"80748.3\"],[\"1.4041\",\"40542.7\"],[\"1.4042\",\"46898.2\"],[\"1.4043\",\"67526.2\"],[\"1.4044\",\"77363.2\"],[\"1.4045\",\"81491.6\"],[\"1.4046\",\"66487.0\"],[\"1.4047\",\"65916.8\"],[\"1.4048\",\"43922.0\"],[\"1.4049\",\"63874.9\"],[\"1.4050\",\"79443.4\"],[\"1.4051\",\"73622.6\"],[\"1.4052\",\"68535.2\"],[\"1.4053\",\"54663.1\"],[\"1.4055\",\"71906.9\"],[\"1.4056\",\"84044.5\"],[\"1.4058\",\"56528.9\"],[\"1.4059\",\"62991.4\"],[\"1.4060\",\"148933.5\"],[\"1.4061\",\"77805.9\"],[\"1.4062\",\"80201.1\"],[\"1.4063\",\"118786.4\"],[\"1.4069\",\"63059.4\"],[\"1.4070\",\"46145.4\"],[\"1.4071\",\"59705.4\"],[\"1.4072\",\"34122.8\"],[\"1.4074\",\"239362.8\"],[\"1.4075\",\"482749.8\"],[\"1.4083\",\"32315.4\"],[\"1.4084\",\"53086.2\"],[\"1.4105\",\"45765.5\"],[\"1.4112\",\"271183.8\"],[\"1.4118\",\"27103.8\"],[\"1.4119\",\"40382.1\"],[\"1.4125\",\"39379.2\"],[\"1.5040\",\"0\"],[\"1.5041\",\"0\"],[\"1.5042\",\"0\"],[\"1.5043\",\"0\"]],\"u\":9831413,\"seq\":241267305542},\"cts\":1778927725502}"}
{"ts":1778927726218,"data":"{\"topic\":\"orderbook.1000.XRPUSDT\",\"type\":\"delta\",\"ts\":1778927725703,\"data\":{\"s\":\"XRPUSDT\",\"b\":[[\"1.4039\",\"198.7\"],[\"1.4038\",\"23.8\"],[\"1.4037\",\"22272.5\"],[\"1.4036\",\"69815.4\"],[\"1.4035\",\"72516.2\"],[\"1.4034\",\"65592.1\"],[\"1.4033\",\"39532.0\"],[\"1.4032\",\"35982.3\"],[\"1.4031\",\"34086.4\"],[\"1.4030\",\"34810.1\"],[\"1.4029\",\"38805.4\"],[\"1.4028\",\"39950.1\"],[\"1.4027\",\"37133.2\"],[\"1.4026\",\"46870.2\"],[\"1.4025\",\"53820.5\"],[\"1.4024\",\"40942.3\"],[\"1.4023\",\"63026.7\"],[\"1.4022\",\"55767.0\"],[\"1.4021\",\"48110.0\"],[\"1.4020\",\"47390.3\"],[\"1.4019\",\"54809.7\"],[\"1.4017\",\"156891.0\"],[\"1.4016\",\"52207.7\"],[\"1.4015\",\"101540.7\"],[\"1.4014\",\"123761.2\"],[\"1.4013\",\"135031.3\"],[\"1.4012\",\"243898.8\"],[\"1.4011\",\"140924.0\"],[\"1.4009\",\"249004.3\"],[\"1.4008\",\"76280.5\"],[\"1.4006\",\"60331.6\"],[\"1.4005\",\"35909.4\"],[\"1.4003\",\"92343.8\"],[\"1.4002\",\"42718.5\"],[\"1.3999\",\"524873.5\"],[\"1.3976\",\"376675.1\"],[\"1.3965\",\"36715.9\"],[\"1.3964\",\"41792.8\"],[\"1.3963\",\"31366.6\"],[\"1.3958\",\"19007.9\"],[\"1.3921\",\"14476.2\"]],\"a\":[[\"1.4040\",\"73762.3\"],[\"1.4041\",\"83078.2\"],[\"1.4042\",\"108144.1\"],[\"1.4043\",\"101203.5\"],[\"1.4044\",\"65609.6\"],[\"1.4045\",\"69663.1\"],[\"1.4046\",\"67152.8\"],[\"1.4047\",\"57076.4\"],[\"1.4048\",\"62014.2\"],[\"1.4049\",\"62747.0\"],[\"1.4050\",\"76632.8\"],[\"1.4051\",\"73480.1\"],[\"1.4052\",\"66950.9\"],[\"1.4053\",\"54667.6\"],[\"1.4054\",\"72291.7\"],[\"1.4055\",\"100405.6\"],[\"1.4056\",\"103855.0\"],[\"1.4057\",\"120255.3\"],[\"1.4058\",\"62241.0\"],[\"1.4059\",\"67263.2\"],[\"1.4060\",\"91944.2\"],[\"1.4061\",\"61297.1\"],[\"1.4063\",\"114744.0\"],[\"1.4066\",\"54439.0\"],[\"1.4067\",\"152131.8\"],[\"1.4068\",\"263675.6\"],[\"1.4069\",\"144032.0\"],[\"1.4070\",\"44780.5\"],[\"1.4072\",\"70436.3\"],[\"1.4073\",\"146955.7\"],[\"1.4074\",\"151752.0\"],[\"1.4075\",\"454837.0\"],[\"1.4077\",\"178587.7\"],[\"1.4078\",\"93520.5\"],[\"1.4079\",\"192205.7\"],[\"1.4081\",\"273468.8\"],[\"1.4082\",\"27902.4\"],[\"1.4083\",\"31463.9\"],[\"1.4084\",\"44080.6\"],[\"1.4102\",\"42208.8\"],[\"1.4104\",\"458655.3\"],[\"1.4106\",\"31040.2\"],[\"1.4107\",\"432177.2\"],[\"1.4110\",\"31367.7\"],[\"1.4116\",\"26949.4\"],[\"1.4117\",\"27631.4\"],[\"1.4122\",\"51853.5\"],[\"1.4123\",\"27492.6\"],[\"1.4124\",\"266586.7\"],[\"1.4125\",\"29233.5\"],[\"1.4178\",\"485.1\"],[\"1.4182\",\"7288.9\"]],\"u\":9831414,\"seq\":241267307219},\"cts\":1778927725700}"}
{"ts":1778927726371,"data":"{\"topic\":\"orderbook.1000.XRPUSDT\",\"type\":\"delta\",\"ts\":1778927725903,\"data\":{\"s\":\"XRPUSDT\",\"b\":[[\"1.4039\",\"0\"],[\"1.4038\",\"0\"],[\"1.4037\",\"187.2\"],[\"1.4036\",\"4597.6\"],[\"1.4035\",\"14711.1\"],[\"1.4034\",\"32945.3\"],[\"1.4033\",\"30579.3\"],[\"1.4032\",\"41600.5\"],[\"1.4031\",\"34044.1\"],[\"1.4030\",\"26517.0\"],[\"1.4029\",\"21734.9\"],[\"1.4028\",\"24198.0\"],[\"1.4027\",\"28264.3\"],[\"1.4026\",\"44355.8\"],[\"1.4025\",\"47629.0\"],[\"1.4024\",\"40945.9\"],[\"1.4023\",\"52219.5\"],[\"1.4022\",\"43607.4\"],[\"1.4021\",\"50538.5\"],[\"1.4020\",\"54727.1\"],[\"1.4019\",\"52672.0\"],[\"1.4018\",\"56123.4\"],[\"1.4017\",\"52160.2\"],[\"1.4016\",\"55166.2\"],[\"1.4015\",\"65896.1\"],[\"1.4014\",\"126272.0\"],[\"1.4013\",\"97751.8\"],[\"1.4012\",\"84473.2\"],[\"1.4011\",\"146480.3\"],[\"1.4010\",\"56500.8\"],[\"1.4009\",\"57654.6\"],[\"1.4008\",\"82412.2\"],[\"1.4007\",\"40022.7\"],[\"1.4006\",\"41288.6\"],[\"1.4005\",\"54925.2\"],[\"1.4004\",\"56549.8\"],[\"1.4003\",\"224363.0\"],[\"1.4001\",\"313194.8\"],[\"1.4000\",\"32645.8\"],[\"1.3999\",\"24439.3\"],[\"1.3996\",\"79362.8\"],[\"1.3994\",\"43982.0\"],[\"1.3988\",\"472646.6\"],[\"1.3984\",\"37943.5\"],[\"1.3983\",\"26840.7\"],[\"1.3982\",\"25509.0\"],[\"1.3979\",\"486773.3\"],[\"1.3973\",\"369719.7\"],[\"1.3966\",\"87723.4\"],[\"1.3962\",\"35894.5\"],[\"1.3960\",\"21506.4\"],[\"1.3957\",\"43741.8\"],[\"1.3953\",\"28227.9\"],[\"1.3952\",\"355025.1\"],[\"1.3948\",\"42444.7\"],[\"1.3897\",\"1509.1\"],[\"1.3774\",\"24091.1\"],[\"1.3039\",\"231.9\"],[\"1.3038\",\"8.7\"]],\"a\":[[\"1.4038\",\"69052.1\"],[\"1.4039\",\"64556.5\"],[\"1.4040\",\"79024.7\"],[\"1.4041\",\"111684.1\"],[\"1.4042\",\"109505.6\"],[\"1.4043\",\"98629.7\"],[\"1.4044\",\"74397.8\"],[\"1.4045\",\"79600.3\"],[\"1.4046\",\"75925.2\"],[\"1.4047\",\"56774.1\"],[\"1.4048\",\"62244.4\"],[\"1.4049\",\"53429.6\"],[\"1.4050\",\"70809.6\"],[\"1.4051\",\"71298.0\"],[\"1.4052\",\"65956.4\"],[\"1.4053\",\"63639.1\"],[\"1.4054\",\"103468.0\"],[\"1.4055\",\"157273.2\"],[\"1.4056\",\"87831.1\"],[\"1.4057\",\"55412.3\"],[\"1.4058\",\"56525.3\"],[\"1.4059\",\"73234.6\"],[\"1.4060\",\"83810.8\"],[\"1.4063\",\"103062.3\"],[\"1.4064\",\"141233.3\"],[\"1.4065\",\"337217.4\"],[\"1.4066\",\"56510.6\"],[\"1.4067\",\"139965.7\"],[\"1.4069\",\"138489.3\"],[\"1.4070\",\"44776.8\"],[\"1.4072\",\"66209.5\"],[\"1.4074\",\"175539.5\"],[\"1.4075\",\"312743.4\"],[\"1.4077\",\"36511.7\"],[\"1.4078\",\"69733.0\"],[\"1.4080\",\"30779.3\"],[\"1.4081\",\"272617.2\"],[\"1.4082\",\"27906.0\"],[\"1.4087\",\"69958.9\"],[\"1.4092\",\"26886.3\"],[\"1.4098\",\"311687.8\"],[\"1.4101\",\"397517.2\"],[\"1.4105\",\"39237.0\"],[\"1.4107\",\"48104.0\"],[\"1.4108\",\"52045.6\"],[\"1.4112\",\"247396.3\"],[\"1.4114\",\"35513.4\"],[\"1.4115\",\"28317.7\"],[\"1.4119\",\"40027.6\"],[\"1.5038\",\"0\"],[\"1.5039\",\"0\"]],\"u\":9831415,\"seq\":241267308696},\"cts\":1778927725901}"}
{"ts":1778927726373,"data":"{\"success\":true,\"ret_msg\":\"\",\"conn_id\":\"d6ki2od31rkomtnee4u0-fg2hm\",\"req_id\":\"\",\"op\":\"subscribe\"}"}
{"ts":1778927726381,"data":"{\"topic\":\"orderbook.1000.XRPUSDT\",\"type\":\"delta\",\"ts\":1778927726103,\"data\":{\"s\":\"XRPUSDT\",\"b\":[[\"1.4037\",\"0\"],[\"1.4036\",\"21278.8\"],[\"1.4034\",\"83148.0\"],[\"1.4033\",\"51312.5\"],[\"1.4032\",\"49262.5\"],[\"1.4031\",\"34255.3\"],[\"1.4030\",\"28475.0\"],[\"1.4029\",\"31797.8\"],[\"1.4027\",\"28983.8\"],[\"1.4026\",\"44712.2\"],[\"1.4025\",\"46849.7\"],[\"1.4024\",\"55627.5\"],[\"1.4023\",\"51947.4\"],[\"1.4022\",\"63522.4\"],[\"1.4021\",\"57581.5\"],[\"1.4020\",\"54494.2\"],[\"1.4019\",\"49713.7\"],[\"1.4018\",\"49028.9\"],[\"1.4017\",\"54570.8\"],[\"1.4016\",\"60073.7\"],[\"1.4015\",\"69208.2\"],[\"1.4014\",\"137090.2\"],[\"1.4013\",\"90630.3\"],[\"1.4012\",\"83048.6\"],[\"1.4011\",\"161320.5\"],[\"1.4010\",\"84379.4\"],[\"1.4009\",\"61492.3\"],[\"1.4008\",\"82408.6\"],[\"1.4007\",\"49373.0\"],[\"1.4006\",\"48073.8\"],[\"1.4005\",\"35909.4\"],[\"1.4004\",\"75531.9\"],[\"1.4003\",\"377964.7\"],[\"1.4002\",\"53536.7\"],[\"1.4001\",\"302377.3\"],[\"1.3999\",\"61037.9\"],[\"1.3998\",\"39910.5\"],[\"1.3997\",\"44774.1\"],[\"1.3996\",\"34163.5\"],[\"1.3995\",\"194605.3\"],[\"1.3993\",\"304643.8\"],[\"1.3992\",\"46880.7\"],[\"1.3991\",\"37721.1\"],[\"1.3989\",\"43475.7\"],[\"1.3987\",\"44776.8\"],[\"1.3984\",\"37939.9\"],[\"1.3977\",\"406891.3\"],[\"1.3975\",\"87442.4\"],[\"1.3974\",\"39466.6\"],[\"1.3972\",\"300183.1\"],[\"1.3961\",\"17297.1\"],[\"1.3958\",\"18935.9\"],[\"1.3957\",\"67529.3\"],[\"1.3956\",\"16687.2\"],[\"1.3955\",\"87970.9\"],[\"1.3953\",\"4517.4\"],[\"1.3782\",\"46667.8\"],[\"1.3037\",\"334.5\"]],\"a\":[[\"1.4037\",\"25526.9\"],[\"1.4038\",\"43225.6\"],[\"1.4039\",\"111156.2\"],[\"1.4040\",\"82136.4\"],[\"1.4041\",\"95943.6\"],[\"1.4042\",\"71971.3\"],[\"1.4043\",\"95420.5\"],[\"1.4044\",\"75287.7\"],[\"1.4045\",\"72375.5\"],[\"1.4046\",\"68201.4\"],[\"1.4047\",\"66919.6\"],[\"1.4048\",\"59113.1\"],[\"1.4049\",\"53669.4\"],[\"1.4050\",\"69854.0\"],[\"1.4051\",\"71244.4\"],[\"1.4052\",\"93984.3\"],[\"1.4053\",\"69752.5\"],[\"1.4054\",\"123960.8\"],[\"1.4055\",\"71713.1\"],[\"1.4056\",\"83187.3\"],[\"1.4057\",\"61602.3\"],[\"1.4058\",\"59897.9\"],[\"1.4059\",\"73164.9\"],[\"1.4060\",\"83468.2\"],[\"1.4061\",\"55061.8\"],[\"1.4062\",\"79929.0\"],[\"1.4063\",\"112970.5\"],[\"1.4066\",\"63321.1\"],[\"1.4067\",\"147800.5\"],[\"1.4069\",\"143633.3\"],[\"1.4070\",\"29989.9\"],[\"1.4071\",\"75658.1\"],[\"1.4074\",\"151752.0\"],[\"1.4078\",\"69729.4\"],[\"1.4079\",\"193057.5\"],[\"1.4080\",\"29927.5\"],[\"1.4097\",\"355668.9\"],[\"1.4098\",\"481371.3\"],[\"1.4105\",\"63024.5\"],[\"1.4108\",\"28258.1\"],[\"1.4111\",\"27292.4\"],[\"1.4113\",\"37081.0\"],[\"1.4114\",\"35509.8\"],[\"1.4115\",\"28314.1\"],[\"1.4119\",\"33493.4\"],[\"1.4120\",\"380733.5\"],[\"1.4121\",\"93613.6\"],[\"1.4124\",\"256461.0\"],[\"1.4125\",\"19098.4\"],[\"1.5037\",\"0\"]],\"u\":9831416,\"seq\":241267309538},\"cts\":1778927726097}"}
{"ts":1778927726427,"data":"{\"topic\":\"orderbook.1000.XRPUSDT\",\"type\":\"delta\",\"ts\":1778927726303,\"data\":{\"s\":\"XRPUSDT\",\"b\":[[\"1.4034\",\"82924.8\"],[\"1.4033\",\"45534.9\"],[\"1.4032\",\"48530.0\"],[\"1.4031\",\"36257.5\"],[\"1.4027\",\"29340.2\"],[\"1.4026\",\"44355.8\"],[\"1.4024\",\"55485.0\"],[\"1.4018\",\"49024.9\"],[\"1.4015\",\"69212.2\"],[\"1.4011\",\"178223.3\"],[\"1.4010\",\"85804.3\"],[\"1.4000\",\"37896.9\"]],\"a\":[[\"1.4037\",\"25972.3\"],[\"1.4038\",\"57182.3\"],[\"1.4039\",\"102053.2\"],[\"1.4040\",\"81657.4\"],[\"1.4044\",\"75285.4\"],[\"1.4047\",\"67103.1\"],[\"1.4050\",\"78825.3\"],[\"1.4051\",\"71248.4\"],[\"1.4053\",\"69744.0\"],[\"1.4054\",\"130137.5\"],[\"1.4063\",\"103062.3\"]],\"u\":9831417,\"seq\":241267309864},\"cts\":1778927726296}"}
{"ts":1778927726627,"data":"{\"topic\":\"orderbook.1000.XRPUSDT\",\"type\":\"delta\",\"ts\":1778927726503,\"data\":{\"s\":\"XRPUSDT\",\"b\":[[\"1.4037\",\"46977.7\"],[\"1.4036\",\"28200.3\"],[\"1.4035\",\"14728.6\"],[\"1.4033\",\"47102.1\"],[\"1.4030\",\"28478.7\"],[\"1.4029\",\"31794.2\"],[\"1.4026\",\"46866.6\"],[\"1.4025\",\"57599.2\"],[\"1.4024\",\"51561.4\"],[\"1.4021\",\"48256.5\"],[\"1.4020\",\"54497.8\"],[\"1.4019\",\"49961.7\"],[\"1.4017\",\"60186.4\"],[\"1.4013\",\"79822.7\"],[\"1.4011\",\"167360.9\"],[\"1.4010\",\"81966.6\"],[\"1.4009\",\"72249.9\"],[\"1.4007\",\"49423.1\"],[\"1.4002\",\"48936.4\"],[\"1.4000\",\"32645.8\"],[\"1.3997\",\"20986.6\"],[\"1.3996\",\"33873.5\"],[\"1.3957\",\"43741.8\"],[\"1.3952\",\"378812.6\"],[\"1.3037\",\"0\"]],\"a\":[[\"1.4037\",\"0\"],[\"1.4038\",\"14536.6\"],[\"1.4039\",\"49816.8\"],[\"1.4040\",\"54837.1\"],[\"1.4041\",\"62165.7\"],[\"1.4042\",\"45145.6\"],[\"1.4043\",\"68501.0\"],[\"1.4044\",\"71774.7\"],[\"1.4045\",\"72379.1\"],[\"1.4046\",\"68927.2\"],[\"1.4047\",\"56320.3\"],[\"1.4048\",\"59065.0\"],[\"1.4049\",\"51235.8\"],[\"1.4050\",\"78075.5\"],[\"1.4060\",\"83326.4\"],[\"1.4067\",\"158546.8\"],[\"1.4071\",\"51870.6\"],[\"1.4105\",\"39237.0\"],[\"1.5037\",\"137.8\"]],\"u\":9831418,\"seq\":241267310309},\"cts\":1778927726502}"}
{"ts":1778927726828,"data":"{\"topic\":\"orderbook.1000.XRPUSDT\",\"type\":\"delta\",\"ts\":1778927726703,\"data\":{\"s\":\"XRPUSDT\",\"b\":[[\"1.4040\",\"40881.1\"],[\"1.4039\",\"34208.5\"],[\"1.4038\",\"117108.6\"],[\"1.4037\",\"83605.6\"],[\"1.4036\",\"69248.4\"],[\"1.4035\",\"85616.8\"],[\"1.4034\",\"74265.4\"],[\"1.4033\",\"44543.2\"],[\"1.4032\",\"43398.1\"],[\"1.4031\",\"37097.7\"],[\"1.4030\",\"39297.0\"],[\"1.4029\",\"36856.9\"],[\"1.4028\",\"34280.0\"],[\"1.4027\",\"39397.6\"],[\"1.4026\",\"48882.3\"],[\"1.4025\",\"57298.3\"],[\"1.4024\",\"45207.8\"],[\"1.4023\",\"50654.1\"],[\"1.4022\",\"47372.8\"],[\"1.4021\",\"40171.6\"],[\"1.4020\",\"60472.9\"],[\"1.4019\",\"39144.2\"],[\"1.4018\",\"59440.4\"],[\"1.4017\",\"83706.2\"],[\"1.4016\",\"133199.1\"],[\"1.4015\",\"119027.8\"],[\"1.4014\",\"303356.2\"],[\"1.4013\",\"195703.7\"],[\"1.4012\",\"67736.0\"],[\"1.4011\",\"79750.1\"],[\"1.4010\",\"85594.8\"],[\"1.4009\",\"60186.1\"],[\"1.4008\",\"74700.8\"],[\"1.4007\",\"49373.0\"],[\"1.4006\",\"65125.3\"],[\"1.4004\",\"45733.1\"],[\"1.4003\",\"272897.9\"],[\"1.4002\",\"44056.3\"],[\"1.4001\",\"159533.8\"],[\"1.4000\",\"270742.1\"],[\"1.3999\",\"23280.5\"],[\"1.3998\",\"62409.4\"],[\"1.3996\",\"35126.7\"],[\"1.3989\",\"43474.9\"],[\"1.3988\",\"234341.3\"],[\"1.3979\",\"189542.2\"],[\"1.3976\",\"28044.2\"],[\"1.3973\",\"45785.0\"],[\"1.3965\",\"28907.4\"],[\"1.3964\",\"33976.2\"],[\"1.3963\",\"31359.4\"],[\"1.3962\",\"35887.3\"],[\"1.3961\",\"17289.9\"],[\"1.3040\",\"0\"],[\"1.3039\",\"0\"],[\"1.3038\",\"0\"]],\"a\":[[\"1.4038\",\"0\"],[\"1.4039\",\"0\"],[\"1.4040\",\"0\"],[\"1.4041\",\"18398.3\"],[\"1.4042\",\"10103.5\"],[\"1.4043\",\"31057.5\"],[\"1.4044\",\"73870.9\"],[\"1.4045\",\"63791.2\"],[\"1.4046\",\"59571.7\"],[\"1.4047\",\"50532.8\"],[\"1.4048\",\"47035.4\"],[\"1.4049\",\"68113.8\"],[\"1.4050\",\"82627.3\"],[\"1.4051\",\"76298.6\"],[\"1.4052\",\"63328.5\"],[\"1.4053\",\"66868.0\"],[\"1.4054\",\"58443.8\"],[\"1.4055\",\"79917.9\"],[\"1.4056\",\"75096.8\"],[\"1.4057\",\"66167.2\"],[\"1.4058\",\"68031.3\"],[\"1.4059\",\"72854.1\"],[\"1.4060\",\"91303.4\"],[\"1.4061\",\"98957.9\"],[\"1.4062\",\"136922.3\"],[\"1.4064\",\"103482.2\"],[\"1.4065\",\"195024.0\"],[\"1.4066\",\"54653.2\"],[\"1.4067\",\"112034.1\"],[\"1.4068\",\"239752.8\"],[\"1.4069\",\"61635.0\"],[\"1.4070\",\"49079.6\"],[\"1.4071\",\"70934.0\"],[\"1.4072\",\"99424.5\"],[\"1.4073\",\"152509.1\"],[\"1.4074\",\"239362.8\"],[\"1.4075\",\"482754.5\"],[\"1.4078\",\"70662.0\"],[\"1.4079\",\"192205.7\"],[\"1.4083\",\"32315.6\"],[\"1.4098\",\"196620.9\"],[\"1.4101\",\"106670.8\"],[\"1.4104\",\"68982.4\"],[\"1.4106\",\"54827.7\"],[\"1.4108\",\"27903.6\"],[\"1.4113\",\"37088.2\"],[\"1.4114\",\"35517.0\"],[\"1.4115\",\"28321.3\"],[\"1.4116\",\"26956.6\"],[\"1.4119\",\"40026.2\"],[\"1.4120\",\"387266.3\"],[\"1.4121\",\"100146.4\"],[\"1.4122\",\"58386.3\"],[\"1.4123\",\"17356.3\"],[\"1.4125\",\"200.3\"],[\"1.4129\",\"22187.6\"],[\"1.4175\",\"1306.4\"],[\"1.4178\",\"132.5\"],[\"1.5038\",\"51.1\"],[\"1.5039\",\"460.4\"],[\"1.5040\",\"5013.4\"]],\"u\":9831419,\"seq\":241267312865},\"cts\":1778927726700}"}
{"ts":1778927727047,"data":"{\"topic\":\"orderbook.1000.XRPUSDT\",\"type\":\"delta\",\"ts\":1778927726903,\"data\":{\"s\":\"XRPUSDT\",\"b\":[[\"1.4039\",\"34189.5\"],[\"1.4038\",\"127909.0\"],[\"1.4037\",\"71339.1\"],[\"1.4036\",\"69213.0\"],[\"1.4035\",\"79819.9\"],[\"1.4031\",\"37026.5\"],[\"1.4021\",\"42413.6\"],[\"1.4020\",\"58311.2\"],[\"1.4019\",\"42356.3\"],[\"1.4018\",\"59451.3\"],[\"1.4015\",\"115711.7\"],[\"1.4012\",\"73643.7\"],[\"1.4011\",\"85991.4\"],[\"1.4008\",\"94005.2\"],[\"1.4007\",\"43215.8\"],[\"1.4006\",\"46030.8\"],[\"1.3997\",\"30281.0\"],[\"1.3992\",\"37822.9\"]],\"a\":[[\"1.4041\",\"17198.3\"],[\"1.4042\",\"10032.3\"],[\"1.4043\",\"17359.7\"],[\"1.4044\",\"69301.6\"],[\"1.4045\",\"70201.1\"],[\"1.4046\",\"59591.6\"],[\"1.4047\",\"51244.8\"],[\"1.4048\",\"46323.4\"],[\"1.4049\",\"68181.2\"],[\"1.4050\",\"76758.8\"],[\"1.4051\",\"72955.7\"],[\"1.4054\",\"58511.2\"],[\"1.4055\",\"85877.3\"],[\"1.4057\",\"70435.7\"],[\"1.4058\",\"75920.2\"],[\"1.4059\",\"114648.0\"],[\"1.4060\",\"140319.7\"],[\"1.4061\",\"61114.8\"],[\"1.4062\",\"79929.0\"],[\"1.4064\",\"103493.1\"],[\"1.4074\",\"244861.9\"],[\"1.4108\",\"27899.1\"],[\"1.4121\",\"100150.9\"],[\"1.4125\",\"19210.3\"],[\"1.4384\",\"2925.2\"]],\"u\":9831420,\"seq\":241267313196},\"cts\":1778927726898}"}
{"ts":1778927727228,"data":"{\"topic\":\"orderbook.1000.XRPUSDT\",\"type\":\"delta\",\"ts\":1778927727104,\"data\":{\"s\":\"XRPUSDT\",\"b\":[[\"1.4039\",\"41141.7\"],[\"1.4038\",\"122902.1\"],[\"1.4037\",\"76196.7\"],[\"1.4035\",\"70478.8\"],[\"1.4034\",\"63065.4\"],[\"1.4033\",\"44543.3\"],[\"1.4031\",\"37022.8\"],[\"1.4030\",\"44976.3\"],[\"1.4029\",\"37006.9\"],[\"1.4025\",\"57147.8\"],[\"1.4012\",\"75133.7\"],[\"1.4001\",\"183321.3\"],[\"1.3998\",\"38621.9\"],[\"1.3995\",\"207025.6\"],[\"1.3991\",\"25300.8\"],[\"1.3962\",\"59674.8\"],[\"1.3956\",\"6546.3\"],[\"1.3955\",\"77830.0\"],[\"1.3952\",\"355025.1\"],[\"1.3951\",\"779.0\"],[\"1.3933\",\"32765.1\"],[\"1.3842\",\"453106.6\"],[\"1.3839\",\"335156.5\"],[\"1.3836\",\"405013.6\"]],\"a\":[[\"1.4041\",\"12261.9\"],[\"1.4043\",\"30812.2\"],[\"1.4044\",\"66386.4\"],[\"1.4046\",\"63196.3\"],[\"1.4049\",\"68184.9\"],[\"1.4051\",\"65389.2\"],[\"1.4055\",\"86031.3\"],[\"1.4065\",\"195019.5\"],[\"1.4069\",\"61639.5\"],[\"1.4071\",\"66144.2\"],[\"1.4072\",\"75637.0\"],[\"1.4076\",\"59871.9\"],[\"1.4106\",\"31040.2\"],[\"1.4112\",\"271183.8\"],[\"1.4123\",\"7229.9\"],[\"1.4147\",\"38294.6\"],[\"1.4242\",\"367127.6\"],[\"1.4245\",\"435182.9\"],[\"1.4248\",\"348515.2\"]],\"u\":9831421,\"seq\":241267313378},\"cts\":1778927727102}"}
{"ts":1778927727427,"data":"{\"topic\":\"orderbook.1000.XRPUSDT\",\"type\":\"delta\",\"ts\":1778927727303,\"data\":{\"s\":\"XRPUSDT\",\"b\":[[\"1.4040\",\"48481.1\"],[\"1.4039\",\"73940.2\"],[\"1.4038\",\"127913.0\"],[\"1.4037\",\"72763.5\"],[\"1.4035\",\"70703.8\"],[\"1.4034\",\"63421.6\"],[\"1.4033\",\"44187.0\"],[\"1.4028\",\"34283.6\"],[\"1.4025\",\"58014.2\"],[\"1.4022\",\"49548.4\"],[\"1.4021\",\"40171.6\"],[\"1.4010\",\"85598.4\"],[\"1.4008\",\"91963.6\"],[\"1.4006\",\"40249.7\"],[\"1.4003\",\"272894.3\"],[\"1.3997\",\"39643.0\"],[\"1.3992\",\"28588.4\"],[\"1.3966\",\"87716.3\"],[\"1.3787\",\"16012.2\"]],\"a\":[[\"1.4041\",\"69.3\"],[\"1.4043\",\"10054.5\"],[\"1.4044\",\"29197.4\"],[\"1.4045\",\"50442.3\"],[\"1.4046\",\"84764.0\"],[\"1.4047\",\"50532.8\"],[\"1.4048\",\"47035.4\"],[\"1.4049\",\"64557.1\"],[\"1.4050\",\"80319.0\"],[\"1.4053\",\"62812.8\"],[\"1.4058\",\"68031.3\"],[\"1.4059\",\"72854.1\"],[\"1.4060\",\"130113.1\"],[\"1.4061\",\"118108.1\"],[\"1.4074\",\"250126.8\"],[\"1.4077\",\"42695.5\"]],\"u\":9831422,\"seq\":241267313841},\"cts\":1778927727298}"}
{"ts":1778927727628,"data":"{\"topic\":\"orderbook.1000.XRPUSDT\",\"type\":\"delta\",\"ts\":1778927727504,\"data\":{\"s\":\"XRPUSDT\",\"b\":[[\"1.4038\",\"127916.6\"],[\"1.4037\",\"72784.5\"],[\"1.4036\",\"70587.6\"],[\"1.3977\",\"423041.8\"],[\"1.3972\",\"283622.6\"],[\"1.3961\",\"17286.3\"],[\"1.3958\",\"18939.5\"],[\"1.3933\",\"32647.1\"],[\"1.3842\",\"40921.9\"],[\"1.3839\",\"4049.3\"],[\"1.3836\",\"26330.0\"]],\"a\":[[\"1.4045\",\"64888.1\"],[\"1.4046\",\"70318.2\"],[\"1.4051\",\"65539.2\"],[\"1.4055\",\"85881.3\"],[\"1.4147\",\"38148.3\"],[\"1.4242\",\"300.8\"],[\"1.4245\",\"34319.7\"],[\"1.4248\",\"38912.2\"],[\"1.4377\",\"17758.0\"]],\"u\":9831423,\"seq\":241267314071},\"cts\":1778927727501}"}
{"ts":1778927727830,"data":"{\"topic\":\"orderbook.1000.XRPUSDT\",\"type\":\"delta\",\"ts\":1778927727703,\"data\":{\"s\":\"XRPUSDT\",\"b\":[[\"1.4039\",\"73872.8\"],[\"1.4037\",\"72855.6\"],[\"1.4032\",\"44815.3\"],[\"1.4030\",\"50057.3\"],[\"1.4029\",\"37257.5\"],[\"1.4025\",\"58085.4\"],[\"1.4024\",\"45380.0\"],[\"1.4021\",\"40239.0\"],[\"1.4014\",\"233101.3\"],[\"1.4012\",\"97155.7\"],[\"1.4011\",\"162297.5\"],[\"1.4008\",\"97161.8\"],[\"1.4001\",\"44046.4\"],[\"1.3998\",\"177926.4\"],[\"1.3995\",\"207183.6\"],[\"1.3987\",\"44773.2\"],[\"1.3986\",\"213510.7\"],[\"1.3979\",\"59884.0\"],[\"1.3976\",\"155029.4\"]],\"a\":[[\"1.4041\",\"89.7\"],[\"1.4043\",\"10125.7\"],[\"1.4044\",\"54231.4\"],[\"1.4045\",\"85030.5\"],[\"1.4046\",\"63249.5\"],[\"1.4048\",\"47039.1\"],[\"1.4050\",\"80322.7\"],[\"1.4058\",\"75920.2\"],[\"1.4059\",\"101350.7\"],[\"1.4060\",\"101616.5\"],[\"1.4071\",\"77837.8\"],[\"1.4072\",\"118322.4\"],[\"1.4073\",\"48291.4\"],[\"1.4076\",\"36084.4\"],[\"1.4077\",\"36511.7\"],[\"1.4079\",\"215993.2\"],[\"1.4084\",\"182533.6\"],[\"1.4086\",\"72143.5\"],[\"1.4087\",\"69963.4\"],[\"1.4088\",\"75549.9\"],[\"1.4107\",\"109207.9\"],[\"1.4109\",\"26816.1\"],[\"1.4112\",\"247396.3\"],[\"1.4116\",\"50744.1\"],[\"1.4376\",\"25901.8\"]],\"u\":9831424,\"seq\":241267314258},\"cts\":1778927727696}"}
{"ts":1778927728027,"data":"{\"topic\":\"orderbook.1000.XRPUSDT\",\"type\":\"delta\",\"ts\":1778927727903,\"data\":{\"s\":\"XRPUSDT\",\"b\":[[\"1.4039\",\"73893.5\"],[\"1.4037\",\"72835.4\"],[\"1.4033\",\"47748.1\"],[\"1.4031\",\"37094.0\"],[\"1.4030\",\"46496.2\"],[\"1.4029\",\"37107.5\"],[\"1.4017\",\"83856.2\"],[\"1.4012\",\"75133.7\"],[\"1.4011\",\"85991.4\"],[\"1.3998\",\"38621.9\"],[\"1.3988\",\"234344.9\"],[\"1.3986\",\"213507.1\"],[\"1.3976\",\"28044.2\"],[\"1.3786\",\"4072.2\"]],\"a\":[[\"1.4043\",\"10551.5\"],[\"1.4045\",\"70677.1\"],[\"1.4046\",\"70371.4\"],[\"1.4051\",\"65389.2\"],[\"1.4071\",\"66144.2\"],[\"1.4072\",\"39323.5\"],[\"1.4084\",\"44080.6\"],[\"1.4107\",\"48104.0\"]],\"u\":9831425,\"seq\":241267314665},\"cts\":1778927727891}"}
{"ts":1778927728227,"data":"{\"topic\":\"orderbook.1000.XRPUSDT\",\"type\":\"delta\",\"ts\":1778927728103,\"data\":{\"s\":\"XRPUSDT\",\"b\":[[\"1.4040\",\"40875.3\"],[\"1.4039\",\"34210.2\"],[\"1.4038\",\"116481.5\"],[\"1.4037\",\"66629.9\"],[\"1.4035\",\"63751.6\"],[\"1.4034\",\"63065.4\"],[\"1.4030\",\"32166.9\"],[\"1.4028\",\"34280.0\"],[\"1.4027\",\"39401.2\"],[\"1.4022\",\"47372.8\"],[\"1.4021\",\"42413.7\"],[\"1.4012\",\"97155.7\"],[\"1.4011\",\"162297.5\"],[\"1.4008\",\"97440.9\"],[\"1.4006\",\"45998.5\"],[\"1.3998\",\"177926.5\"],[\"1.3988\",\"234341.3\"],[\"1.3987\",\"44776.8\"],[\"1.3976\",\"154974.6\"],[\"1.3958\",\"8796.8\"],[\"1.3957\",\"33599.1\"]],\"a\":[[\"1.4041\",\"6916.2\"],[\"1.4043\",\"37520.4\"],[\"1.4044\",\"64380.3\"],[\"1.4045\",\"77799.0\"],[\"1.4046\",\"63249.5\"],[\"1.4049\",\"64553.4\"],[\"1.4051\",\"76156.9\"],[\"1.4059\",\"114648.0\"],[\"1.4060\",\"140319.7\"],[\"1.4061\",\"61114.8\"],[\"1.4071\",\"88839.9\"],[\"1.4072\",\"118364.4\"],[\"1.4074\",\"244861.9\"],[\"1.4084\",\"182534.1\"],[\"1.4107\",\"102306.1\"]],\"u\":9831426,\"seq\":241267314916},\"cts\":1778927728101}"}
{"ts":1778927728428,"data":"{\"topic\":\"orderbook.1000.XRPUSDT\",\"type\":\"delta\",\"ts\":1778927728304,\"data\":{\"s\":\"XRPUSDT\",\"b\":[[\"1.4039\",\"65216.0\"],[\"1.4037\",\"65045.7\"],[\"1.4036\",\"69213.0\"],[\"1.4033\",\"48104.3\"],[\"1.4031\",\"37022.8\"],[\"1.4029\",\"40673.1\"],[\"1.4025\",\"57215.4\"],[\"1.4023\",\"51374.1\"],[\"1.4002\",\"42718.5\"],[\"1.4001\",\"45180.6\"],[\"1.3872\",\"21282.8\"]],\"a\":[[\"1.4041\",\"13583.3\"],[\"1.4042\",\"10103.5\"],[\"1.4043\",\"41174.5\"],[\"1.4044\",\"67288.0\"],[\"1.4045\",\"71571.5\"],[\"1.4046\",\"59644.8\"],[\"1.4047\",\"51244.8\"],[\"1.4048\",\"46327.1\"],[\"1.4053\",\"62880.2\"],[\"1.4055\",\"85885.8\"],[\"1.4056\",\"75092.3\"],[\"1.4070\",\"50218.5\"],[\"1.4071\",\"87546.0\"],[\"1.4074\",\"239362.8\"],[\"1.4081\",\"273468.8\"],[\"1.4083\",\"31463.9\"],[\"1.4273\",\"28127.9\"]],\"u\":9831427,\"seq\":241267315273},\"cts\":1778927728297}"}
{"ts":1778927728627,"data":"{\"topic\":\"orderbook.1000.XRPUSDT\",\"type\":\"delta\",\"ts\":1778927728503,\"data\":{\"s\":\"XRPUSDT\",\"b\":[[\"1.4039\",\"34215.0\"],[\"1.4037\",\"65444.1\"],[\"1.3933\",\"325918.0\"],[\"1.3930\",\"433241.7\"],[\"1.3927\",\"334372.8\"]],\"a\":[[\"1.4042\",\"10107.1\"],[\"1.4043\",\"47705.4\"],[\"1.4049\",\"68113.8\"],[\"1.4050\",\"76762.5\"],[\"1.4057\",\"70432.0\"],[\"1.4069\",\"61643.1\"],[\"1.4150\",\"356629.2\"],[\"1.4153\",\"294030.7\"],[\"1.4156\",\"369222.5\"]],\"u\":9831428,\"seq\":241267315422},\"cts\":1778927728500}"}
{"ts":1778927728828,"data":"{\"topic\":\"orderbook.1000.XRPUSDT\",\"type\":\"delta\",\"ts\":1778927728703,\"data\":{\"s\":\"XRPUSDT\",\"b\":[[\"1.4039\",\"34210.2\"],[\"1.4037\",\"67582.2\"],[\"1.4027\",\"39397.6\"],[\"1.4026\",\"48885.9\"]],\"a\":[[\"1.4042\",\"10035.9\"],[\"1.4043\",\"27335.0\"],[\"1.4044\",\"56150.2\"],[\"1.4045\",\"75174.4\"],[\"1.4053\",\"62883.9\"],[\"1.4059\",\"101350.7\"],[\"1.4060\",\"101616.5\"],[\"1.4061\",\"118108.1\"]],\"u\":9831429,\"seq\":241267315526},\"cts\":1778927728686}"}
{"ts":1778927729027,"data":"{\"topic\":\"orderbook.1000.XRPUSDT\",\"type\":\"delta\",\"ts\":1778927728903,\"data\":{\"s\":\"XRPUSDT\",\"b\":[[\"1.4040\",\"11637.5\"],[\"1.4039\",\"22323.1\"],[\"1.4038\",\"63299.0\"],[\"1.4037\",\"60901.8\"],[\"1.4036\",\"73351.2\"],[\"1.4033\",\"42760.9\"],[\"1.4032\",\"37685.7\"],[\"1.4031\",\"34868.3\"],[\"1.4028\",\"31700.7\"],[\"1.4027\",\"34290.2\"],[\"1.4026\",\"54000.5\"],[\"1.4011\",\"162428.1\"],[\"1.4009\",\"60179.0\"],[\"1.4006\",\"45991.4\"],[\"1.4004\",\"56497.1\"],[\"1.4001\",\"21393.1\"],[\"1.4000\",\"294529.6\"],[\"1.3994\",\"43696.2\"],[\"1.3967\",\"33383.6\"],[\"1.3966\",\"87000.3\"],[\"1.3962\",\"35887.3\"],[\"1.3961\",\"41073.8\"],[\"1.3946\",\"402218.4\"],[\"1.3943\",\"458757.1\"],[\"1.3940\",\"395098.9\"],[\"1.3933\",\"32647.1\"],[\"1.3930\",\"19874.6\"],[\"1.3927\",\"603.4\"]],\"a\":[[\"1.4041\",\"36426.9\"],[\"1.4042\",\"22553.4\"],[\"1.4043\",\"51148.2\"],[\"1.4044\",\"66289.4\"],[\"1.4046\",\"60205.5\"],[\"1.4048\",\"53012.7\"],[\"1.4049\",\"74110.5\"],[\"1.4059\",\"114648.0\"],[\"1.4060\",\"140319.7\"],[\"1.4061\",\"61114.8\"],[\"1.4071\",\"87403.5\"],[\"1.4072\",\"113162.9\"],[\"1.4073\",\"42738.0\"],[\"1.4075\",\"506542.0\"],[\"1.4079\",\"192256.7\"],[\"1.4109\",\"50603.6\"],[\"1.4116\",\"27311.1\"],[\"1.4129\",\"21833.1\"],[\"1.4133\",\"390554.9\"],[\"1.4136\",\"360220.3\"],[\"1.4139\",\"658851.9\"],[\"1.4150\",\"12834.8\"],[\"1.4153\",\"8894.6\"],[\"1.4156\",\"14539.2\"]],\"u\":9831430,\"seq\":241267315921},\"cts\":1778927728902}"}
{"ts":1778927729227,"data":"{\"topic\":\"orderbook.1000.XRPUSDT\",\"type\":\"delta\",\"ts\":1778927729103,\"data\":{\"s\":\"XRPUSDT\",\"b\":[[\"1.4039\",\"22316.7\"],[\"1.4038\",\"104343.1\"],[\"1.4037\",\"79884.3\"],[\"1.4032\",\"36624.8\"],[\"1.4031\",\"34512.0\"],[\"1.4030\",\"35728.0\"],[\"1.4029\",\"40422.5\"],[\"1.4026\",\"53996.9\"],[\"1.4025\",\"57219.0\"],[\"1.4020\",\"58307.2\"],[\"1.4018\",\"59455.3\"],[\"1.4017\",\"83706.2\"],[\"1.4010\",\"85594.8\"],[\"1.4009\",\"60182.6\"],[\"1.4008\",\"78136.5\"],[\"1.4007\",\"62359.8\"],[\"1.4004\",\"51210.3\"],[\"1.4001\",\"21543.1\"],[\"1.3994\",\"43410.4\"],[\"1.3897\",\"825.6\"]],\"a\":[[\"1.4041\",\"40796.6\"],[\"1.4042\",\"32466.9\"],[\"1.4043\",\"75212.0\"],[\"1.4044\",\"79494.6\"],[\"1.4045\",\"58038.9\"],[\"1.4047\",\"54805.9\"],[\"1.4053\",\"62888.4\"],[\"1.4055\",\"85881.3\"],[\"1.4056\",\"82195.6\"],[\"1.4058\",\"104416.8\"],[\"1.4059\",\"129847.4\"],[\"1.4060\",\"83326.4\"],[\"1.4072\",\"113159.2\"],[\"1.4085\",\"38112.5\"],[\"1.4087\",\"69958.9\"],[\"1.4106\",\"31033.1\"]],\"u\":9831431,\"seq\":241267316147},\"cts\":1778927729101}"}
{"ts":1778927729429,"data":"{\"topic\":\"orderbook.1000.XRPUSDT\",\"type\":\"delta\",\"ts\":1778927729303,\"data\":{\"s\":\"XRPUSDT\",\"b\":[[\"1.4040\",\"11632.2\"],[\"1.4037\",\"74151.8\"],[\"1.4036\",\"73354.8\"],[\"1.4025\",\"57147.8\"],[\"1.4024\",\"45207.8\"],[\"1.4010\",\"85598.4\"],[\"1.4009\",\"60107.7\"],[\"1.4007\",\"62217.1\"],[\"1.3897\",\"818.5\"]],\"a\":[[\"1.4041\",\"41222.4\"],[\"1.4043\",\"74786.2\"],[\"1.4049\",\"70549.4\"],[\"1.4054\",\"58514.9\"],[\"1.4056\",\"75092.3\"],[\"1.4057\",\"79506.5\"],[\"1.4106\",\"31040.2\"]],\"u\":9831432,\"seq\":241267316252},\"cts\":1778927729296}"}
{"ts":1778927729627,"data":"{\"topic\":\"orderbook.1000.XRPUSDT\",\"type\":\"delta\",\"ts\":1778927729503,\"data\":{\"s\":\"XRPUSDT\",\"b\":[[\"1.4039\",\"22320.3\"],[\"1.4038\",\"110115.8\"],[\"1.4036\",\"73358.4\"],[\"1.4031\",\"33087.6\"],[\"1.4025\",\"57005.4\"],[\"1.4021\",\"40239.0\"],[\"1.4020\",\"60467.7\"],[\"1.4015\",\"115715.3\"],[\"1.4013\",\"195707.3\"],[\"1.4011\",\"162356.8\"],[\"1.4001\",\"21539.5\"],[\"1.4000\",\"270735.0\"],[\"1.3999\",\"47071.6\"],[\"1.3966\",\"86284.3\"],[\"1.3961\",\"17286.3\"],[\"1.3957\",\"57386.6\"]],\"a\":[[\"1.4041\",\"41225.7\"],[\"1.4042\",\"32463.3\"],[\"1.4043\",\"74782.6\"],[\"1.4056\",\"75088.7\"]],\"u\":9831433,\"seq\":241267316392},\"cts\":1778927729499}"}
{"ts":1778927729827,"data":"{\"topic\":\"orderbook.1000.XRPUSDT\",\"type\":\"delta\",\"ts\":1778927729703,\"data\":{\"s\":\"XRPUSDT\",\"b\":[[\"1.4039\",\"22325.1\"],[\"1.4037\",\"68379.1\"],[\"1.4009\",\"60100.6\"],[\"1.4001\",\"21539.6\"],[\"1.3690\",\"4045.8\"]],\"a\":[[\"1.4045\",\"58042.5\"],[\"1.4057\",\"79577.4\"],[\"1.4079\",\"192355.7\"]],\"u\":9831434,\"seq\":241267316539},\"cts\":1778927729701}"}
{"ts":1778927730027,"data":"{\"topic\":\"orderbook.1000.XRPUSDT\",\"type\":\"delta\",\"ts\":1778927729903,\"data\":{\"s\":\"XRPUSDT\",\"b\":[[\"1.4040\",\"177.0\"],[\"1.4039\",\"17790.4\"],[\"1.4038\",\"34140.3\"],[\"1.4037\",\"40662.9\"],[\"1.4036\",\"71983.5\"],[\"1.4035\",\"65890.0\"],[\"1.4032\",\"36268.5\"],[\"1.4031\",\"33443.9\"],[\"1.4028\",\"28134.9\"],[\"1.4027\",\"37856.2\"],[\"1.4026\",\"43232.9\"],[\"1.4025\",\"46247.8\"],[\"1.4023\",\"57905.0\"],[\"1.4011\",\"162349.7\"],[\"1.4004\",\"56497.1\"],[\"1.3999\",\"23287.7\"],[\"1.3997\",\"63430.5\"],[\"1.3957\",\"33599.1\"],[\"1.3954\",\"121764.6\"]],\"a\":[[\"1.4041\",\"38400.7\"],[\"1.4045\",\"68499.6\"],[\"1.4046\",\"60185.6\"],[\"1.4047\",\"72549.9\"],[\"1.4049\",\"71753.6\"],[\"1.4051\",\"75332.4\"],[\"1.4052\",\"55706.8\"],[\"1.4055\",\"85952.4\"],[\"1.4070\",\"44605.3\"],[\"1.4071\",\"82252.7\"]],\"u\":9831435,\"seq\":241267316735},\"cts\":1778927729902}"}
{"ts":1778927730227,"data":"{\"topic\":\"orderbook.1000.XRPUSDT\",\"type\":\"delta\",\"ts\":1778927730103,\"data\":{\"s\":\"XRPUSDT\",\"b\":[[\"1.4040\",\"59.1\"],[\"1.4039\",\"7776.1\"],[\"1.4038\",\"47774.7\"],[\"1.4037\",\"83722.7\"],[\"1.4036\",\"77752.5\"],[\"1.4035\",\"62665.0\"],[\"1.4034\",\"63069.0\"],[\"1.4033\",\"39551.4\"],[\"1.4031\",\"36236.4\"],[\"1.4030\",\"33573.5\"],[\"1.4026\",\"49128.2\"],[\"1.4025\",\"46244.2\"],[\"1.4024\",\"55971.8\"],[\"1.4023\",\"51549.9\"],[\"1.4022\",\"64667.7\"],[\"1.4021\",\"42749.8\"],[\"1.4020\",\"60465.8\"],[\"1.4018\",\"59451.3\"],[\"1.4017\",\"83710.2\"],[\"1.4010\",\"85594.8\"],[\"1.4008\",\"78143.8\"],[\"1.4007\",\"42930.4\"],[\"1.4006\",\"65219.8\"],[\"1.4001\",\"21539.1\"],[\"1.3987\",\"44773.2\"],[\"1.3986\",\"213510.7\"],[\"1.3946\",\"3032.2\"],[\"1.3943\",\"43031.7\"],[\"1.3940\",\"9202.1\"],[\"1.3684\",\"2649.2\"],[\"1.3650\",\"23198.9\"]],\"a\":[[\"1.4041\",\"41295.6\"],[\"1.4042\",\"32534.5\"],[\"1.4043\",\"88387.2\"],[\"1.4044\",\"62429.5\"],[\"1.4045\",\"65310.5\"],[\"1.4046\",\"69534.8\"],[\"1.4047\",\"69304.5\"],[\"1.4048\",\"53080.5\"],[\"1.4049\",\"71821.0\"],[\"1.4052\",\"58397.6\"],[\"1.4053\",\"62821.0\"],[\"1.4054\",\"58518.7\"],[\"1.4055\",\"86023.1\"],[\"1.4057\",\"99567.0\"],[\"1.4058\",\"68239.9\"],[\"1.4064\",\"103948.8\"],[\"1.4071\",\"87479.5\"],[\"1.4079\",\"192256.7\"],[\"1.4109\",\"50958.1\"],[\"1.4116\",\"26956.6\"],[\"1.4133\",\"1104.7\"],[\"1.4136\",\"3152.3\"],[\"1.4139\",\"359657.4\"]],\"u\":9831436,\"seq\":241267317023},\"cts\":1778927730100}"}
{"ts":1778927730428,"data":"{\"topic\":\"orderbook.1000.XRPUSDT\",\"type\":\"delta\",\"ts\":1778927730303,\"data\":{\"s\":\"XRPUSDT\",\"b\":[[\"1.4040\",\"8879.3\"],[\"1.4038\",\"70176.1\"],[\"1.4037\",\"77950.9\"],[\"1.4036\",\"66247.4\"],[\"1.4034\",\"62868.1\"],[\"1.4031\",\"36592.7\"],[\"1.4030\",\"33217.2\"],[\"1.4025\",\"46311.6\"],[\"1.4023\",\"45019.0\"],[\"1.4022\",\"58136.8\"],[\"1.4021\",\"42682.4\"],[\"1.4020\",\"60469.4\"],[\"1.4013\",\"195908.2\"],[\"1.4009\",\"60104.2\"],[\"1.4008\",\"78140.2\"],[\"1.3999\",\"23294.9\"],[\"1.3998\",\"201714.0\"],[\"1.3997\",\"39643.0\"],[\"1.3987\",\"44776.8\"],[\"1.3986\",\"213507.1\"],[\"1.3957\",\"57386.6\"],[\"1.3954\",\"97977.1\"]],\"a\":[[\"1.4041\",\"41296.6\"],[\"1.4042\",\"32463.3\"],[\"1.4047\",\"58540.1\"],[\"1.4048\",\"49519.4\"],[\"1.4058\",\"84635.0\"],[\"1.4071\",\"93016.7\"],[\"1.4082\",\"27909.6\"],[\"1.4392\",\"1811.7\"]],\"u\":9831437,\"seq\":241267317584},\"cts\":1778927730298}"}
{"ts":1778927730628,"data":"{\"topic\":\"orderbook.1000.XRPUSDT\",\"type\":\"delta\",\"ts\":1778927730504,\"data\":{\"s\":\"XRPUSDT\",\"b\":[[\"1.4040\",\"8861.7\"],[\"1.4038\",\"70175.9\"],[\"1.4037\",\"77950.7\"],[\"1.4024\",\"51953.3\"],[\"1.4023\",\"51549.9\"],[\"1.4020\",\"60473.0\"],[\"1.4010\",\"85598.4\"]],\"a\":[[\"1.4047\",\"58470.5\"],[\"1.4058\",\"125233.1\"],[\"1.4059\",\"72854.1\"],[\"1.4068\",\"239757.3\"],[\"1.4069\",\"61638.6\"]],\"u\":9831438,\"seq\":241267317814},\"cts\":1778927730500}"}
{"ts":1778927730828,"data":"{\"topic\":\"orderbook.1000.XRPUSDT\",\"type\":\"delta\",\"ts\":1778927730704,\"data\":{\"s\":\"XRPUSDT\",\"b\":[[\"1.4040\",\"77.4\"],[\"1.4039\",\"7771.3\"],[\"1.4038\",\"47489.7\"],[\"1.4037\",\"72218.4\"],[\"1.4036\",\"71979.7\"],[\"1.4033\",\"39776.4\"],[\"1.4031\",\"36236.4\"],[\"1.4030\",\"33573.5\"],[\"1.4026\",\"43232.9\"],[\"1.4011\",\"162219.1\"],[\"1.3999\",\"23298.5\"],[\"1.3998\",\"177926.5\"],[\"1.3997\",\"63430.5\"],[\"1.3957\",\"33599.1\"],[\"1.3954\",\"110319.7\"]],\"a\":[[\"1.4044\",\"66033.8\"],[\"1.4047\",\"66528.9\"],[\"1.4058\",\"68309.9\"],[\"1.4059\",\"129847.4\"],[\"1.4068\",\"239752.8\"],[\"1.4069\",\"61643.1\"],[\"1.4071\",\"87479.5\"]],\"u\":9831439,\"seq\":241267318012},\"cts\":1778927730701}"}
{"ts":1778927731027,"data":"{\"topic\":\"orderbook.1000.XRPUSDT\",\"type\":\"delta\",\"ts\":1778927730903,\"data\":{\"s\":\"XRPUSDT\",\"b\":[[\"1.4040\",\"0\"],[\"1.4039\",\"7889.8\"],[\"1.4038\",\"41714.3\"],[\"1.4037\",\"78227.7\"],[\"1.4036\",\"66247.4\"],[\"1.4035\",\"67665.0\"],[\"1.4034\",\"66705.8\"],[\"1.4032\",\"36275.7\"],[\"1.4026\",\"52202.9\"],[\"1.4022\",\"58493.4\"],[\"1.4020\",\"58300.0\"],[\"1.4019\",\"44521.3\"],[\"1.4017\",\"78094.6\"],[\"1.4013\",\"206673.0\"],[\"1.4004\",\"51210.3\"],[\"1.3999\",\"47093.2\"],[\"1.3997\",\"39643.0\"],[\"1.3958\",\"18934.8\"],[\"1.3956\",\"30333.8\"],[\"1.3955\",\"79263.1\"],[\"1.3954\",\"86532.2\"],[\"1.3618\",\"36588.5\"],[\"1.3040\",\"372.5\"]],\"a\":[[\"1.4040\",\"46716.7\"],[\"1.4041\",\"41773.2\"],[\"1.4042\",\"57049.8\"],[\"1.4043\",\"88316.1\"],[\"1.4044\",\"65667.7\"],[\"1.4046\",\"70984.6\"],[\"1.4047\",\"58541.6\"],[\"1.4048\",\"57837.1\"],[\"1.4053\",\"61370.9\"],[\"1.4054\",\"58522.7\"],[\"1.4055\",\"86019.1\"],[\"1.4057\",\"102689.2\"],[\"1.4058\",\"57459.7\"],[\"1.4067\",\"122798.9\"],[\"1.4074\",\"263150.3\"],[\"1.4075\",\"482754.5\"],[\"1.4087\",\"82402.2\"],[\"1.4108\",\"51686.6\"],[\"1.4109\",\"27170.6\"],[\"1.4116\",\"26949.4\"],[\"1.4161\",\"7836.6\"],[\"1.4608\",\"1089.9\"],[\"1.5040\",\"0\"]],\"u\":9831440,\"seq\":241267318259},\"cts\":1778927730901}"}
{"ts":1778927731228,"data":"{\"topic\":\"orderbook.1000.XRPUSDT\",\"type\":\"delta\",\"ts\":1778927731103,\"data\":{\"s\":\"XRPUSDT\",\"b\":[[\"1.4039\",\"21701.9\"],[\"1.4038\",\"41707.4\"],[\"1.4037\",\"83972.3\"],[\"1.4036\",\"73385.7\"],[\"1.4035\",\"60526.6\"],[\"1.4032\",\"36632.0\"],[\"1.4030\",\"35728.0\"],[\"1.4029\",\"47969.5\"],[\"1.4028\",\"31700.8\"],[\"1.4027\",\"43612.5\"],[\"1.4020\",\"60469.3\"],[\"1.4019\",\"42356.3\"],[\"1.4018\",\"59455.3\"],[\"1.4017\",\"78090.6\"],[\"1.4006\",\"59471.0\"],[\"1.4004\",\"45733.1\"],[\"1.3999\",\"47071.6\"],[\"1.3997\",\"39646.6\"],[\"1.3982\",\"354178.9\"],[\"1.3979\",\"386331.6\"],[\"1.3976\",\"533547.4\"],[\"1.3964\",\"33983.4\"],[\"1.3863\",\"7593.1\"],[\"1.3837\",\"8384.2\"],[\"1.3824\",\"33150.9\"],[\"1.3815\",\"27812.2\"],[\"1.3759\",\"50241.4\"]],\"a\":[[\"1.4040\",\"7585.8\"],[\"1.4041\",\"34658.2\"],[\"1.4042\",\"32474.2\"],[\"1.4043\",\"88308.4\"],[\"1.4044\",\"65596.5\"],[\"1.4047\",\"54662.6\"],[\"1.4048\",\"53073.0\"],[\"1.4049\",\"65825.0\"],[\"1.4050\",\"73201.4\"],[\"1.4051\",\"64568.4\"],[\"1.4052\",\"64259.8\"],[\"1.4053\",\"61366.4\"],[\"1.4055\",\"85877.3\"],[\"1.4056\",\"103587.4\"],[\"1.4057\",\"74051.0\"],[\"1.4058\",\"114245.5\"],[\"1.4059\",\"72854.1\"],[\"1.4064\",\"103954.4\"],[\"1.4068\",\"239757.3\"],[\"1.4069\",\"61638.6\"],[\"1.4072\",\"118697.2\"],[\"1.4073\",\"53502.8\"],[\"1.4082\",\"27913.2\"],[\"1.4099\",\"599242.7\"],[\"1.4101\",\"515978.2\"],[\"1.4104\",\"441085.6\"],[\"1.4115\",\"27112.4\"],[\"1.4119\",\"40030.7\"],[\"1.4121\",\"100146.4\"],[\"1.4122\",\"41727.1\"],[\"1.4141\",\"195699.3\"],[\"1.4154\",\"9329.9\"],[\"1.4264\",\"22178.3\"]],\"u\":9831441,\"seq\":241267318876},\"cts\":1778927731099}"}
{"ts":1778927731427,"data":"{\"topic\":\"orderbook.1000.XRPUSDT\",\"type\":\"delta\",\"ts\":1778927731303,\"data\":{\"s\":\"XRPUSDT\",\"b\":[[\"1.4039\",\"16326.9\"],[\"1.4033\",\"39775.4\"],[\"1.4032\",\"36275.7\"],[\"1.4031\",\"36592.7\"],[\"1.4029\",\"40422.5\"],[\"1.4009\",\"60103.2\"],[\"1.4006\",\"59471.2\"],[\"1.4005\",\"46180.4\"],[\"1.4001\",\"21538.7\"],[\"1.4000\",\"294522.5\"],[\"1.3999\",\"23284.1\"],[\"1.3998\",\"438880.2\"],[\"1.3993\",\"43704.5\"],[\"1.3971\",\"61038.6\"],[\"1.3967\",\"33376.5\"],[\"1.3960\",\"45293.9\"],[\"1.3958\",\"18931.2\"],[\"1.3956\",\"6546.3\"]],\"a\":[[\"1.4040\",\"17244.0\"],[\"1.4041\",\"34729.4\"],[\"1.4042\",\"73663.8\"],[\"1.4043\",\"81077.5\"],[\"1.4050\",\"83966.2\"],[\"1.4052\",\"64255.3\"],[\"1.4053\",\"61370.9\"],[\"1.4054\",\"58451.5\"],[\"1.4056\",\"75088.7\"],[\"1.4057\",\"102479.2\"],[\"1.4058\",\"130641.9\"],[\"1.4068\",\"239752.8\"],[\"1.4069\",\"61643.1\"],[\"1.4070\",\"43466.4\"],[\"1.4071\",\"88691.5\"],[\"1.4073\",\"42738.0\"],[\"1.4079\",\"192354.9\"],[\"1.4105\",\"39241.5\"],[\"1.4119\",\"40026.2\"]],\"u\":9831442,\"seq\":241267319271},\"cts\":1778927731299}"}
{"ts":1778927731627,"data":"{\"topic\":\"orderbook.1000.XRPUSDT\",\"type\":\"delta\",\"ts\":1778927731503,\"data\":{\"s\":\"XRPUSDT\",\"b\":[[\"1.4023\",\"51692.4\"],[\"1.4020\",\"60472.9\"],[\"1.4017\",\"78239.8\"],[\"1.4005\",\"41025.4\"],[\"1.4001\",\"21389.5\"]],\"a\":[[\"1.4040\",\"16918.7\"],[\"1.4043\",\"73863.7\"],[\"1.4052\",\"64259.8\"],[\"1.4053\",\"61366.4\"],[\"1.4058\",\"114245.5\"],[\"1.4068\",\"239757.3\"],[\"1.4069\",\"61638.6\"]],\"u\":9831443,\"seq\":241267319472},\"cts\":1778927731497}"}
{"ts":1778927731827,"data":"{\"topic\":\"orderbook.1000.XRPUSDT\",\"type\":\"delta\",\"ts\":1778927731703,\"data\":{\"s\":\"XRPUSDT\",\"b\":[[\"1.4030\",\"35870.5\"],[\"1.4029\",\"49374.5\"],[\"1.4024\",\"51956.9\"],[\"1.4023\",\"51688.8\"],[\"1.3961\",\"41073.8\"],[\"1.3960\",\"21506.4\"],[\"1.3950\",\"156051.0\"],[\"1.3861\",\"3503.1\"],[\"1.3835\",\"18152.4\"],[\"1.3822\",\"3105.9\"],[\"1.3123\",\"211.8\"]],\"a\":[[\"1.4040\",\"7585.8\"],[\"1.4048\",\"54824.2\"],[\"1.4050\",\"73201.4\"],[\"1.4052\",\"64255.3\"],[\"1.4053\",\"61370.9\"],[\"1.4054\",\"54890.4\"],[\"1.4058\",\"57248.1\"],[\"1.4059\",\"129851.5\"],[\"1.4074\",\"239362.8\"],[\"1.4075\",\"506542.0\"],[\"1.4108\",\"27899.1\"],[\"1.4111\",\"51079.9\"],[\"1.4113\",\"38297.1\"],[\"1.4122\",\"31590.8\"],[\"1.4139\",\"360772.5\"],[\"1.4152\",\"93542.4\"],[\"1.4175\",\"953.7\"],[\"1.4178\",\"485.1\"]],\"u\":9831444,\"seq\":241267319619},\"cts\":1778927731699}"}
{"ts":1778927732027,"data":"{\"topic\":\"orderbook.1000.XRPUSDT\",\"type\":\"delta\",\"ts\":1778927731903,\"data\":{\"s\":\"XRPUSDT\",\"b\":[[\"1.4037\",\"83966.8\"],[\"1.4036\",\"73372.7\"]],\"a\":[[\"1.4040\",\"3312.3\"],[\"1.4042\",\"53378.6\"],[\"1.4054\",\"58451.8\"],[\"1.4073\",\"49180.9\"]],\"u\":9831445,\"seq\":241267319740},\"cts\":1778927731902}"}
{"ts":1778927732227,"data":"{\"topic\":\"orderbook.1000.XRPUSDT\",\"type\":\"delta\",\"ts\":1778927732104,\"data\":{\"s\":\"XRPUSDT\",\"b\":[[\"1.4039\",\"27526.9\"],[\"1.4036\",\"71234.4\"],[\"1.4007\",\"62168.7\"],[\"1.4006\",\"40242.6\"]],\"a\":[[\"1.4043\",\"60329.9\"],[\"1.4044\",\"79129.8\"],[\"1.4057\",\"73980.5\"],[\"1.4058\",\"85746.8\"],[\"1.4068\",\"239752.8\"],[\"1.4069\",\"61643.1\"],[\"1.4071\",\"88840.7\"],[\"1.4075\",\"482754.5\"],[\"1.4077\",\"60299.2\"],[\"1.4079\",\"192205.7\"],[\"1.4111\",\"27292.4\"],[\"1.4114\",\"59304.5\"]],\"u\":9831446,\"seq\":241267319854},\"cts\":1778927732100}"}
{"ts":1778927732430,"data":"{\"topic\":\"orderbook.1000.XRPUSDT\",\"type\":\"delta\",\"ts\":1778927732303,\"data\":{\"s\":\"XRPUSDT\",\"b\":[[\"1.4039\",\"27532.7\"],[\"1.4005\",\"35909.4\"],[\"1.3949\",\"4543.7\"]],\"a\":[[\"1.4040\",\"3354.5\"],[\"1.4041\",\"34687.6\"],[\"1.4042\",\"28031.4\"],[\"1.4043\",\"74772.2\"],[\"1.4052\",\"64194.1\"],[\"1.4054\",\"54890.4\"],[\"1.4058\",\"102143.2\"]],\"u\":9831447,\"seq\":241267319973},\"cts\":1778927732296}"}
{"ts":1778927732627,"data":"{\"topic\":\"orderbook.1000.XRPUSDT\",\"type\":\"delta\",\"ts\":1778927732503,\"data\":{\"s\":\"XRPUSDT\",\"b\":[[\"1.3122\",\"79.4\"]],\"a\":[[\"1.4040\",\"3350.9\"],[\"1.4042\",\"34491.6\"],[\"1.4052\",\"61495.8\"],[\"1.4054\",\"58451.8\"],[\"1.4057\",\"73554.2\"],[\"1.4216\",\"1151.2\"],[\"1.4251\",\"42800.2\"]],\"u\":9831448,\"seq\":241267320120},\"cts\":1778927732495}"}
{"ts":1778927732829,"data":"{\"topic\":\"orderbook.1000.XRPUSDT\",\"type\":\"delta\",\"ts\":1778927732703,\"data\":{\"s\":\"XRPUSDT\",\"b\":[[\"1.4039\",\"27481.6\"],[\"1.4037\",\"84046.8\"]],\"a\":[[\"1.4040\",\"3356.4\"]],\"u\":9831449,\"seq\":241267320249},\"cts\":1778927732701}"}
{"ts":1778927733029,"data":"{\"topic\":\"orderbook.1000.XRPUSDT\",\"type\":\"delta\",\"ts\":1778927732903,\"data\":{\"s\":\"XRPUSDT\",\"b\":[[\"1.4037\",\"84063.2\"]],\"a\":[[\"1.4042\",\"48935.4\"]],\"u\":9831450,\"seq\":241267320348},\"cts\":1778927732901}"}
{"ts":1778927733229,"data":"{\"topic\":\"orderbook.1000.XRPUSDT\",\"type\":\"delta\",\"ts\":1778927733103,\"data\":{\"s\":\"XRPUSDT\",\"b\":[[\"1.4027\",\"43546.0\"]],\"a\":[[\"1.4040\",\"3350.9\"],[\"1.4043\",\"60328.4\"],[\"1.4054\",\"54890.4\"],[\"1.4106\",\"31033.1\"]],\"u\":9831451,\"seq\":241267320461},\"cts\":1778927733086}"}
{"ts":1778927733427,"data":"{\"topic\":\"orderbook.1000.XRPUSDT\",\"type\":\"delta\",\"ts\":1778927733303,\"data\":{\"s\":\"XRPUSDT\",\"b\":[[\"1.4036\",\"71264.0\"],[\"1.4022\",\"58136.8\"],[\"1.4018\",\"59456.3\"]],\"a\":[[\"1.4040\",\"3108.7\"],[\"1.4042\",\"27960.2\"],[\"1.4043\",\"74771.3\"],[\"1.4053\",\"64932.3\"],[\"1.4057\",\"76288.4\"],[\"1.4106\",\"31040.2\"]],\"u\":9831452,\"seq\":241267320683},\"cts\":1778927733294}"}
{"ts":1778927733627,"data":"{\"topic\":\"orderbook.1000.XRPUSDT\",\"type\":\"delta\",\"ts\":1778927733503,\"data\":{\"s\":\"XRPUSDT\",\"b\":[[\"1.4038\",\"41711.1\"],[\"1.4036\",\"71406.4\"],[\"1.4025\",\"46460.8\"],[\"1.4024\",\"52313.5\"],[\"1.4017\",\"78090.6\"],[\"1.4014\",\"233294.6\"],[\"1.4013\",\"206680.1\"],[\"1.4008\",\"78136.5\"]],\"a\":[[\"1.4040\",\"3110.7\"],[\"1.4053\",\"61370.9\"],[\"1.4055\",\"86026.5\"],[\"1.4057\",\"79410.6\"],[\"1.4071\",\"88691.5\"]],\"u\":9831453,\"seq\":241267320889},\"cts\":1778927733499}"}
{"ts":1778927733827,"data":"{\"topic\":\"orderbook.1000.XRPUSDT\",\"type\":\"delta\",\"ts\":1778927733703,\"data\":{\"s\":\"XRPUSDT\",\"b\":[[\"1.4039\",\"27487.4\"],[\"1.3650\",\"23191.6\"]],\"a\":[],\"u\":9831454,\"seq\":241267320958},\"cts\":1778927733696}"}
{"ts":1778927734028,"data":"{\"topic\":\"orderbook.1000.XRPUSDT\",\"type\":\"delta\",\"ts\":1778927733903,\"data\":{\"s\":\"XRPUSDT\",\"b\":[[\"1.4037\",\"84055.4\"],[\"1.3630\",\"5243.4\"]],\"a\":[[\"1.4053\",\"64932.3\"],[\"1.4376\",\"25905.4\"],[\"1.4377\",\"17754.4\"]],\"u\":9831455,\"seq\":241267321186},\"cts\":1778927733900}"}
{"ts":1778927734231,"data":"{\"topic\":\"orderbook.1000.XRPUSDT\",\"type\":\"delta\",\"ts\":1778927734103,\"data\":{\"s\":\"XRPUSDT\",\"b\":[[\"1.4042\",\"62147.8\"],[\"1.4041\",\"37010.5\"],[\"1.4040\",\"103721.1\"],[\"1.4039\",\"82659.5\"],[\"1.4038\",\"75505.6\"],[\"1.4037\",\"57288.3\"],[\"1.4036\",\"57591.4\"],[\"1.4035\",\"62308.9\"],[\"1.4034\",\"66702.2\"],[\"1.4033\",\"47158.6\"],[\"1.4032\",\"43550.2\"],[\"1.4031\",\"42308.7\"],[\"1.4030\",\"46612.3\"],[\"1.4029\",\"46081.0\"],[\"1.4028\",\"28142.1\"],[\"1.4027\",\"43609.8\"],[\"1.4026\",\"43232.9\"],[\"1.4025\",\"54061.1\"],[\"1.4024\",\"41223.8\"],[\"1.4023\",\"45426.4\"],[\"1.4022\",\"63322.3\"],[\"1.4021\",\"40171.6\"],[\"1.4020\",\"57508.2\"],[\"1.4019\",\"42084.1\"],[\"1.4018\",\"54246.7\"],[\"1.4017\",\"77818.4\"],[\"1.4016\",\"138821.5\"],[\"1.4015\",\"115805.1\"],[\"1.4012\",\"86400.8\"],[\"1.4011\",\"160863.2\"],[\"1.4010\",\"85602.9\"],[\"1.4009\",\"56265.5\"],[\"1.4008\",\"85665.3\"],[\"1.4007\",\"42930.4\"],[\"1.4003\",\"274120.5\"],[\"1.4002\",\"41786.3\"],[\"1.4001\",\"20255.3\"],[\"1.3970\",\"205708.6\"],[\"1.3965\",\"28900.2\"],[\"1.3964\",\"33976.2\"],[\"1.3958\",\"8793.2\"],[\"1.3921\",\"12680.4\"],[\"1.3899\",\"5997.1\"],[\"1.3042\",\"0\"],[\"1.3041\",\"0\"],[\"1.3040\",\"0\"]],\"a\":[[\"1.4040\",\"0\"],[\"1.4041\",\"0\"],[\"1.4042\",\"0\"],[\"1.4043\",\"4841.5\"],[\"1.4044\",\"17079.9\"],[\"1.4045\",\"40222.9\"],[\"1.4046\",\"80424.1\"],[\"1.4047\",\"50581.3\"],[\"1.4048\",\"51635.7\"],[\"1.4049\",\"78757.0\"],[\"1.4050\",\"80899.5\"],[\"1.4051\",\"68277.7\"],[\"1.4052\",\"54463.3\"],[\"1.4053\",\"66733.4\"],[\"1.4054\",\"54681.6\"],[\"1.4055\",\"89070.1\"],[\"1.4056\",\"82013.0\"],[\"1.4057\",\"65533.5\"],[\"1.4058\",\"68015.0\"],[\"1.4059\",\"73280.4\"],[\"1.4060\",\"101382.3\"],[\"1.4061\",\"71885.1\"],[\"1.4062\",\"137190.4\"],[\"1.4067\",\"112034.1\"],[\"1.4070\",\"43470.1\"],[\"1.4071\",\"93016.7\"],[\"1.4072\",\"120290.6\"],[\"1.4073\",\"50484.3\"],[\"1.4074\",\"250129.5\"],[\"1.4077\",\"36511.7\"],[\"1.4078\",\"94449.5\"],[\"1.4081\",\"272617.2\"],[\"1.4084\",\"183385.4\"],[\"1.4087\",\"46797.3\"],[\"1.4092\",\"62496.3\"],[\"1.4109\",\"26816.1\"],[\"1.4112\",\"247399.9\"],[\"1.4114\",\"35517.0\"],[\"1.4115\",\"50899.9\"],[\"1.4116\",\"26956.6\"],[\"1.4117\",\"27638.6\"],[\"1.4118\",\"27465.5\"],[\"1.4122\",\"58404.1\"],[\"1.4123\",\"34043.2\"],[\"1.4124\",\"283274.3\"],[\"1.5040\",\"5013.4\"],[\"1.5041\",\"101.4\"],[\"1.5042\",\"78.8\"]],\"u\":9831456,\"seq\":241267322383},\"cts\":1778927734102}"}
{"ts":1778927734427,"data":"{\"topic\":\"orderbook.1000.XRPUSDT\",\"type\":\"delta\",\"ts\":1778927734303,\"data\":{\"s\":\"XRPUSDT\",\"b\":[[\"1.4042\",\"67492.4\"],[\"1.4041\",\"34760.1\"],[\"1.4040\",\"96854.2\"],[\"1.4039\",\"64229.8\"],[\"1.4038\",\"64890.6\"],[\"1.4037\",\"51079.5\"],[\"1.4036\",\"57816.4\"],[\"1.4035\",\"61952.7\"],[\"1.4034\",\"70625.9\"],[\"1.4033\",\"47076.1\"],[\"1.4031\",\"42188.4\"],[\"1.4030\",\"42901.8\"],[\"1.4026\",\"38313.6\"],[\"1.4023\",\"47603.5\"],[\"1.4022\",\"61148.0\"],[\"1.4018\",\"53930.3\"],[\"1.4012\",\"92528.9\"],[\"1.4011\",\"160916.1\"],[\"1.4010\",\"104942.7\"],[\"1.4009\",\"56215.8\"],[\"1.4008\",\"69129.2\"],[\"1.4004\",\"46682.4\"],[\"1.3978\",\"51813.3\"],[\"1.3973\",\"33470.7\"],[\"1.3966\",\"86277.1\"]],\"a\":[[\"1.4043\",\"21063.7\"],[\"1.4044\",\"17140.5\"],[\"1.4045\",\"53173.6\"],[\"1.4046\",\"82533.6\"],[\"1.4047\",\"49816.1\"],[\"1.4048\",\"48148.1\"],[\"1.4049\",\"75195.9\"],[\"1.4050\",\"80895.8\"],[\"1.4051\",\"71838.3\"],[\"1.4053\",\"70508.6\"],[\"1.4056\",\"82009.0\"],[\"1.4057\",\"65537.5\"],[\"1.4059\",\"67309.0\"],[\"1.4060\",\"72885.7\"],[\"1.4061\",\"115856.0\"],[\"1.4062\",\"137186.3\"],[\"1.4063\",\"109066.0\"],[\"1.4073\",\"49180.9\"],[\"1.4074\",\"251434.9\"],[\"1.4099\",\"212555.6\"]],\"u\":9831457,\"seq\":241267322728},\"cts\":1778927734302}"}
{"ts":1778927734628,"data":"{\"topic\":\"orderbook.1000.XRPUSDT\",\"type\":\"delta\",\"ts\":1778927734503,\"data\":{\"s\":\"XRPUSDT\",\"b\":[[\"1.4039\",\"64233.4\"],[\"1.4032\",\"43578.7\"],[\"1.4031\",\"42159.9\"],[\"1.4021\",\"40175.6\"],[\"1.4020\",\"57497.0\"],[\"1.4010\",\"104946.3\"],[\"1.4003\",\"297908.0\"],[\"1.4000\",\"270735.0\"],[\"1.3999\",\"23287.7\"],[\"1.3964\",\"57763.7\"],[\"1.3961\",\"17286.3\"]],\"a\":[[\"1.4043\",\"16791.1\"],[\"1.4045\",\"55127.5\"],[\"1.4046\",\"68090.7\"],[\"1.4050\",\"81351.5\"],[\"1.4052\",\"59061.9\"],[\"1.4053\",\"66948.0\"],[\"1.4055\",\"89065.6\"],[\"1.4056\",\"82013.5\"],[\"1.4060\",\"101378.3\"],[\"1.4061\",\"128870.3\"],[\"1.4062\",\"80201.1\"],[\"1.4063\",\"109069.6\"],[\"1.4064\",\"103498.7\"],[\"1.4078\",\"70662.0\"],[\"1.4079\",\"215993.2\"],[\"1.4085\",\"38108.0\"],[\"1.4088\",\"75554.4\"]],\"u\":9831458,\"seq\":241267322913},\"cts\":1778927734500}"}
{"ts":1778927734827,"data":"{\"topic\":\"orderbook.1000.XRPUSDT\",\"type\":\"delta\",\"ts\":1778927734703,\"data\":{\"s\":\"XRPUSDT\",\"b\":[[\"1.4042\",\"67498.2\"],[\"1.4040\",\"96858.2\"],[\"1.4035\",\"62308.9\"],[\"1.4034\",\"70269.7\"],[\"1.4033\",\"54028.3\"],[\"1.4014\",\"233101.3\"],[\"1.4011\",\"160919.7\"],[\"1.4009\",\"56212.2\"],[\"1.4008\",\"68836.3\"]],\"a\":[[\"1.4043\",\"15523.9\"],[\"1.4044\",\"17069.3\"],[\"1.4045\",\"41217.4\"],[\"1.4046\",\"79014.6\"],[\"1.4047\",\"56937.5\"],[\"1.4049\",\"75199.6\"],[\"1.4050\",\"80895.8\"],[\"1.4053\",\"67528.1\"],[\"1.4056\",\"82017.2\"],[\"1.4060\",\"72885.7\"],[\"1.4061\",\"100377.7\"],[\"1.4062\",\"137642.0\"],[\"1.4063\",\"109066.0\"],[\"1.4082\",\"27916.8\"],[\"1.4105\",\"39237.0\"],[\"1.4109\",\"26820.6\"]],\"u\":9831459,\"seq\":241267323243},\"cts\":1778927734695}"}
{"ts":1778927735027,"data":"{\"topic\":\"orderbook.1000.XRPUSDT\",\"type\":\"delta\",\"ts\":1778927734903,\"data\":{\"s\":\"XRPUSDT\",\"b\":[[\"1.4042\",\"67492.4\"],[\"1.4040\",\"96890.7\"],[\"1.4039\",\"64268.2\"],[\"1.4037\",\"51052.6\"],[\"1.4036\",\"57798.6\"],[\"1.4025\",\"54061.0\"],[\"1.3988\",\"234344.9\"],[\"1.3987\",\"44773.2\"],[\"1.3973\",\"33474.3\"],[\"1.3971\",\"61035.0\"],[\"1.3970\",\"205701.5\"]],\"a\":[[\"1.4045\",\"48430.0\"],[\"1.4047\",\"56956.6\"],[\"1.4051\",\"71740.9\"],[\"1.4053\",\"63967.5\"],[\"1.4060\",\"101378.3\"],[\"1.4061\",\"71885.1\"],[\"1.4062\",\"137186.3\"],[\"1.4063\",\"109069.6\"],[\"1.4069\",\"62098.7\"],[\"1.4087\",\"46801.8\"],[\"1.4088\",\"75549.9\"],[\"1.4105\",\"39106.0\"],[\"1.4115\",\"27112.4\"],[\"1.4116\",\"50744.1\"]],\"u\":9831460,\"seq\":241267323442},\"cts\":1778927734898}"}
{"ts":1778927735227,"data":"{\"topic\":\"orderbook.1000.XRPUSDT\",\"type\":\"delta\",\"ts\":1778927735103,\"data\":{\"s\":\"XRPUSDT\",\"b\":[[\"1.4041\",\"34758.2\"],[\"1.4038\",\"53690.6\"],[\"1.4035\",\"61952.7\"],[\"1.4034\",\"70625.9\"],[\"1.4013\",\"206673.0\"],[\"1.3960\",\"11363.7\"],[\"1.3959\",\"386324.5\"]],\"a\":[[\"1.4043\",\"15487.2\"],[\"1.4045\",\"55642.6\"],[\"1.4046\",\"71785.6\"],[\"1.4050\",\"78047.3\"],[\"1.4051\",\"67468.2\"],[\"1.4053\",\"67528.1\"],[\"1.4055\",\"88638.3\"],[\"1.4060\",\"101307.7\"],[\"1.4063\",\"109066.0\"],[\"1.4069\",\"61643.1\"],[\"1.4072\",\"120294.2\"],[\"1.4082\",\"27920.4\"]],\"u\":9831461,\"seq\":241267323609},\"cts\":1778927735101}"}
{"ts":1778927735428,"data":"{\"topic\":\"orderbook.1000.XRPUSDT\",\"type\":\"delta\",\"ts\":1778927735304,\"data\":{\"s\":\"XRPUSDT\",\"b\":[[\"1.4042\",\"63706.0\"],[\"1.4040\",\"93104.3\"],[\"1.4034\",\"70745.1\"],[\"1.3999\",\"23291.3\"],[\"1.3988\",\"234341.3\"],[\"1.3987\",\"44776.8\"],[\"1.3630\",\"5236.1\"]],\"a\":[[\"1.4043\",\"15500.2\"],[\"1.4044\",\"17140.5\"],[\"1.4045\",\"55571.4\"],[\"1.4046\",\"64573.5\"],[\"1.4050\",\"78051.0\"],[\"1.4051\",\"70459.2\"],[\"1.4053\",\"68240.2\"],[\"1.4057\",\"65964.8\"],[\"1.4060\",\"72815.1\"],[\"1.4061\",\"115856.0\"],[\"1.4063\",\"109069.6\"],[\"1.4073\",\"77539.7\"],[\"1.4087\",\"46797.3\"],[\"1.4088\",\"75554.4\"]],\"u\":9831462,\"seq\":241267323711},\"cts\":1778927735294}"}
{"ts":1778927735631,"data":"{\"topic\":\"orderbook.1000.XRPUSDT\",\"type\":\"delta\",\"ts\":1778927735503,\"data\":{\"s\":\"XRPUSDT\",\"b\":[[\"1.4042\",\"63777.3\"],[\"1.3999\",\"23294.9\"],[\"1.3610\",\"3210.7\"]],\"a\":[[\"1.4047\",\"57105.7\"],[\"1.4051\",\"70407.4\"],[\"1.4053\",\"71800.8\"],[\"1.4060\",\"101307.7\"],[\"1.4061\",\"71885.1\"],[\"1.4063\",\"109066.0\"],[\"1.4082\",\"27927.6\"],[\"1.4087\",\"46801.8\"],[\"1.4088\",\"75549.9\"],[\"1.4107\",\"510359.7\"],[\"1.4108\",\"27903.6\"],[\"1.4109\",\"26816.1\"],[\"1.4119\",\"40157.2\"]],\"u\":9831463,\"seq\":241267323854},\"cts\":1778927735493}"}
{"ts":1778927735827,"data":"{\"topic\":\"orderbook.1000.XRPUSDT\",\"type\":\"delta\",\"ts\":1778927735703,\"data\":{\"s\":\"XRPUSDT\",\"b\":[[\"1.4041\",\"34775.7\"],[\"1.4040\",\"100795.3\"],[\"1.4038\",\"48692.8\"],[\"1.4037\",\"43361.8\"],[\"1.4018\",\"54246.7\"],[\"1.4004\",\"45733.1\"],[\"1.3999\",\"23298.5\"]],\"a\":[[\"1.4053\",\"68240.2\"],[\"1.4063\",\"109073.2\"],[\"1.4082\",\"27931.2\"],[\"1.4286\",\"7941.0\"],[\"1.4305\",\"222.2\"]],\"u\":9831464,\"seq\":241267323940},\"cts\":1778927735694}"}
{"ts":1778927736027,"data":"{\"topic\":\"orderbook.1000.XRPUSDT\",\"type\":\"delta\",\"ts\":1778927735903,\"data\":{\"s\":\"XRPUSDT\",\"b\":[[\"1.4040\",\"100788.1\"],[\"1.4018\",\"53930.3\"],[\"1.4004\",\"46682.4\"],[\"1.3999\",\"23302.1\"]],\"a\":[[\"1.4049\",\"73995.4\"],[\"1.4051\",\"71605.5\"]],\"u\":9831465,\"seq\":241267324027},\"cts\":1778927735901}"}
{"ts":1778927736230,"data":"{\"topic\":\"orderbook.1000.XRPUSDT\",\"type\":\"delta\",\"ts\":1778927736105,\"data\":{\"s\":\"XRPUSDT\",\"b\":[[\"1.4041\",\"34758.2\"],[\"1.4018\",\"54246.7\"],[\"1.4012\",\"146410.1\"],[\"1.4011\",\"352236.1\"],[\"1.4010\",\"104995.4\"],[\"1.4004\",\"45733.1\"],[\"1.4003\",\"106552.5\"],[\"1.3999\",\"23305.7\"],[\"1.3957\",\"44992.6\"],[\"1.3818\",\"1114.9\"],[\"1.3815\",\"27604.6\"]],\"a\":[[\"1.4048\",\"46539.4\"],[\"1.4052\",\"60670.6\"],[\"1.4082\",\"27934.8\"],[\"1.4125\",\"30101.7\"],[\"1.4264\",\"21970.7\"],[\"1.4267\",\"26261.8\"],[\"1.4270\",\"27214.4\"]],\"u\":9831466,\"seq\":241267324125},\"cts\":1778927736100}"}
{"ts":1778927736438,"data":"{\"topic\":\"orderbook.1000.XRPUSDT\",\"type\":\"delta\",\"ts\":1778927736303,\"data\":{\"s\":\"XRPUSDT\",\"b\":[[\"1.4044\",\"33326.3\"],[\"1.4043\",\"83066.8\"],[\"1.4042\",\"38914.4\"],[\"1.4041\",\"61085.1\"],[\"1.4038\",\"41530.5\"],[\"1.4037\",\"50314.0\"],[\"1.4036\",\"63495.5\"],[\"1.4033\",\"64796.3\"],[\"1.4032\",\"39044.0\"],[\"1.4029\",\"37129.0\"],[\"1.4028\",\"39226.1\"],[\"1.4026\",\"37858.5\"],[\"1.4024\",\"40948.0\"],[\"1.4023\",\"58371.5\"],[\"1.4020\",\"57493.4\"],[\"1.4018\",\"53930.3\"],[\"1.4015\",\"115805.6\"],[\"1.4014\",\"233177.6\"],[\"1.4013\",\"206680.1\"],[\"1.4012\",\"156640.2\"],[\"1.4010\",\"94228.7\"],[\"1.4008\",\"61244.4\"],[\"1.3989\",\"37775.5\"],[\"1.3044\",\"0\"],[\"1.3043\",\"0\"]],\"a\":[[\"1.4043\",\"0\"],[\"1.4044\",\"0\"],[\"1.4045\",\"0\"],[\"1.4046\",\"10062.5\"],[\"1.4047\",\"17638.3\"],[\"1.4048\",\"19318.8\"],[\"1.4049\",\"46040.7\"],[\"1.4050\",\"73261.8\"],[\"1.4051\",\"68049.0\"],[\"1.4052\",\"60215.6\"],[\"1.4053\",\"63738.0\"],[\"1.4055\",\"77416.5\"],[\"1.4056\",\"81581.0\"],[\"1.4060\",\"101378.2\"],[\"1.4061\",\"87363.4\"],[\"1.4062\",\"126403.1\"],[\"1.4070\",\"44855.7\"],[\"1.4074\",\"240668.2\"],[\"1.4077\",\"47279.7\"],[\"1.4078\",\"77046.7\"],[\"1.4084\",\"183389.4\"],[\"1.4115\",\"50899.9\"],[\"1.4116\",\"26956.6\"],[\"1.4125\",\"29347.8\"],[\"1.5043\",\"411.3\"],[\"1.5044\",\"220.6\"],[\"1.5045\",\"2380.2\"]],\"u\":9831467,\"seq\":241267324667},\"cts\":1778927736301}"}
{"ts":1778927736628,"data":"{\"topic\":\"orderbook.1000.XRPUSDT\",\"type\":\"delta\",\"ts\":1778927736503,\"data\":{\"s\":\"XRPUSDT\",\"b\":[[\"1.4047\",\"11.2\"],[\"1.4046\",\"23.9\"],[\"1.4045\",\"39352.7\"],[\"1.4044\",\"87200.4\"],[\"1.4043\",\"71223.1\"],[\"1.4042\",\"69559.5\"],[\"1.4041\",\"65820.6\"],[\"1.4040\",\"78183.5\"],[\"1.4039\",\"42038.5\"],[\"1.4038\",\"42231.2\"],[\"1.4037\",\"37281.2\"],[\"1.4036\",\"40735.6\"],[\"1.4035\",\"45752.1\"],[\"1.4034\",\"49471.6\"],[\"1.4033\",\"29267.2\"],[\"1.4032\",\"26285.0\"],[\"1.4031\",\"37828.8\"],[\"1.4030\",\"26599.5\"],[\"1.4029\",\"44172.7\"],[\"1.4028\",\"38502.7\"],[\"1.4027\",\"29262.5\"],[\"1.4026\",\"59730.2\"],[\"1.4025\",\"44399.2\"],[\"1.4024\",\"46788.2\"],[\"1.4023\",\"130380.5\"],[\"1.4022\",\"248598.8\"],[\"1.4021\",\"46199.7\"],[\"1.4020\",\"57327.0\"],[\"1.4019\",\"53235.2\"],[\"1.4018\",\"58135.4\"],[\"1.4017\",\"51775.5\"],[\"1.4016\",\"52024.9\"],[\"1.4015\",\"92865.6\"],[\"1.4014\",\"187968.1\"],[\"1.4013\",\"79923.4\"],[\"1.4012\",\"139271.5\"],[\"1.4011\",\"326736.0\"],[\"1.4010\",\"80857.8\"],[\"1.4009\",\"91236.0\"],[\"1.4008\",\"59103.9\"],[\"1.4007\",\"44168.8\"],[\"1.4006\",\"43213.0\"],[\"1.4005\",\"179711.8\"],[\"1.4004\",\"45740.2\"],[\"1.4003\",\"66131.3\"],[\"1.4002\",\"53816.5\"],[\"1.4001\",\"220746.3\"],[\"1.4000\",\"285520.7\"],[\"1.3999\",\"21843.0\"],[\"1.3998\",\"439167.5\"],[\"1.3997\",\"20990.2\"],[\"1.3996\",\"33884.9\"],[\"1.3995\",\"244664.9\"],[\"1.3994\",\"27689.6\"],[\"1.3993\",\"42770.5\"],[\"1.3992\",\"28588.7\"],[\"1.3989\",\"37780.6\"],[\"1.3988\",\"34825.8\"],[\"1.3987\",\"41927.1\"],[\"1.3986\",\"28036.7\"],[\"1.3985\",\"39034.2\"],[\"1.3984\",\"60500.8\"],[\"1.3982\",\"53736.5\"],[\"1.3981\",\"359510.0\"],[\"1.3980\",\"30307.9\"],[\"1.3979\",\"302087.2\"],[\"1.3977\",\"394817.1\"],[\"1.3976\",\"154992.2\"],[\"1.3975\",\"62835.7\"],[\"1.3974\",\"63036.6\"],[\"1.3973\",\"33493.7\"],[\"1.3972\",\"41350.0\"],[\"1.3971\",\"61027.6\"],[\"1.3970\",\"199964.4\"],[\"1.3969\",\"33413.9\"],[\"1.3968\",\"41100.2\"],[\"1.3967\",\"33369.3\"],[\"1.3966\",\"56342.1\"],[\"1.3965\",\"27526.2\"],[\"1.3964\",\"134893.7\"],[\"1.3963\",\"61278.8\"],[\"1.3960\",\"11365.6\"],[\"1.3957\",\"44992.9\"],[\"1.3956\",\"6542.6\"],[\"1.3954\",\"55631.6\"],[\"1.3948\",\"23915.6\"],[\"1.3946\",\"3028.6\"],[\"1.3945\",\"12847.9\"],[\"1.3938\",\"3077.7\"],[\"1.3934\",\"1106.9\"],[\"1.3930\",\"107941.0\"],[\"1.3925\",\"286129.2\"],[\"1.3916\",\"7646.2\"],[\"1.3912\",\"5891.7\"],[\"1.3904\",\"1985.1\"],[\"1.3899\",\"6680.4\"],[\"1.3047\",\"0\"],[\"1.3046\",\"0\"],[\"1.3045\",\"0\"]],\"a\":[[\"1.4046\",\"0\"],[\"1.4047\",\"0\"],[\"1.4048\",\"79069.3\"],[\"1.4049\",\"57621.1\"],[\"1.4050\",\"89350.1\"],[\"1.4051\",\"68001.7\"],[\"1.4052\",\"60296.5\"],[\"1.4053\",\"68880.3\"],[\"1.4054\",\"70889.8\"],[\"1.4055\",\"74203.1\"],[\"1.4056\",\"74836.7\"],[\"1.4057\",\"65867.9\"],[\"1.4058\",\"52798.9\"],[\"1.4059\",\"54012.7\"],[\"1.4060\",\"45773.4\"],[\"1.4061\",\"60869.5\"],[\"1.4062\",\"54291.5\"],[\"1.4063\",\"89262.1\"],[\"1.4064\",\"57399.8\"],[\"1.4065\",\"77465.8\"],[\"1.4066\",\"38210.9\"],[\"1.4067\",\"77727.9\"],[\"1.4068\",\"76615.8\"],[\"1.4069\",\"67689.4\"],[\"1.4070\",\"103072.0\"],[\"1.4071\",\"93309.6\"],[\"1.4072\",\"149018.1\"],[\"1.4073\",\"44989.0\"],[\"1.4074\",\"137196.0\"],[\"1.4075\",\"355738.3\"],[\"1.4076\",\"86832.4\"],[\"1.4077\",\"92064.5\"],[\"1.4078\",\"138460.3\"],[\"1.4079\",\"256656.5\"],[\"1.4080\",\"131697.0\"],[\"1.4081\",\"50649.1\"],[\"1.4082\",\"34160.0\"],[\"1.4083\",\"40543.4\"],[\"1.4084\",\"193319.0\"],[\"1.4087\",\"47648.3\"],[\"1.4088\",\"76969.6\"],[\"1.4089\",\"288188.4\"],[\"1.4090\",\"208552.5\"],[\"1.4091\",\"260858.8\"],[\"1.4092\",\"26886.3\"],[\"1.4094\",\"48606.7\"],[\"1.4095\",\"34952.6\"],[\"1.4096\",\"63690.3\"],[\"1.4097\",\"360874.6\"],[\"1.4098\",\"73434.8\"],[\"1.4099\",\"241138.9\"],[\"1.4100\",\"363660.0\"],[\"1.4101\",\"94295.5\"],[\"1.4102\",\"34152.8\"],[\"1.4104\",\"46419.1\"],[\"1.4105\",\"27063.2\"],[\"1.4107\",\"114412.1\"],[\"1.4108\",\"34636.3\"],[\"1.4109\",\"34872.1\"],[\"1.4110\",\"43745.4\"],[\"1.4111\",\"218254.3\"],[\"1.4112\",\"77099.2\"],[\"1.4118\",\"27111.0\"],[\"1.4119\",\"40204.3\"],[\"1.4120\",\"579485.4\"],[\"1.4121\",\"100153.6\"],[\"1.4122\",\"58411.3\"],[\"1.4123\",\"30864.2\"],[\"1.4125\",\"46025.2\"],[\"1.4126\",\"34850.4\"],[\"1.4127\",\"31038.1\"],[\"1.4128\",\"28987.2\"],[\"1.4129\",\"26863.8\"],[\"1.4132\",\"25726.4\"],[\"1.4133\",\"574.0\"],[\"1.4139\",\"382540.5\"],[\"1.4147\",\"9340.6\"],[\"1.4152\",\"9686.5\"],[\"1.4153\",\"38237.3\"],[\"1.4154\",\"10213.0\"],[\"1.4155\",\"8256.0\"],[\"1.4156\",\"11748.9\"],[\"1.4159\",\"8576.6\"],[\"1.4163\",\"8563.4\"],[\"1.4164\",\"3238.8\"],[\"1.4165\",\"56.5\"],[\"1.4167\",\"11526.9\"],[\"1.4168\",\"78726.2\"],[\"1.4177\",\"285103.5\"],[\"1.4183\",\"4092.0\"],[\"1.4185\",\"157.5\"],[\"1.4188\",\"20769.5\"],[\"1.4200\",\"13046.0\"],[\"1.4201\",\"41681.8\"],[\"1.4207\",\"1581.6\"],[\"1.4210\",\"4369.0\"],[\"1.4218\",\"7222.4\"],[\"1.4220\",\"12171.1\"],[\"1.4239\",\"910.6\"],[\"1.4244\",\"1117.7\"],[\"1.4246\",\"6079.2\"],[\"1.4256\",\"2000.0\"],[\"1.4266\",\"43631.7\"],[\"1.4276\",\"29007.3\"],[\"1.4306\",\"6504.8\"],[\"1.4315\",\"7639.8\"],[\"1.4317\",\"21059.8\"],[\"1.4336\",\"236.0\"],[\"1.4345\",\"269.2\"],[\"1.4356\",\"614.6\"],[\"1.4358\",\"11906.2\"],[\"1.4386\",\"8575.6\"],[\"1.4400\",\"24798.5\"],[\"1.4414\",\"27402.0\"],[\"1.5046\",\"462.4\"],[\"1.5047\",\"345.7\"]],\"u\":9831468,\"seq\":241267328512},\"cts\":1778927736501}"}
{"ts":1778927736827,"data":"{\"topic\":\"orderbook.1000.XRPUSDT\",\"type\":\"delta\",\"ts\":1778927736703,\"data\":{\"s\":\"XRPUSDT\",\"b\":[[\"1.4047\",\"7.9\"],[\"1.4046\",\"7257.5\"],[\"1.4045\",\"32288.9\"],[\"1.4044\",\"102906.6\"],[\"1.4043\",\"69326.6\"],[\"1.4042\",\"62760.9\"],[\"1.4041\",\"66045.6\"],[\"1.4040\",\"74089.8\"],[\"1.4039\",\"42034.9\"],[\"1.4038\",\"42227.6\"],[\"1.4037\",\"42249.4\"],[\"1.4036\",\"44477.6\"],[\"1.4035\",\"43630.3\"],[\"1.4034\",\"52592.3\"],[\"1.4033\",\"32828.1\"],[\"1.4032\",\"29018.5\"],[\"1.4031\",\"38532.9\"],[\"1.4030\",\"27379.5\"],[\"1.4029\",\"44179.6\"],[\"1.4028\",\"36096.2\"],[\"1.4027\",\"31444.9\"],[\"1.4026\",\"61827.2\"],[\"1.4025\",\"44547.8\"],[\"1.4021\",\"46192.8\"],[\"1.4016\",\"56255.4\"],[\"1.4014\",\"207340.0\"],[\"1.4013\",\"60551.4\"],[\"1.4005\",\"166521.0\"],[\"1.3973\",\"33490.1\"],[\"1.3963\",\"51171.5\"],[\"1.3962\",\"25780.0\"],[\"1.3961\",\"17289.9\"],[\"1.3857\",\"16257.6\"]],\"a\":[[\"1.4048\",\"79093.5\"],[\"1.4049\",\"68574.7\"],[\"1.4050\",\"82942.6\"],[\"1.4051\",\"67241.2\"],[\"1.4052\",\"53109.6\"],[\"1.4053\",\"62193.5\"],[\"1.4054\",\"76367.6\"],[\"1.4055\",\"74936.0\"],[\"1.4056\",\"70160.5\"],[\"1.4058\",\"55674.8\"],[\"1.4059\",\"60913.5\"],[\"1.4060\",\"50639.2\"],[\"1.4061\",\"53178.6\"],[\"1.4062\",\"54429.1\"],[\"1.4063\",\"102136.3\"],[\"1.4064\",\"64264.9\"],[\"1.4065\",\"113524.5\"],[\"1.4066\",\"95175.8\"],[\"1.4067\",\"60593.0\"],[\"1.4068\",\"76615.9\"],[\"1.4069\",\"51116.1\"],[\"1.4070\",\"56111.1\"],[\"1.4071\",\"93458.2\"],[\"1.4078\",\"143839.7\"],[\"1.4084\",\"203970.0\"],[\"1.4101\",\"88196.7\"],[\"1.4115\",\"77468.9\"],[\"1.4132\",\"31811.8\"],[\"1.4234\",\"587.0\"]],\"u\":9831469,\"seq\":241267329308},\"cts\":1778927736698}"}
{"ts":1778927737028,"data":"{\"topic\":\"orderbook.1000.XRPUSDT\",\"type\":\"delta\",\"ts\":1778927736903,\"data\":{\"s\":\"XRPUSDT\",\"b\":[[\"1.4047\",\"0\"],[\"1.4046\",\"15636.5\"],[\"1.4045\",\"26544.6\"],[\"1.4044\",\"105378.8\"],[\"1.4042\",\"64458.4\"],[\"1.4041\",\"55045.6\"],[\"1.4040\",\"62861.2\"],[\"1.4039\",\"42007.3\"],[\"1.4037\",\"42253.0\"],[\"1.4034\",\"52595.9\"],[\"1.4033\",\"36517.0\"],[\"1.4032\",\"39772.6\"],[\"1.4031\",\"38536.5\"],[\"1.4030\",\"26599.5\"],[\"1.4029\",\"41039.6\"],[\"1.4028\",\"25329.3\"],[\"1.4024\",\"57570.8\"],[\"1.4023\",\"130391.4\"],[\"1.4018\",\"47380.5\"],[\"1.4016\",\"62715.4\"],[\"1.4014\",\"193566.8\"],[\"1.4013\",\"74448.1\"],[\"1.4012\",\"130556.7\"],[\"1.4010\",\"86711.5\"],[\"1.4005\",\"190308.5\"],[\"1.4004\",\"34573.3\"],[\"1.4003\",\"30949.3\"],[\"1.4002\",\"51063.7\"],[\"1.3971\",\"61034.8\"],[\"1.3970\",\"199248.6\"],[\"1.3047\",\"383.0\"]],\"a\":[[\"1.4047\",\"40871.7\"],[\"1.4048\",\"74291.3\"],[\"1.4049\",\"101568.4\"],[\"1.4050\",\"69129.5\"],[\"1.4051\",\"60444.8\"],[\"1.4053\",\"62193.7\"],[\"1.4054\",\"68472.5\"],[\"1.4055\",\"74932.4\"],[\"1.4056\",\"70596.7\"],[\"1.4057\",\"58662.6\"],[\"1.4058\",\"52116.6\"],[\"1.4059\",\"60982.2\"],[\"1.4062\",\"64449.6\"],[\"1.4063\",\"147757.3\"],[\"1.4064\",\"112573.3\"],[\"1.4065\",\"65476.4\"],[\"1.4066\",\"53400.7\"],[\"1.4067\",\"71375.6\"],[\"1.4069\",\"45518.1\"],[\"1.4074\",\"147978.6\"],[\"1.4077\",\"74083.5\"],[\"1.4079\",\"232869.0\"],[\"1.4080\",\"127470.2\"],[\"1.4081\",\"74436.6\"],[\"1.4083\",\"41492.1\"],[\"1.4096\",\"62108.9\"],[\"1.4100\",\"363653.0\"],[\"1.4123\",\"30857.0\"],[\"1.4129\",\"20336.1\"],[\"1.4131\",\"7530.6\"],[\"1.4256\",\"1996.3\"],[\"1.5047\",\"0\"]],\"u\":9831470,\"seq\":241267329884},\"cts\":1778927736902}"}
{"ts":1778927737228,"data":"{\"topic\":\"orderbook.1000.XRPUSDT\",\"type\":\"delta\",\"ts\":1778927737103,\"data\":{\"s\":\"XRPUSDT\",\"b\":[[\"1.4046\",\"15070.2\"],[\"1.4045\",\"27648.7\"],[\"1.4044\",\"101340.1\"],[\"1.4043\",\"75095.2\"],[\"1.4040\",\"62868.1\"],[\"1.4037\",\"35300.8\"],[\"1.4034\",\"53116.9\"],[\"1.4033\",\"36545.5\"],[\"1.4030\",\"26595.9\"],[\"1.4029\",\"41036.0\"],[\"1.4027\",\"32171.4\"],[\"1.4025\",\"44547.7\"],[\"1.4022\",\"248594.8\"],[\"1.4020\",\"57112.2\"],[\"1.4017\",\"51779.1\"],[\"1.4011\",\"326593.3\"],[\"1.3998\",\"438881.8\"],[\"1.3962\",\"15671.8\"],[\"1.3961\",\"7147.2\"],[\"1.3899\",\"5997.1\"],[\"1.3693\",\"1287.9\"],[\"1.3610\",\"3203.4\"]],\"a\":[[\"1.4047\",\"44208.0\"],[\"1.4048\",\"79988.2\"],[\"1.4051\",\"60589.0\"],[\"1.4052\",\"51167.6\"],[\"1.4053\",\"61757.5\"],[\"1.4058\",\"52121.1\"],[\"1.4061\",\"53174.1\"],[\"1.4063\",\"125236.0\"],[\"1.4064\",\"69503.0\"],[\"1.4065\",\"128075.5\"],[\"1.4071\",\"93458.1\"],[\"1.4073\",\"44992.6\"],[\"1.4076\",\"85297.4\"],[\"1.4106\",\"31033.1\"],[\"1.4129\",\"10198.6\"]],\"u\":9831471,\"seq\":241267330191},\"cts\":1778927737099}"}
{"ts":1778927737427,"data":"{\"topic\":\"orderbook.1000.XRPUSDT\",\"type\":\"delta\",\"ts\":1778927737303,\"data\":{\"s\":\"XRPUSDT\",\"b\":[[\"1.4046\",\"0\"],[\"1.4045\",\"13302.9\"],[\"1.4044\",\"27971.1\"],[\"1.4043\",\"50328.4\"],[\"1.4042\",\"58169.7\"],[\"1.4041\",\"60481.8\"],[\"1.4038\",\"41875.1\"],[\"1.4037\",\"35967.7\"],[\"1.4036\",\"39902.5\"],[\"1.4035\",\"50758.6\"],[\"1.4033\",\"34578.7\"],[\"1.4032\",\"28990.0\"],[\"1.4031\",\"42106.9\"],[\"1.4030\",\"36110.4\"],[\"1.4028\",\"29186.6\"],[\"1.4027\",\"40776.2\"],[\"1.4026\",\"64001.7\"],[\"1.4025\",\"44551.7\"],[\"1.4023\",\"97521.3\"],[\"1.4022\",\"140095.0\"],[\"1.4018\",\"72518.5\"],[\"1.4017\",\"145035.1\"],[\"1.4013\",\"73499.2\"],[\"1.4012\",\"141343.9\"],[\"1.4011\",\"326450.6\"],[\"1.4010\",\"80857.8\"],[\"1.4009\",\"96704.0\"],[\"1.4006\",\"44161.8\"],[\"1.4004\",\"34566.2\"],[\"1.4001\",\"220742.3\"],[\"1.3994\",\"27693.2\"],[\"1.3987\",\"41923.5\"],[\"1.3986\",\"33732.0\"],[\"1.3974\",\"61662.6\"],[\"1.3973\",\"34864.1\"],[\"1.3970\",\"199252.2\"],[\"1.3857\",\"16096.8\"],[\"1.3835\",\"393014.1\"],[\"1.3832\",\"355119.0\"],[\"1.3829\",\"381731.8\"],[\"1.3697\",\"18157.1\"],[\"1.3610\",\"3218.0\"],[\"1.3457\",\"279.9\"],[\"1.3427\",\"1043.8\"],[\"1.3046\",\"4.7\"]],\"a\":[[\"1.4046\",\"36159.6\"],[\"1.4047\",\"41415.8\"],[\"1.4048\",\"77357.1\"],[\"1.4049\",\"94354.1\"],[\"1.4051\",\"60517.9\"],[\"1.4052\",\"57921.3\"],[\"1.4053\",\"65384.8\"],[\"1.4054\",\"72073.7\"],[\"1.4055\",\"91250.7\"],[\"1.4057\",\"55107.7\"],[\"1.4058\",\"63747.9\"],[\"1.4059\",\"60978.0\"],[\"1.4060\",\"49795.6\"],[\"1.4061\",\"53249.1\"],[\"1.4062\",\"64382.2\"],[\"1.4063\",\"149276.4\"],[\"1.4064\",\"112712.2\"],[\"1.4065\",\"70680.2\"],[\"1.4066\",\"53396.7\"],[\"1.4068\",\"65851.7\"],[\"1.4069\",\"49758.0\"],[\"1.4070\",\"61753.9\"],[\"1.4074\",\"137199.6\"],[\"1.4075\",\"443349.1\"],[\"1.4076\",\"85412.5\"],[\"1.4078\",\"137091.1\"],[\"1.4080\",\"39859.4\"],[\"1.4085\",\"38959.2\"],[\"1.4087\",\"46797.3\"],[\"1.4106\",\"31040.2\"],[\"1.4122\",\"58407.7\"],[\"1.4125\",\"27015.2\"],[\"1.4128\",\"22459.5\"],[\"1.4132\",\"6899.5\"],[\"1.4183\",\"4095.7\"],[\"1.4234\",\"434.3\"],[\"1.4257\",\"341348.4\"],[\"1.4260\",\"356032.3\"],[\"1.4263\",\"354291.0\"],[\"1.5046\",\"0\"]],\"u\":9831472,\"seq\":241267330699},\"cts\":1778927737302}"}
{"ts":1778927737627,"data":"{\"topic\":\"orderbook.1000.XRPUSDT\",\"type\":\"delta\",\"ts\":1778927737503,\"data\":{\"s\":\"XRPUSDT\",\"b\":[[\"1.4045\",\"23311.8\"],[\"1.4044\",\"27964.2\"],[\"1.4043\",\"88479.4\"],[\"1.4042\",\"56907.6\"],[\"1.4041\",\"68172.7\"],[\"1.4038\",\"41878.7\"],[\"1.4036\",\"38121.3\"],[\"1.4033\",\"43644.0\"],[\"1.4031\",\"38538.3\"],[\"1.4028\",\"28318.3\"],[\"1.4027\",\"41622.0\"],[\"1.4026\",\"64005.3\"],[\"1.4025\",\"44547.7\"],[\"1.4024\",\"57574.8\"],[\"1.4020\",\"57022.8\"],[\"1.4015\",\"92743.7\"],[\"1.4014\",\"193618.5\"],[\"1.4013\",\"54183.8\"],[\"1.4012\",\"160609.4\"],[\"1.4009\",\"91236.0\"],[\"1.3982\",\"53879.5\"],[\"1.3970\",\"198540.0\"],[\"1.3969\",\"40394.4\"],[\"1.3962\",\"15690.3\"],[\"1.3955\",\"82846.0\"],[\"1.3951\",\"778.3\"],[\"1.3948\",\"24561.5\"],[\"1.3945\",\"5712.8\"],[\"1.3938\",\"3077.0\"],[\"1.3935\",\"7935.5\"],[\"1.3934\",\"1125.5\"],[\"1.3931\",\"4147.4\"],[\"1.3930\",\"107948.1\"],[\"1.3927\",\"1177.8\"],[\"1.3924\",\"1586.8\"],[\"1.3903\",\"2273.7\"],[\"1.3901\",\"2617.4\"],[\"1.3896\",\"5489.0\"],[\"1.3842\",\"45581.6\"],[\"1.3835\",\"411048.0\"],[\"1.3793\",\"13633.9\"],[\"1.3783\",\"8420.6\"],[\"1.3782\",\"28564.5\"],[\"1.3779\",\"392.5\"],[\"1.3764\",\"464.2\"],[\"1.3750\",\"22230.4\"],[\"1.3736\",\"17585.6\"],[\"1.3730\",\"7932.1\"],[\"1.3708\",\"560.2\"],[\"1.3694\",\"21766.7\"],[\"1.3680\",\"28993.2\"],[\"1.3662\",\"2583.7\"],[\"1.3609\",\"15283.6\"],[\"1.3597\",\"3049.4\"],[\"1.3592\",\"4324.4\"],[\"1.3567\",\"15207.3\"],[\"1.3371\",\"1390.4\"],[\"1.3344\",\"2733.3\"],[\"1.3343\",\"195.4\"],[\"1.3315\",\"2069.0\"]],\"a\":[[\"1.4046\",\"28078.0\"],[\"1.4047\",\"34147.1\"],[\"1.4048\",\"101936.3\"],[\"1.4049\",\"93527.4\"],[\"1.4050\",\"64563.3\"],[\"1.4051\",\"57001.1\"],[\"1.4052\",\"58633.1\"],[\"1.4053\",\"64673.0\"],[\"1.4054\",\"63392.3\"],[\"1.4055\",\"78492.3\"],[\"1.4056\",\"67676.7\"],[\"1.4057\",\"51548.3\"],[\"1.4060\",\"49799.6\"],[\"1.4061\",\"61214.2\"],[\"1.4062\",\"91073.9\"],[\"1.4063\",\"120793.1\"],[\"1.4064\",\"112716.2\"],[\"1.4066\",\"53080.5\"],[\"1.4070\",\"62070.2\"],[\"1.4078\",\"143440.2\"],[\"1.4122\",\"58404.1\"],[\"1.4240\",\"15634.0\"],[\"1.4301\",\"38108.5\"]],\"u\":9831473,\"seq\":241267331055},\"cts\":1778927737502}"}
{"ts":1778927737829,"data":"{\"topic\":\"orderbook.1000.XRPUSDT\",\"type\":\"delta\",\"ts\":1778927737703,\"data\":{\"s\":\"XRPUSDT\",\"b\":[[\"1.4045\",\"23299.1\"],[\"1.4043\",\"56110.5\"],[\"1.4036\",\"38477.5\"],[\"1.4033\",\"40305.3\"],[\"1.4032\",\"34685.3\"],[\"1.4025\",\"44562.8\"],[\"1.4015\",\"168665.4\"],[\"1.4012\",\"106726.5\"],[\"1.4011\",\"250144.5\"],[\"1.3986\",\"28036.7\"],[\"1.3966\",\"80129.6\"],[\"1.3964\",\"111106.2\"],[\"1.3963\",\"51316.3\"],[\"1.3899\",\"5990.0\"],[\"1.3835\",\"36186.3\"],[\"1.3832\",\"687.6\"],[\"1.3829\",\"7133.7\"]],\"a\":[[\"1.4046\",\"28104.4\"],[\"1.4047\",\"48138.7\"],[\"1.4062\",\"91390.2\"],[\"1.4063\",\"120909.3\"],[\"1.4064\",\"112880.2\"],[\"1.4070\",\"61753.9\"],[\"1.4071\",\"76902.0\"],[\"1.4072\",\"69977.2\"],[\"1.4075\",\"498532.9\"],[\"1.4080\",\"63646.9\"],[\"1.4081\",\"50649.1\"],[\"1.4093\",\"49675.5\"],[\"1.4114\",\"59304.5\"],[\"1.4115\",\"53681.4\"],[\"1.4125\",\"27131.9\"],[\"1.4128\",\"12312.1\"],[\"1.4129\",\"51.2\"],[\"1.4200\",\"14568.0\"],[\"1.4257\",\"17849.3\"],[\"1.4260\",\"11813.7\"],[\"1.4263\",\"3689.2\"]],\"u\":9831474,\"seq\":241267331413},\"cts\":1778927737702}"}
{"ts":1778927738027,"data":"{\"topic\":\"orderbook.1000.XRPUSDT\",\"type\":\"delta\",\"ts\":1778927737903,\"data\":{\"s\":\"XRPUSDT\",\"b\":[[\"1.4045\",\"19928.7\"],[\"1.4044\",\"27928.9\"],[\"1.4043\",\"56132.7\"],[\"1.4042\",\"62565.3\"],[\"1.4033\",\"42273.1\"],[\"1.4032\",\"38250.1\"],[\"1.4028\",\"28321.9\"],[\"1.4026\",\"64001.7\"],[\"1.4016\",\"84515.8\"],[\"1.4015\",\"168658.3\"],[\"1.3961\",\"7143.6\"],[\"1.3958\",\"8796.8\"]],\"a\":[[\"1.4053\",\"61113.4\"],[\"1.4054\",\"66952.2\"],[\"1.4055\",\"82051.2\"],[\"1.4056\",\"64117.9\"],[\"1.4057\",\"51613.2\"],[\"1.4076\",\"84246.9\"],[\"1.4077\",\"75299.4\"],[\"1.4674\",\"138.5\"]],\"u\":9831475,\"seq\":241267331762},\"cts\":1778927737898}"}
{"ts":1778927738228,"data":"{\"topic\":\"orderbook.1000.XRPUSDT\",\"type\":\"delta\",\"ts\":1778927738104,\"data\":{\"s\":\"XRPUSDT\",\"b\":[[\"1.4045\",\"15385.0\"],[\"1.4043\",\"56121.7\"],[\"1.4034\",\"52595.9\"],[\"1.4033\",\"36740.6\"],[\"1.4020\",\"53643.6\"],[\"1.4019\",\"56539.9\"],[\"1.4016\",\"83994.8\"],[\"1.4009\",\"97420.5\"],[\"1.3997\",\"20795.2\"],[\"1.3966\",\"56342.1\"],[\"1.3965\",\"51313.7\"],[\"1.3963\",\"41208.1\"],[\"1.3923\",\"105619.1\"],[\"1.3814\",\"7173.5\"],[\"1.3722\",\"4048.8\"],[\"1.3694\",\"18261.6\"],[\"1.3643\",\"2627.9\"],[\"1.3610\",\"3203.4\"]],\"a\":[[\"1.4046\",\"28132.1\"],[\"1.4049\",\"93893.5\"],[\"1.4052\",\"58113.1\"],[\"1.4054\",\"72489.5\"],[\"1.4057\",\"51617.7\"],[\"1.4058\",\"63743.4\"],[\"1.4061\",\"58124.5\"],[\"1.4062\",\"91460.6\"],[\"1.4064\",\"112360.2\"],[\"1.4083\",\"40973.1\"],[\"1.4092\",\"26890.8\"],[\"1.4094\",\"48602.2\"],[\"1.4119\",\"40199.8\"],[\"1.4121\",\"100158.1\"],[\"1.4128\",\"2174.6\"],[\"1.4159\",\"8095.6\"],[\"1.4213\",\"18105.4\"],[\"1.4332\",\"287.0\"]],\"u\":9831476,\"seq\":241267332001},\"cts\":1778927738100}"}
{"ts":1778927738428,"data":"{\"topic\":\"orderbook.1000.XRPUSDT\",\"type\":\"delta\",\"ts\":1778927738303,\"data\":{\"s\":\"XRPUSDT\",\"b\":[[\"1.4042\",\"62569.3\"],[\"1.4033\",\"42286.9\"],[\"1.4023\",\"97517.3\"],[\"1.4021\",\"67502.7\"],[\"1.4009\",\"91236.0\"],[\"1.3965\",\"27526.2\"],[\"1.3964\",\"134893.7\"],[\"1.3960\",\"11364.3\"],[\"1.3610\",\"3225.3\"]],\"a\":[[\"1.4046\",\"28147.5\"],[\"1.4047\",\"48202.5\"],[\"1.4051\",\"53398.7\"],[\"1.4052\",\"68795.5\"],[\"1.4053\",\"61046.0\"],[\"1.4054\",\"66952.2\"],[\"1.4061\",\"58057.1\"],[\"1.4091\",\"260860.1\"],[\"1.4121\",\"100161.7\"]],\"u\":9831477,\"seq\":241267332128},\"cts\":1778927738301}"}
{"ts":1778927738627,"data":"{\"topic\":\"orderbook.1000.XRPUSDT\",\"type\":\"delta\",\"ts\":1778927738503,\"data\":{\"s\":\"XRPUSDT\",\"b\":[[\"1.4045\",\"15377.7\"],[\"1.4043\",\"70878.5\"],[\"1.4022\",\"146822.2\"],[\"1.4016\",\"62194.4\"],[\"1.4015\",\"92736.6\"],[\"1.4004\",\"34567.5\"],[\"1.3998\",\"299577.2\"]],\"a\":[[\"1.4048\",\"101939.9\"],[\"1.4050\",\"68165.9\"],[\"1.4075\",\"443349.1\"],[\"1.4084\",\"65516.5\"]],\"u\":9831478,\"seq\":241267332249},\"cts\":1778927738501}"}
{"ts":1778927738828,"data":"{\"topic\":\"orderbook.1000.XRPUSDT\",\"type\":\"delta\",\"ts\":1778927738703,\"data\":{\"s\":\"XRPUSDT\",\"b\":[[\"1.4042\",\"67569.3\"],[\"1.4041\",\"63172.7\"],[\"1.4029\",\"41039.6\"],[\"1.4028\",\"28318.3\"],[\"1.4016\",\"83992.5\"],[\"1.4015\",\"168657.9\"],[\"1.4014\",\"193542.2\"],[\"1.4002\",\"190326.8\"],[\"1.3994\",\"27689.6\"],[\"1.3990\",\"20699.0\"],[\"1.3980\",\"145328.4\"],[\"1.3976\",\"28061.8\"],[\"1.3958\",\"8793.2\"],[\"1.3954\",\"55635.2\"],[\"1.3813\",\"18317.3\"],[\"1.3757\",\"16615.4\"],[\"1.3751\",\"23876.2\"],[\"1.3695\",\"9851.4\"]],\"a\":[[\"1.4062\",\"91464.6\"],[\"1.4075\",\"499046.3\"],[\"1.4088\",\"215389.2\"],[\"1.4107\",\"60210.0\"],[\"1.4110\",\"146845.9\"],[\"1.4121\",\"100157.2\"],[\"1.4122\",\"58408.6\"]],\"u\":9831479,\"seq\":241267332380},\"cts\":1778927738701}"}
{"ts":1778927739027,"data":"{\"topic\":\"orderbook.1000.XRPUSDT\",\"type\":\"delta\",\"ts\":1778927738903,\"data\":{\"s\":\"XRPUSDT\",\"b\":[[\"1.4044\",\"27946.4\"],[\"1.4043\",\"72371.0\"],[\"1.4041\",\"63176.7\"],[\"1.4029\",\"41036.0\"],[\"1.4028\",\"28321.9\"],[\"1.3994\",\"27693.2\"],[\"1.3990\",\"20695.4\"],[\"1.3963\",\"41063.3\"],[\"1.3958\",\"8796.8\"],[\"1.3954\",\"55631.6\"],[\"1.3610\",\"3203.4\"]],\"a\":[[\"1.4054\",\"63392.3\"],[\"1.4125\",\"27015.2\"]],\"u\":9831480,\"seq\":241267332625},\"cts\":1778927738893}"}
{"ts":1778927739228,"data":"{\"topic\":\"orderbook.1000.XRPUSDT\",\"type\":\"delta\",\"ts\":1778927739103,\"data\":{\"s\":\"XRPUSDT\",\"b\":[[\"1.4045\",\"0\"],[\"1.4044\",\"7654.3\"],[\"1.4043\",\"10065.8\"],[\"1.4042\",\"15802.5\"],[\"1.4041\",\"16437.1\"],[\"1.4040\",\"80708.8\"],[\"1.4037\",\"38513.1\"],[\"1.4036\",\"38325.7\"],[\"1.4035\",\"47793.1\"],[\"1.4034\",\"47433.3\"],[\"1.4033\",\"31912.3\"],[\"1.4032\",\"44764.8\"],[\"1.4031\",\"34026.7\"],[\"1.4030\",\"43889.2\"],[\"1.4029\",\"40894.0\"],[\"1.4028\",\"39151.2\"],[\"1.4027\",\"43287.0\"],[\"1.4026\",\"51873.6\"],[\"1.4025\",\"46725.5\"],[\"1.4024\",\"57308.9\"],[\"1.4022\",\"150927.9\"],[\"1.4021\",\"46192.8\"],[\"1.4019\",\"53313.6\"],[\"1.4018\",\"76060.2\"],[\"1.4017\",\"145120.6\"],[\"1.4015\",\"168800.6\"],[\"1.4014\",\"193494.2\"],[\"1.4013\",\"54229.9\"],[\"1.4012\",\"95942.9\"],[\"1.4011\",\"250140.9\"],[\"1.4010\",\"91690.7\"],[\"1.4008\",\"66727.2\"],[\"1.4007\",\"42935.9\"],[\"1.4005\",\"167703.5\"],[\"1.4002\",\"214114.3\"],[\"1.4000\",\"286092.1\"],[\"1.3999\",\"22007.1\"],[\"1.3974\",\"63100.9\"],[\"1.3969\",\"40401.6\"],[\"1.3964\",\"111106.2\"],[\"1.3963\",\"51196.6\"],[\"1.3959\",\"410112.0\"],[\"1.3956\",\"6546.3\"],[\"1.3936\",\"331266.7\"],[\"1.3933\",\"423997.3\"],[\"1.3930\",\"419720.5\"],[\"1.3904\",\"2675.3\"],[\"1.3876\",\"36536.4\"],[\"1.3610\",\"3232.6\"],[\"1.3539\",\"1131.4\"],[\"1.3315\",\"2519.6\"],[\"1.3045\",\"762.8\"]],\"a\":[[\"1.4045\",\"57973.3\"],[\"1.4046\",\"38854.0\"],[\"1.4047\",\"86195.7\"],[\"1.4048\",\"105613.7\"],[\"1.4049\",\"101449.6\"],[\"1.4050\",\"57495.1\"],[\"1.4051\",\"55218.1\"],[\"1.4052\",\"76678.0\"],[\"1.4053\",\"80016.9\"],[\"1.4054\",\"79394.6\"],[\"1.4055\",\"70354.3\"],[\"1.4056\",\"64572.6\"],[\"1.4057\",\"52243.8\"],[\"1.4058\",\"62293.8\"],[\"1.4059\",\"50214.2\"],[\"1.4060\",\"49344.9\"],[\"1.4063\",\"177882.3\"],[\"1.4064\",\"55387.2\"],[\"1.4069\",\"55446.6\"],[\"1.4071\",\"71364.8\"],[\"1.4073\",\"46342.9\"],[\"1.4074\",\"148032.5\"],[\"1.4076\",\"74530.1\"],[\"1.4077\",\"74083.5\"],[\"1.4078\",\"137091.1\"],[\"1.4083\",\"43095.1\"],[\"1.4085\",\"38108.0\"],[\"1.4088\",\"215512.8\"],[\"1.4121\",\"100158.1\"],[\"1.4122\",\"58404.1\"],[\"1.4154\",\"325701.5\"],[\"1.4157\",\"428553.2\"],[\"1.4160\",\"509585.3\"],[\"1.5045\",\"0\"]],\"u\":9831481,\"seq\":241267333384},\"cts\":1778927739101}"}
{"ts":1778927739427,"data":"{\"topic\":\"orderbook.1000.XRPUSDT\",\"type\":\"delta\",\"ts\":1778927739303,\"data\":{\"s\":\"XRPUSDT\",\"b\":[[\"1.4044\",\"18870.3\"],[\"1.4043\",\"10058.9\"],[\"1.4042\",\"47954.9\"],[\"1.4041\",\"71342.8\"],[\"1.4040\",\"74935.3\"],[\"1.4039\",\"50134.0\"],[\"1.4037\",\"38516.8\"],[\"1.4036\",\"38688.8\"],[\"1.4034\",\"47077.1\"],[\"1.4033\",\"36438.5\"],[\"1.4032\",\"50774.3\"],[\"1.4031\",\"40975.2\"],[\"1.4030\",\"40323.9\"],[\"1.4029\",\"34365.4\"],[\"1.4026\",\"51869.1\"],[\"1.4025\",\"46724.9\"],[\"1.4024\",\"57308.5\"],[\"1.4023\",\"97521.3\"],[\"1.4012\",\"76679.1\"],[\"1.4011\",\"269312.3\"],[\"1.4008\",\"59111.0\"],[\"1.3974\",\"63093.8\"],[\"1.3904\",\"2671.2\"]],\"a\":[[\"1.4045\",\"46745.8\"],[\"1.4046\",\"38762.6\"],[\"1.4047\",\"86206.6\"],[\"1.4048\",\"93974.4\"],[\"1.4049\",\"94676.0\"],[\"1.4050\",\"68788.2\"],[\"1.4053\",\"69187.2\"],[\"1.4054\",\"66858.4\"],[\"1.4055\",\"70613.0\"],[\"1.4056\",\"61013.2\"],[\"1.4057\",\"52236.9\"],[\"1.4059\",\"50218.2\"],[\"1.4060\",\"49408.3\"],[\"1.4061\",\"97709.4\"],[\"1.4062\",\"119955.2\"],[\"1.4063\",\"104814.6\"],[\"1.4076\",\"74526.4\"],[\"1.4077\",\"80298.7\"],[\"1.4121\",\"100154.5\"],[\"1.4127\",\"24508.1\"]],\"u\":9831482,\"seq\":241267333714},\"cts\":1778927739301}"}
{"ts":1778927739627,"data":"{\"topic\":\"orderbook.1000.XRPUSDT\",\"type\":\"delta\",\"ts\":1778927739503,\"data\":{\"s\":\"XRPUSDT\",\"b\":[[\"1.4042\",\"63856.7\"],[\"1.4041\",\"60280.7\"],[\"1.4040\",\"63442.3\"],[\"1.4039\",\"49694.2\"],[\"1.4038\",\"42103.7\"],[\"1.4029\",\"35075.0\"],[\"1.4025\",\"46728.5\"],[\"1.4021\",\"46196.4\"],[\"1.4019\",\"56541.5\"],[\"1.4018\",\"72834.8\"],[\"1.4011\",\"269333.9\"],[\"1.4003\",\"54736.8\"],[\"1.4002\",\"190326.8\"],[\"1.4000\",\"285806.4\"],[\"1.3963\",\"74984.1\"],[\"1.3959\",\"386324.5\"],[\"1.3884\",\"1119.3\"]],\"a\":[[\"1.4045\",\"40073.2\"],[\"1.4046\",\"37530.6\"],[\"1.4047\",\"86210.2\"],[\"1.4048\",\"93974.1\"],[\"1.4051\",\"54020.0\"],[\"1.4053\",\"70371.6\"],[\"1.4054\",\"70418.5\"],[\"1.4057\",\"51607.2\"],[\"1.4063\",\"104807.4\"],[\"1.4073\",\"44992.6\"],[\"1.4074\",\"149197.2\"],[\"1.4079\",\"256656.5\"],[\"1.4080\",\"39859.4\"],[\"1.4113\",\"62084.6\"],[\"1.4114\",\"35517.0\"],[\"1.4134\",\"289.5\"]],\"u\":9831483,\"seq\":241267333823},\"cts\":1778927739496}"}
{"ts":1778927739827,"data":"{\"topic\":\"orderbook.1000.XRPUSDT\",\"type\":\"delta\",\"ts\":1778927739703,\"data\":{\"s\":\"XRPUSDT\",\"b\":[[\"1.4044\",\"19072.5\"],[\"1.4042\",\"50022.9\"],[\"1.4041\",\"54512.2\"],[\"1.4040\",\"63438.7\"],[\"1.4027\",\"43290.6\"],[\"1.4024\",\"57304.9\"],[\"1.4021\",\"46200.0\"],[\"1.4012\",\"76675.5\"],[\"1.4010\",\"91694.3\"],[\"1.4008\",\"65311.5\"],[\"1.3610\",\"3203.4\"],[\"1.3482\",\"962.9\"]],\"a\":[[\"1.4048\",\"93959.1\"],[\"1.4059\",\"50285.6\"],[\"1.4060\",\"57311.9\"],[\"1.4068\",\"67352.1\"],[\"1.4127\",\"14360.7\"],[\"1.4147\",\"9694.0\"],[\"1.4178\",\"132.5\"],[\"1.4184\",\"6857.4\"]],\"u\":9831484,\"seq\":241267333908},\"cts\":1778927739687}"}
{"ts":1778927740027,"data":"{\"topic\":\"orderbook.1000.XRPUSDT\",\"type\":\"delta\",\"ts\":1778927739903,\"data\":{\"s\":\"XRPUSDT\",\"b\":[[\"1.4044\",\"10241.3\"],[\"1.4043\",\"10036.7\"],[\"1.4042\",\"33032.6\"],[\"1.4041\",\"69506.1\"],[\"1.4040\",\"64662.2\"],[\"1.4036\",\"38332.6\"],[\"1.4035\",\"48149.3\"],[\"1.4032\",\"46348.1\"],[\"1.4031\",\"37410.0\"],[\"1.4030\",\"43889.1\"],[\"1.4029\",\"40894.0\"],[\"1.4028\",\"39860.8\"],[\"1.4027\",\"43287.0\"],[\"1.4026\",\"51872.7\"],[\"1.4019\",\"53313.6\"],[\"1.4018\",\"76060.7\"],[\"1.4003\",\"30949.3\"],[\"1.4002\",\"214114.3\"],[\"1.3963\",\"51196.6\"],[\"1.3961\",\"30931.1\"],[\"1.3960\",\"11371.4\"],[\"1.3930\",\"419713.4\"],[\"1.3610\",\"3239.9\"]],\"a\":[[\"1.4045\",\"46745.8\"],[\"1.4046\",\"37598.0\"],[\"1.4048\",\"94310.2\"],[\"1.4049\",\"94679.6\"],[\"1.4050\",\"65185.6\"],[\"1.4053\",\"75608.4\"],[\"1.4057\",\"52206.9\"],[\"1.4059\",\"50289.8\"],[\"1.4060\",\"57244.5\"],[\"1.4077\",\"74083.5\"],[\"1.4082\",\"35011.2\"],[\"1.4083\",\"42243.9\"],[\"1.4228\",\"8787.9\"]],\"u\":9831485,\"seq\":241267334154},\"cts\":1778927739891}"}
{"ts":1778927740230,"data":"{\"topic\":\"orderbook.1000.XRPUSDT\",\"type\":\"delta\",\"ts\":1778927740104,\"data\":{\"s\":\"XRPUSDT\",\"b\":[[\"1.4044\",\"10230.5\"],[\"1.4042\",\"33112.6\"],[\"1.4041\",\"63736.3\"],[\"1.4040\",\"58893.7\"],[\"1.4031\",\"40975.2\"],[\"1.4030\",\"40323.9\"],[\"1.4021\",\"46203.6\"],[\"1.4020\",\"74847.8\"],[\"1.3994\",\"27689.6\"],[\"1.3993\",\"42774.1\"],[\"1.3976\",\"28056.8\"],[\"1.3955\",\"81412.9\"],[\"1.3677\",\"7538.7\"]],\"a\":[[\"1.4045\",\"46792.4\"],[\"1.4046\",\"37595.4\"],[\"1.4053\",\"84345.1\"],[\"1.4054\",\"66859.3\"],[\"1.4056\",\"61017.7\"],[\"1.4057\",\"52202.4\"],[\"1.4059\",\"50222.4\"],[\"1.4127\",\"4223.2\"]],\"u\":9831486,\"seq\":241267334267},\"cts\":1778927740097}"}
{"ts":1778927740428,"data":"{\"topic\":\"orderbook.1000.XRPUSDT\",\"type\":\"delta\",\"ts\":1778927740304,\"data\":{\"s\":\"XRPUSDT\",\"b\":[[\"1.4044\",\"10234.0\"],[\"1.4042\",\"47774.0\"],[\"1.4041\",\"58736.3\"],[\"1.4040\",\"63893.7\"],[\"1.4021\",\"46200.0\"],[\"1.4000\",\"285520.7\"],[\"1.3999\",\"21843.0\"],[\"1.3976\",\"28061.8\"]],\"a\":[[\"1.4053\",\"75608.4\"],[\"1.4054\",\"66858.6\"],[\"1.4058\",\"62365.0\"],[\"1.4061\",\"98135.7\"],[\"1.4062\",\"120025.8\"],[\"1.4068\",\"67348.5\"],[\"1.4075\",\"499050.8\"],[\"1.4076\",\"74521.9\"],[\"1.4079\",\"256660.1\"],[\"1.4088\",\"215389.2\"],[\"1.4209\",\"10984.1\"]],\"u\":9831487,\"seq\":241267334373},\"cts\":1778927740298}"}
{"ts":1778927740627,"data":"{\"topic\":\"orderbook.1000.XRPUSDT\",\"type\":\"delta\",\"ts\":1778927740503,\"data\":{\"s\":\"XRPUSDT\",\"b\":[[\"1.4044\",\"14841.8\"],[\"1.4042\",\"70162.8\"],[\"1.4041\",\"53008.5\"],[\"1.4032\",\"46415.5\"],[\"1.4029\",\"35074.5\"],[\"1.4028\",\"39151.2\"],[\"1.4025\",\"46732.3\"],[\"1.4021\",\"46203.6\"],[\"1.4019\",\"56487.5\"],[\"1.4018\",\"72834.8\"],[\"1.4017\",\"145113.5\"],[\"1.4016\",\"83996.1\"],[\"1.4012\",\"76671.9\"],[\"1.4009\",\"91232.4\"],[\"1.4008\",\"59111.0\"],[\"1.4003\",\"54736.8\"],[\"1.4002\",\"190330.4\"],[\"1.3962\",\"39477.8\"],[\"1.3961\",\"7143.6\"],[\"1.3936\",\"3601.8\"],[\"1.3935\",\"7933.7\"],[\"1.3933\",\"32647.1\"],[\"1.3930\",\"107941.0\"]],\"a\":[[\"1.4045\",\"46741.5\"],[\"1.4046\",\"37582.6\"],[\"1.4050\",\"68788.5\"],[\"1.4052\",\"76748.9\"],[\"1.4053\",\"70371.6\"],[\"1.4059\",\"50289.8\"],[\"1.4077\",\"80456.6\"],[\"1.4082\",\"34968.0\"],[\"1.4090\",\"208556.1\"],[\"1.4154\",\"10213.0\"],[\"1.4157\",\"8634.6\"],[\"1.4160\",\"94311.3\"]],\"u\":9831488,\"seq\":241267334516},\"cts\":1778927740501}"}
{"ts":1778927740827,"data":"{\"topic\":\"orderbook.1000.XRPUSDT\",\"type\":\"delta\",\"ts\":1778927740703,\"data\":{\"s\":\"XRPUSDT\",\"b\":[[\"1.4044\",\"11434.0\"],[\"1.4042\",\"62596.1\"],[\"1.4041\",\"58735.7\"],[\"1.4040\",\"71583.8\"],[\"1.4039\",\"42003.7\"],[\"1.4029\",\"40894.5\"],[\"1.4028\",\"39860.3\"],[\"1.4026\",\"51869.1\"],[\"1.4025\",\"46735.9\"],[\"1.4021\",\"46200.0\"],[\"1.4008\",\"64771.1\"],[\"1.4001\",\"220745.9\"],[\"1.3994\",\"27693.2\"],[\"1.3993\",\"42770.5\"],[\"1.3974\",\"62378.2\"],[\"1.3938\",\"3078.8\"],[\"1.3876\",\"36530.6\"],[\"1.3610\",\"3203.4\"]],\"a\":[[\"1.4045\",\"44208.6\"],[\"1.4046\",\"37515.2\"],[\"1.4054\",\"70418.7\"],[\"1.4060\",\"57311.9\"],[\"1.4091\",\"260864.6\"],[\"1.4092\",\"26886.3\"]],\"u\":9831489,\"seq\":241267334664},\"cts\":1778927740701}"}
{"ts":1778927741027,"data":"{\"topic\":\"orderbook.1000.XRPUSDT\",\"type\":\"delta\",\"ts\":1778927740903,\"data\":{\"s\":\"XRPUSDT\",\"b\":[[\"1.4042\",\"72728.0\"],[\"1.4041\",\"47228.6\"],[\"1.4040\",\"71587.4\"],[\"1.4035\",\"48291.8\"],[\"1.4033\",\"36602.1\"],[\"1.4029\",\"35074.5\"],[\"1.4028\",\"39151.2\"],[\"1.4026\",\"51872.7\"],[\"1.4025\",\"46568.7\"],[\"1.4021\",\"46207.2\"],[\"1.4019\",\"53313.6\"],[\"1.4018\",\"76006.5\"],[\"1.4017\",\"145106.4\"],[\"1.3885\",\"10808.7\"],[\"1.3610\",\"3254.5\"]],\"a\":[[\"1.4050\",\"65185.6\"],[\"1.4054\",\"66858.6\"]],\"u\":9831490,\"seq\":241267334769},\"cts\":1778927740889}"}
{"ts":1778927741227,"data":"{\"topic\":\"orderbook.1000.XRPUSDT\",\"type\":\"delta\",\"ts\":1778927741103,\"data\":{\"s\":\"XRPUSDT\",\"b\":[[\"1.4044\",\"11451.5\"],[\"1.4042\",\"61268.9\"],[\"1.4040\",\"71583.8\"],[\"1.4035\",\"48284.8\"],[\"1.4025\",\"46570.3\"],[\"1.4021\",\"46200.0\"],[\"1.4020\",\"74840.8\"],[\"1.4003\",\"30949.3\"],[\"1.4002\",\"214117.9\"],[\"1.4001\",\"220749.5\"],[\"1.3962\",\"15690.3\"],[\"1.3961\",\"30931.1\"],[\"1.3904\",\"1988.1\"],[\"1.3899\",\"5986.4\"],[\"1.3884\",\"1125.1\"],[\"1.3821\",\"1533.1\"],[\"1.3818\",\"907.3\"],[\"1.3517\",\"2438.6\"]],\"a\":[[\"1.4045\",\"44209.4\"],[\"1.4061\",\"98206.6\"],[\"1.4106\",\"31033.1\"],[\"1.4267\",\"26054.2\"],[\"1.4269\",\"18010.6\"]],\"u\":9831491,\"seq\":241267334917},\"cts\":1778927741093}"}
{"ts":1778927741427,"data":"{\"topic\":\"orderbook.1000.XRPUSDT\",\"type\":\"delta\",\"ts\":1778927741303,\"data\":{\"s\":\"XRPUSDT\",\"b\":[[\"1.4044\",\"11457.0\"],[\"1.4041\",\"52228.6\"],[\"1.4040\",\"66583.8\"],[\"1.4037\",\"38644.0\"],[\"1.4025\",\"44395.8\"],[\"1.4024\",\"59478.6\"],[\"1.4021\",\"46203.6\"],[\"1.4017\",\"145035.1\"],[\"1.4015\",\"168657.9\"]],\"a\":[[\"1.4048\",\"101430.5\"],[\"1.4049\",\"87559.4\"],[\"1.4050\",\"65306.6\"],[\"1.4054\",\"70418.7\"],[\"1.4106\",\"31040.2\"]],\"u\":9831492,\"seq\":241267335012},\"cts\":1778927741296}"}
{"ts":1778927741627,"data":"{\"topic\":\"orderbook.1000.XRPUSDT\",\"type\":\"delta\",\"ts\":1778927741504,\"data\":{\"s\":\"XRPUSDT\",\"b\":[[\"1.4040\",\"66587.4\"],[\"1.4019\",\"53242.3\"],[\"1.3974\",\"61662.6\"],[\"1.3836\",\"26334.1\"]],\"a\":[[\"1.4051\",\"54091.1\"],[\"1.4053\",\"74073.5\"],[\"1.4054\",\"66859.3\"]],\"u\":9831493,\"seq\":241267335094},\"cts\":1778927741499}"}
{"ts":1778927741827,"data":"{\"topic\":\"orderbook.1000.XRPUSDT\",\"type\":\"delta\",\"ts\":1778927741703,\"data\":{\"s\":\"XRPUSDT\",\"b\":[[\"1.4044\",\"11451.5\"],[\"1.4019\",\"56353.3\"],[\"1.4018\",\"72834.8\"],[\"1.4008\",\"64764.0\"],[\"1.3904\",\"1981.0\"]],\"a\":[[\"1.4045\",\"44143.3\"],[\"1.4046\",\"37488.8\"],[\"1.4048\",\"94310.2\"],[\"1.4049\",\"94679.6\"]],\"u\":9831494,\"seq\":241267335205},\"cts\":1778927741702}"}
{"ts":1778927742027,"data":"{\"topic\":\"orderbook.1000.XRPUSDT\",\"type\":\"delta\",\"ts\":1778927741903,\"data\":{\"s\":\"XRPUSDT\",\"b\":[[\"1.4044\",\"11446.0\"],[\"1.4041\",\"52239.7\"],[\"1.4019\",\"56346.3\"]],\"a\":[[\"1.4049\",\"98282.5\"],[\"1.4054\",\"63299.2\"],[\"1.4055\",\"70776.6\"],[\"1.4071\",\"71201.2\"]],\"u\":9831495,\"seq\":241267335397},\"cts\":1778927741892}"}
{"ts":1778927742230,"data":"{\"topic\":\"orderbook.1000.XRPUSDT\",\"type\":\"delta\",\"ts\":1778927742105,\"data\":{\"s\":\"XRPUSDT\",\"b\":[[\"1.4044\",\"11457.0\"],[\"1.4042\",\"72498.5\"],[\"1.4024\",\"49562.5\"],[\"1.4023\",\"69744.1\"],[\"1.4019\",\"56283.3\"],[\"1.4012\",\"104658.2\"],[\"1.4006\",\"44145.8\"],[\"1.4001\",\"35224.1\"],[\"1.3994\",\"27689.6\"],[\"1.3988\",\"34829.4\"],[\"1.3984\",\"247450.1\"]],\"a\":[[\"1.4054\",\"66859.3\"],[\"1.4067\",\"78893.2\"],[\"1.4068\",\"94934.9\"],[\"1.4075\",\"471134.6\"],[\"1.4251\",\"41747.7\"]],\"u\":9831496,\"seq\":241267335605},\"cts\":1778927742095}"}
{"ts":1778927742428,"data":"{\"topic\":\"orderbook.1000.XRPUSDT\",\"type\":\"delta\",\"ts\":1778927742304,\"data\":{\"s\":\"XRPUSDT\",\"b\":[[\"1.4044\",\"11439.5\"],[\"1.4006\",\"44161.8\"]],\"a\":[[\"1.4045\",\"58366.2\"],[\"1.4049\",\"94679.6\"],[\"1.4052\",\"78822.7\"],[\"1.4054\",\"63299.2\"],[\"1.4056\",\"58943.9\"],[\"1.4062\",\"120094.1\"]],\"u\":9831497,\"seq\":241267335858},\"cts\":1778927742301}"}
{"ts":1778927742627,"data":"{\"topic\":\"orderbook.1000.XRPUSDT\",\"type\":\"delta\",\"ts\":1778927742504,\"data\":{\"s\":\"XRPUSDT\",\"b\":[[\"1.4044\",\"11434.0\"],[\"1.3987\",\"387673.0\"],[\"1.3984\",\"667250.2\"],[\"1.3981\",\"657314.8\"],[\"1.3961\",\"7143.6\"],[\"1.3960\",\"35158.9\"]],\"a\":[[\"1.4045\",\"58385.1\"],[\"1.4102\",\"457426.3\"],[\"1.4105\",\"415283.8\"],[\"1.4108\",\"435472.9\"]],\"u\":9831498,\"seq\":241267336004},\"cts\":1778927742498}"}
{"ts":1778927742827,"data":"{\"topic\":\"orderbook.1000.XRPUSDT\",\"type\":\"delta\",\"ts\":1778927742703,\"data\":{\"s\":\"XRPUSDT\",\"b\":[[\"1.4044\",\"11428.5\"],[\"1.4042\",\"61268.9\"],[\"1.4033\",\"36602.4\"],[\"1.4004\",\"35809.4\"],[\"1.3974\",\"61666.2\"],[\"1.3958\",\"8793.2\"]],\"a\":[[\"1.4051\",\"54255.0\"],[\"1.4053\",\"79758.7\"],[\"1.4054\",\"66859.3\"],[\"1.4055\",\"70613.0\"],[\"1.4109\",\"34876.6\"],[\"1.4121\",\"100150.0\"]],\"u\":9831499,\"seq\":241267336098},\"cts\":1778927742701}"}
{"ts":1778927743028,"data":"{\"topic\":\"orderbook.1000.XRPUSDT\",\"type\":\"delta\",\"ts\":1778927742903,\"data\":{\"s\":\"XRPUSDT\",\"b\":[[\"1.4044\",\"11439.5\"],[\"1.4043\",\"10054.2\"],[\"1.4042\",\"72496.7\"],[\"1.4041\",\"52233.7\"],[\"1.4035\",\"51844.9\"],[\"1.4029\",\"31514.9\"],[\"1.4019\",\"53235.2\"],[\"1.4018\",\"75880.5\"],[\"1.3988\",\"34825.8\"],[\"1.3987\",\"387676.6\"],[\"1.3548\",\"54919.7\"]],\"a\":[[\"1.4048\",\"101430.5\"],[\"1.4049\",\"91162.0\"],[\"1.4055\",\"70617.5\"],[\"1.4056\",\"58939.4\"]],\"u\":9831500,\"seq\":241267336199},\"cts\":1778927742887}"}
{"ts":1778927743227,"data":"{\"topic\":\"orderbook.1000.XRPUSDT\",\"type\":\"delta\",\"ts\":1778927743103,\"data\":{\"s\":\"XRPUSDT\",\"b\":[[\"1.4043\",\"10036.7\"],[\"1.4042\",\"61268.9\"],[\"1.4033\",\"36602.5\"],[\"1.4025\",\"46570.3\"],[\"1.4024\",\"47388.8\"],[\"1.3988\",\"34829.4\"],[\"1.3987\",\"387673.0\"]],\"a\":[[\"1.4046\",\"37560.0\"],[\"1.4051\",\"54324.7\"]],\"u\":9831501,\"seq\":241267336276},\"cts\":1778927743094}"}
{"ts":1778927743429,"data":"{\"topic\":\"orderbook.1000.XRPUSDT\",\"type\":\"delta\",\"ts\":1778927743304,\"data\":{\"s\":\"XRPUSDT\",\"b\":[[\"1.4044\",\"11434.0\"],[\"1.4042\",\"43244.5\"],[\"1.4041\",\"57959.6\"],[\"1.4035\",\"51849.9\"],[\"1.4029\",\"37334.9\"],[\"1.4028\",\"39860.3\"],[\"1.3686\",\"558.4\"]],\"a\":[[\"1.4045\",\"58412.5\"]],\"u\":9831502,\"seq\":241267336426},\"cts\":1778927743297}"}
{"ts":1778927743627,"data":"{\"topic\":\"orderbook.1000.XRPUSDT\",\"type\":\"delta\",\"ts\":1778927743503,\"data\":{\"s\":\"XRPUSDT\",\"b\":[[\"1.4044\",\"11439.5\"],[\"1.4041\",\"63726.2\"],[\"1.4025\",\"44395.8\"],[\"1.4024\",\"49562.1\"]],\"a\":[[\"1.4046\",\"37488.8\"],[\"1.4051\",\"59032.6\"],[\"1.4061\",\"98633.8\"],[\"1.4062\",\"122237.9\"]],\"u\":9831503,\"seq\":241267336541},\"cts\":1778927743500}"}
{"ts":1778927743828,"data":"{\"topic\":\"orderbook.1000.XRPUSDT\",\"type\":\"delta\",\"ts\":1778927743703,\"data\":{\"s\":\"XRPUSDT\",\"b\":[[\"1.4044\",\"11435.4\"],[\"1.4043\",\"10054.2\"],[\"1.4042\",\"61265.4\"],[\"1.4041\",\"58000.3\"],[\"1.4036\",\"38688.8\"],[\"1.4035\",\"51493.7\"],[\"1.4032\",\"50841.7\"],[\"1.4029\",\"31514.9\"],[\"1.4028\",\"39151.2\"],[\"1.4027\",\"43290.6\"],[\"1.4026\",\"51869.1\"],[\"1.3531\",\"8962.6\"]],\"a\":[[\"1.4045\",\"47671.0\"],[\"1.4053\",\"74073.5\"],[\"1.4054\",\"63299.2\"],[\"1.4055\",\"70613.0\"],[\"1.4056\",\"58943.9\"],[\"1.4069\",\"112972.6\"],[\"1.4070\",\"253095.9\"],[\"1.4072\",\"69981.7\"],[\"1.4075\",\"471130.1\"],[\"1.4077\",\"62701.9\"],[\"1.4078\",\"81526.6\"],[\"1.4079\",\"65291.8\"],[\"1.4259\",\"14341.1\"],[\"1.4576\",\"12.8\"]],\"u\":9831504,\"seq\":241267336832},\"cts\":1778927743700}"}
{"ts":1778927744029,"data":"{\"topic\":\"orderbook.1000.XRPUSDT\",\"type\":\"delta\",\"ts\":1778927743903,\"data\":{\"s\":\"XRPUSDT\",\"b\":[[\"1.4044\",\"8547.4\"],[\"1.4043\",\"10272.3\"],[\"1.4042\",\"55498.8\"],[\"1.4041\",\"63720.7\"],[\"1.4040\",\"66151.2\"],[\"1.4039\",\"42439.9\"],[\"1.4036\",\"38332.6\"],[\"1.4035\",\"51849.9\"],[\"1.4032\",\"46467.9\"],[\"1.4031\",\"40975.1\"],[\"1.4030\",\"41716.6\"],[\"1.4027\",\"43287.0\"],[\"1.4025\",\"44399.4\"]],\"a\":[[\"1.4045\",\"47598.8\"],[\"1.4050\",\"72427.3\"],[\"1.4051\",\"60628.9\"],[\"1.4052\",\"71702.9\"],[\"1.4054\",\"66859.3\"],[\"1.4058\",\"60767.8\"],[\"1.4060\",\"57244.5\"],[\"1.4077\",\"56133.7\"]],\"u\":9831505,\"seq\":241267337240},\"cts\":1778927743901}"}
{"ts":1778927744228,"data":"{\"topic\":\"orderbook.1000.XRPUSDT\",\"type\":\"delta\",\"ts\":1778927744104,\"data\":{\"s\":\"XRPUSDT\",\"b\":[[\"1.4044\",\"9752.9\"],[\"1.4043\",\"13337.6\"],[\"1.4041\",\"57995.5\"]],\"a\":[[\"1.4046\",\"37556.2\"],[\"1.4072\",\"71271.6\"],[\"1.4074\",\"148032.5\"],[\"1.4077\",\"61315.4\"]],\"u\":9831506,\"seq\":241267337382},\"cts\":1778927744102}"}
{"ts":1778927744428,"data":"{\"topic\":\"orderbook.1000.XRPUSDT\",\"type\":\"delta\",\"ts\":1778927744303,\"data\":{\"s\":\"XRPUSDT\",\"b\":[[\"1.4044\",\"16507.2\"],[\"1.4043\",\"13119.5\"],[\"1.4042\",\"74213.3\"],[\"1.4037\",\"38516.8\"],[\"1.4026\",\"51872.7\"],[\"1.4025\",\"46567.3\"],[\"1.4024\",\"47388.8\"],[\"1.4008\",\"59103.9\"],[\"1.4003\",\"54736.8\"],[\"1.4002\",\"190330.4\"],[\"1.3962\",\"39477.8\"],[\"1.3960\",\"11371.4\"]],\"a\":[[\"1.4046\",\"37488.8\"],[\"1.4048\",\"94310.2\"],[\"1.4049\",\"98282.2\"],[\"1.4053\",\"74073.4\"],[\"1.4072\",\"69981.7\"],[\"1.4073\",\"46342.8\"]],\"u\":9831507,\"seq\":241267337555},\"cts\":1778927744291}"}
{"ts":1778927744627,"data":"{\"topic\":\"orderbook.1000.XRPUSDT\",\"type\":\"delta\",\"ts\":1778927744503,\"data\":{\"s\":\"XRPUSDT\",\"b\":[[\"1.4044\",\"16501.7\"],[\"1.4042\",\"61265.6\"],[\"1.4041\",\"52228.9\"],[\"1.4023\",\"69740.5\"],[\"1.4021\",\"46200.0\"],[\"1.4002\",\"190334.0\"]],\"a\":[[\"1.4045\",\"47599.4\"],[\"1.4054\",\"63299.2\"],[\"1.4080\",\"39855.8\"],[\"1.4211\",\"860.1\"]],\"u\":9831508,\"seq\":241267337707},\"cts\":1778927744495}"}
{"ts":1778927744827,"data":"{\"topic\":\"orderbook.1000.XRPUSDT\",\"type\":\"delta\",\"ts\":1778927744703,\"data\":{\"s\":\"XRPUSDT\",\"b\":[[\"1.4042\",\"72492.0\"],[\"1.4040\",\"66154.8\"],[\"1.4033\",\"36602.8\"],[\"1.4027\",\"43290.6\"],[\"1.4026\",\"51869.1\"]],\"a\":[[\"1.4045\",\"47586.3\"],[\"1.4048\",\"101430.5\"],[\"1.4049\",\"91162.0\"],[\"1.4051\",\"60629.2\"],[\"1.4060\",\"57311.9\"]],\"u\":9831509,\"seq\":241267337826},\"cts\":1778927744700}"}
{"ts":1778927745027,"data":"{\"topic\":\"orderbook.1000.XRPUSDT\",\"type\":\"delta\",\"ts\":1778927744903,\"data\":{\"s\":\"XRPUSDT\",\"b\":[[\"1.4044\",\"0\"],[\"1.4043\",\"0\"],[\"1.4042\",\"110.7\"],[\"1.4041\",\"10060.1\"],[\"1.4040\",\"26650.8\"],[\"1.4039\",\"42957.6\"],[\"1.4038\",\"39100.1\"],[\"1.4036\",\"38336.2\"],[\"1.4035\",\"43805.3\"],[\"1.4034\",\"48600.0\"],[\"1.4033\",\"40766.8\"],[\"1.4032\",\"34490.0\"],[\"1.4031\",\"34026.7\"],[\"1.4030\",\"36402.5\"],[\"1.4029\",\"50317.6\"],[\"1.4028\",\"43479.1\"],[\"1.4027\",\"33208.9\"],[\"1.4026\",\"45543.5\"],[\"1.4025\",\"57740.3\"],[\"1.4024\",\"48115.7\"],[\"1.4023\",\"71908.4\"],[\"1.4022\",\"158960.7\"],[\"1.4021\",\"35433.5\"],[\"1.4020\",\"61460.1\"],[\"1.4019\",\"81006.0\"],[\"1.4018\",\"72834.8\"],[\"1.4017\",\"148026.4\"],[\"1.4016\",\"87933.6\"],[\"1.4015\",\"168672.1\"],[\"1.4013\",\"54183.8\"],[\"1.4012\",\"76730.4\"],[\"1.4011\",\"251526.5\"],[\"1.4010\",\"110950.4\"],[\"1.4009\",\"85876.4\"],[\"1.4008\",\"65542.1\"],[\"1.4006\",\"44168.9\"],[\"1.4005\",\"166521.0\"],[\"1.4004\",\"35880.8\"],[\"1.4003\",\"30949.3\"],[\"1.4001\",\"59011.6\"],[\"1.4000\",\"285806.4\"],[\"1.3987\",\"41923.5\"],[\"1.3977\",\"401974.8\"],[\"1.3972\",\"42072.8\"],[\"1.3962\",\"15690.3\"],[\"1.3958\",\"32580.7\"],[\"1.3902\",\"2698.1\"],[\"1.3044\",\"152.5\"],[\"1.3043\",\"57.8\"]],\"a\":[[\"1.4043\",\"10150.5\"],[\"1.4044\",\"69824.0\"],[\"1.4045\",\"56814.7\"],[\"1.4046\",\"38372.7\"],[\"1.4047\",\"93197.2\"],[\"1.4048\",\"98229.7\"],[\"1.4049\",\"89642.0\"],[\"1.4050\",\"83659.1\"],[\"1.4051\",\"86078.9\"],[\"1.4052\",\"73776.7\"],[\"1.4053\",\"72356.3\"],[\"1.4054\",\"66859.3\"],[\"1.4056\",\"59109.3\"],[\"1.4059\",\"58355.8\"],[\"1.4060\",\"68077.8\"],[\"1.4062\",\"119709.5\"],[\"1.4063\",\"92407.3\"],[\"1.4064\",\"55383.6\"],[\"1.4072\",\"76915.4\"],[\"1.4073\",\"38549.7\"],[\"1.4074\",\"137199.6\"],[\"1.4077\",\"56133.7\"],[\"1.5043\",\"0\"],[\"1.5044\",\"0\"]],\"u\":9831510,\"seq\":241267338728},\"cts\":1778927744901}"}
{"ts":1778927745228,"data":"{\"topic\":\"orderbook.1000.XRPUSDT\",\"type\":\"delta\",\"ts\":1778927745104,\"data\":{\"s\":\"XRPUSDT\",\"b\":[[\"1.4042\",\"24688.1\"],[\"1.4041\",\"23786.8\"],[\"1.4040\",\"58458.5\"],[\"1.4039\",\"53475.8\"],[\"1.4038\",\"52325.5\"],[\"1.4037\",\"31159.1\"],[\"1.4036\",\"38339.8\"],[\"1.4035\",\"39631.7\"],[\"1.4034\",\"37866.1\"],[\"1.4033\",\"35270.8\"],[\"1.4032\",\"47835.3\"],[\"1.4031\",\"46803.4\"],[\"1.4030\",\"42910.9\"],[\"1.4029\",\"44396.3\"],[\"1.4028\",\"52666.7\"],[\"1.4027\",\"33663.6\"],[\"1.4026\",\"54895.8\"],[\"1.4025\",\"54781.8\"],[\"1.4024\",\"44444.8\"],[\"1.4023\",\"70012.5\"],[\"1.4022\",\"156449.9\"],[\"1.4021\",\"36921.5\"],[\"1.4020\",\"68403.2\"],[\"1.4019\",\"70241.4\"],[\"1.4018\",\"80061.8\"],[\"1.4017\",\"67935.7\"],[\"1.4016\",\"95053.1\"],[\"1.4015\",\"164433.6\"],[\"1.4013\",\"84471.0\"],[\"1.4012\",\"188112.9\"],[\"1.4011\",\"304551.3\"],[\"1.4010\",\"91695.9\"],[\"1.4009\",\"48132.5\"],[\"1.4005\",\"204248.8\"],[\"1.4004\",\"34567.5\"],[\"1.4002\",\"182371.0\"],[\"1.4001\",\"46897.3\"],[\"1.4000\",\"285520.7\"],[\"1.3998\",\"308936.1\"],[\"1.3996\",\"45997.7\"],[\"1.3982\",\"37729.0\"],[\"1.3977\",\"418125.3\"],[\"1.3972\",\"41360.7\"],[\"1.3968\",\"41107.4\"],[\"1.3967\",\"33376.5\"],[\"1.3962\",\"25818.4\"],[\"1.3961\",\"17271.7\"],[\"1.3902\",\"2014.9\"]],\"a\":[[\"1.4043\",\"15836.1\"],[\"1.4044\",\"28572.8\"],[\"1.4045\",\"79812.9\"],[\"1.4046\",\"65522.4\"],[\"1.4047\",\"79324.4\"],[\"1.4048\",\"88660.7\"],[\"1.4049\",\"88600.9\"],[\"1.4050\",\"72242.1\"],[\"1.4051\",\"68836.9\"],[\"1.4052\",\"77259.1\"],[\"1.4053\",\"67742.2\"],[\"1.4054\",\"73551.5\"],[\"1.4055\",\"67049.4\"],[\"1.4056\",\"60176.2\"],[\"1.4057\",\"50082.3\"],[\"1.4058\",\"61293.5\"],[\"1.4059\",\"60911.5\"],[\"1.4060\",\"84578.3\"],[\"1.4061\",\"47217.0\"],[\"1.4062\",\"62408.8\"],[\"1.4063\",\"151210.5\"],[\"1.4064\",\"60864.2\"],[\"1.4066\",\"53126.1\"],[\"1.4067\",\"78435.0\"],[\"1.4068\",\"88474.1\"],[\"1.4069\",\"111087.6\"],[\"1.4070\",\"341855.8\"],[\"1.4072\",\"68596.1\"],[\"1.4073\",\"57215.1\"],[\"1.4074\",\"144082.1\"],[\"1.4075\",\"383519.3\"],[\"1.4077\",\"48300.6\"],[\"1.4079\",\"66143.1\"],[\"1.4082\",\"34116.8\"],[\"1.4092\",\"62476.0\"],[\"1.4098\",\"37840.0\"],[\"1.4106\",\"31033.1\"],[\"1.4108\",\"435118.4\"],[\"1.4119\",\"40192.6\"],[\"1.4120\",\"579478.2\"],[\"1.4125\",\"10347.7\"],[\"1.4126\",\"18182.9\"],[\"1.4129\",\"405.7\"],[\"1.4221\",\"1628.7\"],[\"1.4376\",\"25911.1\"]],\"u\":9831511,\"seq\":241267340378},\"cts\":1778927745102}"}
{"ts":1778927745427,"data":"{\"topic\":\"orderbook.1000.XRPUSDT\",\"type\":\"delta\",\"ts\":1778927745303,\"data\":{\"s\":\"XRPUSDT\",\"b\":[[\"1.4042\",\"23275.7\"],[\"1.4041\",\"10063.8\"],[\"1.4039\",\"53912.0\"],[\"1.4038\",\"38868.9\"],[\"1.4037\",\"30722.9\"],[\"1.4036\",\"38564.8\"],[\"1.4035\",\"39987.9\"],[\"1.4034\",\"37509.9\"],[\"1.4033\",\"35471.8\"],[\"1.4021\",\"36917.9\"],[\"1.4019\",\"75505.2\"],[\"1.4013\",\"84270.1\"],[\"1.4003\",\"54736.8\"],[\"1.4001\",\"23109.8\"],[\"1.3964\",\"134893.7\"],[\"1.3958\",\"8793.2\"],[\"1.3670\",\"46483.5\"]],\"a\":[[\"1.4044\",\"28640.2\"],[\"1.4045\",\"94039.4\"],[\"1.4051\",\"68837.0\"],[\"1.4054\",\"62219.3\"],[\"1.4057\",\"50014.9\"],[\"1.4058\",\"61154.9\"],[\"1.4059\",\"65030.8\"],[\"1.4060\",\"84079.9\"],[\"1.4063\",\"151052.9\"],[\"1.4064\",\"60793.7\"],[\"1.4071\",\"71204.8\"],[\"1.4078\",\"88578.4\"],[\"1.4079\",\"42355.6\"],[\"1.4106\",\"31040.2\"],[\"1.4112\",\"100886.7\"],[\"1.4113\",\"38297.1\"]],\"u\":9831512,\"seq\":241267340627},\"cts\":1778927745302}"}
{"ts":1778927745628,"data":"{\"topic\":\"orderbook.1000.XRPUSDT\",\"type\":\"delta\",\"ts\":1778927745503,\"data\":{\"s\":\"XRPUSDT\",\"b\":[[\"1.4041\",\"25006.1\"],[\"1.4038\",\"46558.6\"],[\"1.4031\",\"46945.8\"],[\"1.4030\",\"46476.3\"],[\"1.4029\",\"40830.7\"],[\"1.4025\",\"54785.4\"],[\"1.4023\",\"70008.5\"],[\"1.4021\",\"36921.9\"],[\"1.4011\",\"304554.9\"],[\"1.4003\",\"54740.4\"],[\"1.3978\",\"413006.3\"],[\"1.3947\",\"5701.9\"]],\"a\":[[\"1.4043\",\"15530.4\"],[\"1.4044\",\"28572.8\"],[\"1.4045\",\"94024.0\"],[\"1.4046\",\"65451.2\"],[\"1.4049\",\"88377.2\"],[\"1.4051\",\"68743.2\"],[\"1.4052\",\"80818.9\"],[\"1.4053\",\"64182.5\"],[\"1.4054\",\"63150.3\"],[\"1.4056\",\"59998.3\"],[\"1.4057\",\"50086.3\"],[\"1.4058\",\"61222.3\"],[\"1.4059\",\"72017.0\"],[\"1.4060\",\"87186.6\"],[\"1.4061\",\"47075.1\"],[\"1.4062\",\"119182.2\"],[\"1.4063\",\"94067.7\"],[\"1.4377\",\"17748.7\"]],\"u\":9831513,\"seq\":241267340891},\"cts\":1778927745501}"}
{"ts":1778927745827,"data":"{\"topic\":\"orderbook.1000.XRPUSDT\",\"type\":\"delta\",\"ts\":1778927745703,\"data\":{\"s\":\"XRPUSDT\",\"b\":[[\"1.4042\",\"23270.4\"],[\"1.4041\",\"10077.6\"],[\"1.4035\",\"39631.7\"],[\"1.4034\",\"37866.1\"],[\"1.4021\",\"36918.3\"],[\"1.4015\",\"164426.5\"],[\"1.4006\",\"44161.8\"],[\"1.4002\",\"182363.8\"],[\"1.4001\",\"23106.2\"],[\"1.3999\",\"21821.4\"],[\"1.3902\",\"2007.8\"]],\"a\":[[\"1.4043\",\"11257.8\"],[\"1.4044\",\"28640.2\"],[\"1.4045\",\"94028.0\"],[\"1.4054\",\"59594.2\"],[\"1.4056\",\"59993.8\"],[\"1.4057\",\"50018.9\"],[\"1.4058\",\"61154.9\"],[\"1.4061\",\"63534.0\"],[\"1.4098\",\"37836.4\"],[\"1.4099\",\"241135.3\"],[\"1.4102\",\"457422.7\"],[\"1.4103\",\"28814.9\"],[\"1.4112\",\"77099.2\"],[\"1.4113\",\"62084.6\"],[\"1.4125\",\"200.3\"],[\"1.4126\",\"8035.5\"],[\"1.4182\",\"7641.4\"],[\"1.4184\",\"6504.9\"]],\"u\":9831514,\"seq\":241267341098},\"cts\":1778927745697}"}
{"ts":1778927746028,"data":"{\"topic\":\"orderbook.1000.XRPUSDT\",\"type\":\"delta\",\"ts\":1778927745903,\"data\":{\"s\":\"XRPUSDT\",\"b\":[[\"1.4041\",\"10054.2\"],[\"1.4040\",\"58459.1\"],[\"1.4039\",\"53931.5\"],[\"1.4032\",\"47782.2\"],[\"1.4025\",\"54781.8\"],[\"1.4024\",\"44448.4\"],[\"1.4017\",\"67928.6\"],[\"1.3999\",\"21825.0\"]],\"a\":[[\"1.4043\",\"11377.2\"],[\"1.4045\",\"93959.1\"],[\"1.4054\",\"63154.8\"],[\"1.4058\",\"69171.4\"],[\"1.4059\",\"93448.9\"],[\"1.4060\",\"58694.0\"],[\"1.4464\",\"404.0\"]],\"u\":9831515,\"seq\":241267341736},\"cts\":1778927745900}"}
{"ts":1778927746227,"data":"{\"topic\":\"orderbook.1000.XRPUSDT\",\"type\":\"delta\",\"ts\":1778927746103,\"data\":{\"s\":\"XRPUSDT\",\"b\":[[\"1.4042\",\"23352.8\"],[\"1.4041\",\"24965.4\"],[\"1.4040\",\"63459.1\"],[\"1.4039\",\"48931.5\"],[\"1.4035\",\"39987.9\"],[\"1.4034\",\"51520.0\"],[\"1.4033\",\"42436.6\"],[\"1.4031\",\"39815.4\"],[\"1.4030\",\"42910.9\"],[\"1.4029\",\"40995.0\"],[\"1.4013\",\"84273.7\"],[\"1.4010\",\"86266.4\"],[\"1.4008\",\"59103.9\"],[\"1.4002\",\"183594.4\"],[\"1.3999\",\"21821.4\"],[\"1.3972\",\"41353.6\"],[\"1.3821\",\"1325.5\"],[\"1.3817\",\"3433.6\"]],\"a\":[[\"1.4043\",\"3121.0\"],[\"1.4044\",\"7179.2\"],[\"1.4045\",\"30780.3\"],[\"1.4048\",\"81539.0\"],[\"1.4049\",\"88380.8\"],[\"1.4052\",\"77259.1\"],[\"1.4053\",\"64182.2\"],[\"1.4055\",\"59099.8\"],[\"1.4056\",\"53613.6\"],[\"1.4057\",\"57731.7\"],[\"1.4058\",\"61222.3\"],[\"1.4059\",\"72087.7\"],[\"1.4060\",\"87186.6\"],[\"1.4077\",\"59133.9\"],[\"1.4108\",\"435114.8\"],[\"1.4109\",\"34880.2\"],[\"1.4266\",\"43839.3\"],[\"1.4269\",\"17803.0\"]],\"u\":9831516,\"seq\":241267342033},\"cts\":1778927746101}"}
{"ts":1778927746428,"data":"{\"topic\":\"orderbook.1000.XRPUSDT\",\"type\":\"delta\",\"ts\":1778927746304,\"data\":{\"s\":\"XRPUSDT\",\"b\":[[\"1.4039\",\"50804.8\"],[\"1.4036\",\"38921.0\"],[\"1.4035\",\"44660.7\"],[\"1.4031\",\"43380.6\"],[\"1.4025\",\"56337.1\"],[\"1.4024\",\"42879.3\"],[\"1.4021\",\"36925.5\"],[\"1.4010\",\"91529.0\"]],\"a\":[[\"1.4043\",\"2041.8\"],[\"1.4045\",\"24322.4\"],[\"1.4046\",\"59617.3\"],[\"1.4047\",\"70341.1\"],[\"1.4048\",\"89095.9\"],[\"1.4049\",\"87668.8\"],[\"1.4050\",\"80074.5\"],[\"1.4051\",\"69936.6\"],[\"1.4053\",\"62997.8\"],[\"1.4054\",\"63150.3\"],[\"1.4055\",\"65697.7\"],[\"1.4056\",\"53618.1\"],[\"1.4059\",\"64956.3\"],[\"1.4060\",\"66759.5\"],[\"1.4061\",\"92026.6\"],[\"1.4078\",\"64790.9\"],[\"1.4080\",\"63643.3\"],[\"1.4113\",\"38297.1\"],[\"1.4117\",\"51426.1\"]],\"u\":9831517,\"seq\":241267342385},\"cts\":1778927746294}"}
{"ts":1778927746628,"data":"{\"topic\":\"orderbook.1000.XRPUSDT\",\"type\":\"delta\",\"ts\":1778927746504,\"data\":{\"s\":\"XRPUSDT\",\"b\":[[\"1.4042\",\"26306.9\"],[\"1.4036\",\"38564.8\"],[\"1.4035\",\"45016.9\"],[\"1.4034\",\"40686.7\"],[\"1.4033\",\"44003.3\"],[\"1.4025\",\"56340.7\"],[\"1.4024\",\"42875.7\"],[\"1.4022\",\"156453.9\"],[\"1.4021\",\"36925.1\"],[\"1.4008\",\"64585.8\"]],\"a\":[[\"1.4043\",\"10348.4\"],[\"1.4044\",\"7250.4\"],[\"1.4045\",\"65479.2\"],[\"1.4046\",\"67325.0\"],[\"1.4057\",\"57603.1\"],[\"1.4059\",\"65023.7\"],[\"1.4071\",\"71209.3\"],[\"1.4072\",\"68591.6\"],[\"1.4077\",\"53523.1\"],[\"1.4091\",\"260860.1\"],[\"1.4092\",\"62480.5\"]],\"u\":9831518,\"seq\":241267342575},\"cts\":1778927746492}"}
{"ts":1778927746827,"data":"{\"topic\":\"orderbook.1000.XRPUSDT\",\"type\":\"delta\",\"ts\":1778927746703,\"data\":{\"s\":\"XRPUSDT\",\"b\":[[\"1.4042\",\"26301.6\"],[\"1.4016\",\"94953.3\"],[\"1.4008\",\"59103.9\"],[\"1.3989\",\"37784.2\"],[\"1.3988\",\"34825.8\"],[\"1.3976\",\"28065.4\"],[\"1.3974\",\"61662.6\"]],\"a\":[[\"1.4043\",\"2041.8\"],[\"1.4046\",\"60101.3\"],[\"1.4055\",\"65702.2\"],[\"1.4056\",\"53613.6\"],[\"1.4091\",\"260864.6\"],[\"1.4092\",\"62476.0\"]],\"u\":9831519,\"seq\":241267342814},\"cts\":1778927746695}"}
{"ts":1778927747027,"data":"{\"topic\":\"orderbook.1000.XRPUSDT\",\"type\":\"delta\",\"ts\":1778927746903,\"data\":{\"s\":\"XRPUSDT\",\"b\":[[\"1.4041\",\"36165.4\"],[\"1.4040\",\"63462.2\"],[\"1.4029\",\"40995.2\"],[\"1.4015\",\"164419.4\"],[\"1.3989\",\"37780.6\"],[\"1.3988\",\"34829.4\"],[\"1.3976\",\"28061.8\"],[\"1.3975\",\"62839.3\"]],\"a\":[[\"1.4043\",\"2425.9\"],[\"1.4051\",\"69936.8\"]],\"u\":9831520,\"seq\":241267342969},\"cts\":1778927746899}"}
{"ts":1778927747227,"data":"{\"topic\":\"orderbook.1000.XRPUSDT\",\"type\":\"delta\",\"ts\":1778927747103,\"data\":{\"s\":\"XRPUSDT\",\"b\":[[\"1.4042\",\"26306.9\"],[\"1.3989\",\"37784.2\"],[\"1.3988\",\"34825.8\"],[\"1.3976\",\"28065.4\"],[\"1.3975\",\"62835.7\"]],\"a\":[[\"1.4043\",\"2042.8\"],[\"1.4044\",\"7179.2\"],[\"1.4045\",\"55421.4\"]],\"u\":9831521,\"seq\":241267343135},\"cts\":1778927747102}"}
{"ts":1778927747427,"data":"{\"topic\":\"orderbook.1000.XRPUSDT\",\"type\":\"delta\",\"ts\":1778927747303,\"data\":{\"s\":\"XRPUSDT\",\"b\":[[\"1.4025\",\"61403.9\"],[\"1.4024\",\"37818.1\"],[\"1.4016\",\"73155.2\"],[\"1.4015\",\"88498.1\"],[\"1.4014\",\"213150.6\"],[\"1.4013\",\"160697.6\"],[\"1.4012\",\"233065.3\"],[\"1.4011\",\"259653.8\"],[\"1.4008\",\"64879.0\"],[\"1.4002\",\"44331.3\"],[\"1.4000\",\"424805.1\"],[\"1.3989\",\"37780.6\"],[\"1.3988\",\"34829.4\"],[\"1.3980\",\"30307.9\"],[\"1.3978\",\"532985.7\"],[\"1.3976\",\"28061.8\"],[\"1.3970\",\"198543.6\"]],\"a\":[[\"1.4043\",\"9173.7\"],[\"1.4044\",\"7250.4\"],[\"1.4045\",\"55350.2\"],[\"1.4061\",\"75567.7\"],[\"1.4062\",\"62197.0\"],[\"1.4063\",\"151052.9\"],[\"1.4072\",\"93434.5\"],[\"1.4073\",\"131271.1\"],[\"1.4075\",\"327822.1\"],[\"1.4079\",\"66143.1\"],[\"1.4080\",\"39855.8\"],[\"1.4085\",\"176552.3\"],[\"1.4088\",\"76969.6\"],[\"1.4091\",\"260860.1\"],[\"1.4092\",\"62480.5\"],[\"1.4108\",\"513479.8\"],[\"1.4110\",\"43745.4\"],[\"1.4114\",\"59304.5\"],[\"1.4117\",\"27638.6\"],[\"1.4294\",\"32164.9\"],[\"1.4480\",\"4267.3\"]],\"u\":9831522,\"seq\":241267343258},\"cts\":1778927747288}"}
{"ts":1778927747627,"data":"{\"topic\":\"orderbook.1000.XRPUSDT\",\"type\":\"delta\",\"ts\":1778927747503,\"data\":{\"s\":\"XRPUSDT\",\"b\":[[\"1.4011\",\"259657.4\"],[\"1.4010\",\"91525.4\"],[\"1.3989\",\"37784.2\"],[\"1.3988\",\"34825.8\"],[\"1.3976\",\"28065.4\"],[\"1.3970\",\"198540.0\"]],\"a\":[[\"1.4043\",\"9173.6\"],[\"1.4054\",\"59589.7\"],[\"1.4091\",\"260864.6\"],[\"1.4092\",\"62476.0\"],[\"1.4464\",\"2473.7\"]],\"u\":9831523,\"seq\":241267343444},\"cts\":1778927747491}"}
{"ts":1778927747827,"data":"{\"topic\":\"orderbook.1000.XRPUSDT\",\"type\":\"delta\",\"ts\":1778927747703,\"data\":{\"s\":\"XRPUSDT\",\"b\":[[\"1.4041\",\"10036.7\"],[\"1.4040\",\"52699.0\"],[\"1.4039\",\"52201.1\"],[\"1.4038\",\"51994.8\"],[\"1.4035\",\"44660.7\"],[\"1.4034\",\"41042.9\"],[\"1.4033\",\"40742.6\"],[\"1.4032\",\"45323.3\"],[\"1.4031\",\"39815.4\"],[\"1.4030\",\"46863.8\"],[\"1.4027\",\"39484.5\"],[\"1.4026\",\"55610.9\"],[\"1.4025\",\"54785.4\"],[\"1.4024\",\"46930.0\"],[\"1.4012\",\"188112.9\"],[\"1.4011\",\"304598.0\"],[\"1.4008\",\"65614.5\"]],\"a\":[[\"1.4043\",\"10356.4\"],[\"1.4044\",\"33974.8\"],[\"1.4045\",\"79223.9\"],[\"1.4047\",\"78888.0\"],[\"1.4048\",\"84049.0\"],[\"1.4049\",\"88380.8\"],[\"1.4050\",\"82923.2\"],[\"1.4051\",\"70079.3\"],[\"1.4052\",\"78745.0\"],[\"1.4053\",\"59438.2\"],[\"1.4054\",\"63150.3\"],[\"1.4057\",\"57670.5\"],[\"1.4059\",\"64956.3\"],[\"1.4061\",\"92026.6\"],[\"1.4062\",\"119182.2\"],[\"1.4063\",\"94067.7\"],[\"1.4074\",\"148025.6\"],[\"1.4077\",\"48300.6\"],[\"1.4079\",\"42355.6\"],[\"1.4080\",\"63643.3\"],[\"1.4114\",\"35517.0\"],[\"1.4117\",\"51426.1\"],[\"1.4448\",\"493.3\"]],\"u\":9831524,\"seq\":241267343897},\"cts\":1778927747698}"}
{"ts":1778927748027,"data":"{\"topic\":\"orderbook.1000.XRPUSDT\",\"type\":\"delta\",\"ts\":1778927747903,\"data\":{\"s\":\"XRPUSDT\",\"b\":[[\"1.4042\",\"23352.8\"],[\"1.4041\",\"24967.7\"],[\"1.4040\",\"58469.4\"],[\"1.4039\",\"40706.0\"],[\"1.4032\",\"47834.1\"],[\"1.4027\",\"33663.6\"],[\"1.4026\",\"54895.8\"],[\"1.4025\",\"54781.8\"],[\"1.4024\",\"46933.6\"],[\"1.4022\",\"156449.9\"],[\"1.4021\",\"36929.1\"],[\"1.4012\",\"188105.8\"],[\"1.4008\",\"65055.3\"]],\"a\":[[\"1.4043\",\"10022.7\"],[\"1.4045\",\"78664.9\"],[\"1.4049\",\"88381.1\"],[\"1.4054\",\"59589.7\"],[\"1.4059\",\"72017.0\"],[\"1.4060\",\"87186.6\"],[\"1.4061\",\"63534.0\"],[\"1.4074\",\"148029.3\"],[\"1.4077\",\"55817.5\"]],\"u\":9831525,\"seq\":241267344193},\"cts\":1778927747897}"}
{"ts":1778927748228,"data":"{\"topic\":\"orderbook.1000.XRPUSDT\",\"type\":\"delta\",\"ts\":1778927748104,\"data\":{\"s\":\"XRPUSDT\",\"b\":[[\"1.4042\",\"23356.5\"],[\"1.4041\",\"28036.8\"],[\"1.4040\",\"63469.4\"],[\"1.4039\",\"41142.0\"],[\"1.4038\",\"46558.6\"],[\"1.4035\",\"45016.9\"],[\"1.4034\",\"51520.0\"],[\"1.4033\",\"43253.4\"],[\"1.4032\",\"47833.9\"],[\"1.4031\",\"43380.5\"],[\"1.4030\",\"43298.5\"],[\"1.4029\",\"40995.3\"],[\"1.4024\",\"44420.8\"],[\"1.4016\",\"73153.2\"],[\"1.4012\",\"188102.1\"],[\"1.4011\",\"304594.4\"],[\"1.4010\",\"86266.4\"],[\"1.4008\",\"59103.9\"]],\"a\":[[\"1.4043\",\"2042.7\"],[\"1.4044\",\"21534.1\"],[\"1.4045\",\"24251.2\"],[\"1.4046\",\"39905.9\"],[\"1.4047\",\"91894.3\"],[\"1.4048\",\"84048.8\"],[\"1.4051\",\"70079.4\"],[\"1.4052\",\"71625.2\"],[\"1.4053\",\"62997.8\"],[\"1.4054\",\"63154.8\"],[\"1.4055\",\"64314.7\"],[\"1.4056\",\"53613.4\"],[\"1.4064\",\"60791.7\"],[\"1.4072\",\"93432.5\"],[\"1.4077\",\"59133.9\"]],\"u\":9831526,\"seq\":241267344433},\"cts\":1778927748102}"}
{"ts":1778927748428,"data":"{\"topic\":\"orderbook.1000.XRPUSDT\",\"type\":\"delta\",\"ts\":1778927748304,\"data\":{\"s\":\"XRPUSDT\",\"b\":[[\"1.4043\",\"44377.6\"],[\"1.4042\",\"23367.4\"],[\"1.4041\",\"56192.1\"],[\"1.4039\",\"41284.4\"],[\"1.4034\",\"40686.7\"],[\"1.4033\",\"51080.7\"],[\"1.4025\",\"50539.4\"],[\"1.4024\",\"37816.1\"],[\"1.4023\",\"80841.1\"],[\"1.4022\",\"156453.9\"],[\"1.4021\",\"36925.1\"],[\"1.4017\",\"57141.4\"],[\"1.4015\",\"88524.4\"],[\"1.4013\",\"155166.9\"],[\"1.4012\",\"243884.6\"],[\"1.4011\",\"259653.8\"],[\"1.3989\",\"37780.6\"],[\"1.3988\",\"34829.4\"],[\"1.3976\",\"28061.8\"],[\"1.3975\",\"62839.3\"],[\"1.3972\",\"41350.0\"],[\"1.3043\",\"0\"]],\"a\":[[\"1.4043\",\"0\"],[\"1.4044\",\"25622.3\"],[\"1.4045\",\"24322.4\"],[\"1.4046\",\"74536.5\"],[\"1.4047\",\"70341.1\"],[\"1.4048\",\"91169.6\"],[\"1.4049\",\"87669.1\"],[\"1.4050\",\"83635.1\"],[\"1.4051\",\"70083.0\"],[\"1.4054\",\"59589.7\"],[\"1.4055\",\"69937.6\"],[\"1.4058\",\"50435.5\"],[\"1.4059\",\"64956.3\"],[\"1.4060\",\"58694.0\"],[\"1.4061\",\"92026.6\"],[\"1.4062\",\"130014.8\"],[\"1.4072\",\"99038.3\"],[\"1.4074\",\"137199.6\"],[\"1.4076\",\"85354.5\"],[\"1.4077\",\"48300.6\"],[\"1.4125\",\"20469.1\"],[\"1.5043\",\"411.3\"]],\"u\":9831527,\"seq\":241267344591},\"cts\":1778927748300}"}
{"ts":1778927748627,"data":"{\"topic\":\"orderbook.1000.XRPUSDT\",\"type\":\"delta\",\"ts\":1778927748503,\"data\":{\"s\":\"XRPUSDT\",\"b\":[[\"1.4042\",\"23296.1\"],[\"1.4041\",\"62253.4\"],[\"1.4040\",\"45914.9\"],[\"1.4039\",\"41142.0\"],[\"1.4035\",\"45013.2\"],[\"1.4029\",\"40995.2\"],[\"1.4028\",\"46847.2\"],[\"1.4027\",\"32954.5\"],[\"1.4026\",\"54899.4\"],[\"1.4025\",\"50535.8\"],[\"1.4018\",\"86161.6\"],[\"1.4017\",\"50874.0\"],[\"1.4011\",\"259657.4\"],[\"1.4010\",\"86262.8\"],[\"1.4004\",\"58355.0\"],[\"1.4003\",\"30952.9\"],[\"1.3989\",\"37784.2\"],[\"1.3988\",\"34825.8\"],[\"1.3976\",\"28065.4\"],[\"1.3975\",\"62835.7\"],[\"1.3967\",\"33369.3\"],[\"1.3965\",\"51313.7\"],[\"1.3964\",\"111106.2\"]],\"a\":[[\"1.4044\",\"24123.3\"],[\"1.4045\",\"24315.5\"],[\"1.4046\",\"74543.4\"],[\"1.4049\",\"81260.9\"],[\"1.4050\",\"90042.9\"],[\"1.4051\",\"70082.9\"],[\"1.4054\",\"63150.1\"],[\"1.4057\",\"57666.5\"],[\"1.4058\",\"50439.5\"],[\"1.4060\",\"58764.9\"],[\"1.4061\",\"75565.6\"],[\"1.4062\",\"73029.6\"],[\"1.4063\",\"151048.8\"],[\"1.4070\",\"336213.0\"],[\"1.4079\",\"66143.1\"],[\"1.4080\",\"39855.8\"],[\"1.4114\",\"59304.5\"],[\"1.4117\",\"27638.6\"],[\"1.4119\",\"40199.8\"],[\"1.4125\",\"26999.1\"],[\"1.4872\",\"57.0\"]],\"u\":9831528,\"seq\":241267344721},\"cts\":1778927748492}"}
{"ts":1778927748827,"data":"{\"topic\":\"orderbook.1000.XRPUSDT\",\"type\":\"delta\",\"ts\":1778927748703,\"data\":{\"s\":\"XRPUSDT\",\"b\":[[\"1.4041\",\"59203.5\"],[\"1.4033\",\"49656.5\"],[\"1.3989\",\"37780.6\"],[\"1.3988\",\"34829.4\"],[\"1.3976\",\"28061.8\"],[\"1.3975\",\"62839.3\"]],\"a\":[],\"u\":9831529,\"seq\":241267344808},\"cts\":1778927748692}"}
{"ts":1778927749027,"data":"{\"topic\":\"orderbook.1000.XRPUSDT\",\"type\":\"delta\",\"ts\":1778927748903,\"data\":{\"s\":\"XRPUSDT\",\"b\":[[\"1.4040\",\"45921.9\"],[\"1.4034\",\"40911.0\"],[\"1.4033\",\"49628.0\"],[\"1.4029\",\"40995.5\"]],\"a\":[[\"1.4044\",\"24158.2\"],[\"1.4045\",\"24288.2\"],[\"1.4051\",\"70083.2\"]],\"u\":9831530,\"seq\":241267345000},\"cts\":1778927748896}"}
{"ts":1778927749228,"data":"{\"topic\":\"orderbook.1000.XRPUSDT\",\"type\":\"delta\",\"ts\":1778927749104,\"data\":{\"s\":\"XRPUSDT\",\"b\":[[\"1.4043\",\"44383.4\"],[\"1.4042\",\"39832.9\"],[\"1.4039\",\"43260.2\"],[\"1.4036\",\"38921.0\"],[\"1.4035\",\"44657.0\"],[\"1.4034\",\"38821.3\"],[\"1.4032\",\"51398.9\"],[\"1.4031\",\"39815.4\"],[\"1.4026\",\"61478.4\"],[\"1.4025\",\"43948.1\"],[\"1.4013\",\"200150.4\"],[\"1.4012\",\"198934.7\"],[\"1.3961\",\"7143.6\"]],\"a\":[[\"1.4044\",\"22573.8\"],[\"1.4045\",\"15365.6\"],[\"1.4046\",\"60487.0\"],[\"1.4048\",\"84048.8\"],[\"1.4049\",\"88381.2\"],[\"1.4050\",\"89331.0\"],[\"1.4051\",\"70630.3\"],[\"1.4055\",\"64479.5\"],[\"1.4056\",\"58635.1\"],[\"1.4061\",\"47075.1\"],[\"1.4062\",\"101520.1\"],[\"1.4078\",\"71065.9\"],[\"1.4106\",\"31033.1\"]],\"u\":9831531,\"seq\":241267345299},\"cts\":1778927749099}"}
{"ts":1778927749427,"data":"{\"topic\":\"orderbook.1000.XRPUSDT\",\"type\":\"delta\",\"ts\":1778927749303,\"data\":{\"s\":\"XRPUSDT\",\"b\":[],\"a\":[[\"1.4044\",\"28532.4\"],[\"1.4054\",\"68478.9\"],[\"1.4078\",\"64790.9\"],[\"1.4106\",\"31040.2\"],[\"1.4113\",\"62084.6\"],[\"1.4114\",\"35517.0\"],[\"1.4448\",\"589.3\"]],\"u\":9831532,\"seq\":241267345383},\"cts\":1778927749302}"}
{"ts":1778927749627,"data":"{\"topic\":\"orderbook.1000.XRPUSDT\",\"type\":\"delta\",\"ts\":1778927749503,\"data\":{\"s\":\"XRPUSDT\",\"b\":[[\"1.4043\",\"44406.7\"],[\"1.4040\",\"45925.5\"],[\"1.4038\",\"46555.0\"],[\"1.4036\",\"38564.8\"],[\"1.4035\",\"45013.2\"],[\"1.4033\",\"41800.7\"],[\"1.4021\",\"36917.9\"],[\"1.4014\",\"213147.0\"],[\"1.4002\",\"44327.7\"],[\"1.3999\",\"21825.0\"]],\"a\":[[\"1.4044\",\"28531.4\"],[\"1.4048\",\"91169.2\"],[\"1.4049\",\"81260.9\"],[\"1.4061\",\"75565.6\"],[\"1.4062\",\"73029.6\"],[\"1.4069\",\"110135.1\"],[\"1.4077\",\"49253.3\"],[\"1.4078\",\"325708.3\"],[\"1.4089\",\"27231.6\"],[\"1.4090\",\"208552.5\"],[\"1.4091\",\"260868.2\"]],\"u\":9831533,\"seq\":241267345528},\"cts\":1778927749498}"}
{"ts":1778927749827,"data":"{\"topic\":\"orderbook.1000.XRPUSDT\",\"type\":\"delta\",\"ts\":1778927749703,\"data\":{\"s\":\"XRPUSDT\",\"b\":[[\"1.4043\",\"33652.5\"],[\"1.4042\",\"26617.8\"],[\"1.4032\",\"37000.6\"],[\"1.4031\",\"54213.0\"],[\"1.4026\",\"56411.6\"],[\"1.4025\",\"49013.7\"],[\"1.4013\",\"155166.9\"],[\"1.4012\",\"243909.4\"],[\"1.4009\",\"53560.1\"]],\"a\":[[\"1.4044\",\"30781.4\"],[\"1.4045\",\"22038.2\"],[\"1.4046\",\"74869.1\"],[\"1.4050\",\"90042.9\"],[\"1.4051\",\"69918.4\"],[\"1.4054\",\"70210.8\"],[\"1.4055\",\"64484.0\"],[\"1.4056\",\"58630.6\"],[\"1.4078\",\"349495.8\"],[\"1.4079\",\"42355.6\"],[\"1.4112\",\"100886.7\"],[\"1.4113\",\"38297.1\"]],\"u\":9831534,\"seq\":241267345662},\"cts\":1778927749691}"}
{"ts":1778927750027,"data":"{\"topic\":\"orderbook.1000.XRPUSDT\",\"type\":\"delta\",\"ts\":1778927749903,\"data\":{\"s\":\"XRPUSDT\",\"b\":[[\"1.4043\",\"33513.0\"],[\"1.4040\",\"45925.1\"],[\"1.4029\",\"40995.6\"],[\"1.4026\",\"54895.8\"],[\"1.4025\",\"50528.1\"],[\"1.4021\",\"36921.5\"],[\"1.3455\",\"692.9\"]],\"a\":[[\"1.4044\",\"37454.0\"],[\"1.4045\",\"21967.0\"],[\"1.4046\",\"33638.2\"],[\"1.4047\",\"70707.2\"],[\"1.4049\",\"87668.7\"],[\"1.4050\",\"83635.1\"],[\"1.4052\",\"75184.9\"],[\"1.4053\",\"59438.2\"],[\"1.4054\",\"73771.2\"],[\"1.4055\",\"64479.6\"],[\"1.4056\",\"58635.1\"],[\"1.4062\",\"130010.7\"],[\"1.4063\",\"94067.7\"],[\"1.4069\",\"111488.6\"],[\"1.4070\",\"335063.9\"],[\"1.4076\",\"79872.4\"]],\"u\":9831535,\"seq\":241267345806},\"cts\":1778927749901}"}
{"ts":1778927750228,"data":"{\"topic\":\"orderbook.1000.XRPUSDT\",\"type\":\"delta\",\"ts\":1778927750103,\"data\":{\"s\":\"XRPUSDT\",\"b\":[[\"1.4043\",\"35774.1\"],[\"1.4042\",\"39832.9\"],[\"1.4041\",\"59040.3\"],[\"1.4040\",\"44153.3\"],[\"1.4036\",\"38921.0\"],[\"1.4035\",\"48240.4\"],[\"1.4034\",\"37772.0\"],[\"1.4033\",\"52633.3\"],[\"1.4032\",\"40565.6\"],[\"1.4031\",\"50505.6\"],[\"1.4030\",\"46858.9\"],[\"1.4029\",\"40995.7\"],[\"1.4026\",\"56396.0\"],[\"1.4025\",\"46502.9\"],[\"1.4023\",\"80845.1\"],[\"1.4022\",\"156449.9\"],[\"1.4021\",\"36925.1\"],[\"1.4012\",\"239794.1\"],[\"1.4010\",\"80857.8\"],[\"1.4009\",\"48132.5\"],[\"1.4004\",\"34567.5\"],[\"1.3965\",\"27526.2\"]],\"a\":[[\"1.4044\",\"1163.2\"],[\"1.4045\",\"8408.0\"],[\"1.4046\",\"55354.3\"],[\"1.4047\",\"69625.6\"],[\"1.4048\",\"72634.6\"],[\"1.4049\",\"95073.5\"],[\"1.4050\",\"81157.4\"],[\"1.4051\",\"74730.5\"],[\"1.4052\",\"66638.5\"],[\"1.4054\",\"68293.8\"],[\"1.4055\",\"60697.2\"],[\"1.4056\",\"59915.5\"],[\"1.4057\",\"50021.1\"],[\"1.4058\",\"61276.6\"],[\"1.4060\",\"58694.0\"],[\"1.4061\",\"47075.1\"],[\"1.4062\",\"101520.1\"],[\"1.4063\",\"151048.8\"],[\"1.4069\",\"111938.6\"],[\"1.4071\",\"71204.8\"],[\"1.4073\",\"131275.6\"],[\"1.4076\",\"85358.2\"],[\"1.4077\",\"57553.7\"],[\"1.4078\",\"325708.3\"],[\"1.4112\",\"77099.2\"]],\"u\":9831536,\"seq\":241267346092},\"cts\":1778927750102}"}
{"ts":1778927750427,"data":"{\"topic\":\"orderbook.1000.XRPUSDT\",\"type\":\"delta\",\"ts\":1778927750303,\"data\":{\"s\":\"XRPUSDT\",\"b\":[[\"1.4042\",\"36505.4\"],[\"1.4035\",\"39797.3\"],[\"1.4026\",\"61463.1\"],[\"1.4025\",\"41437.3\"],[\"1.4021\",\"36928.7\"],[\"1.4013\",\"200154.4\"],[\"1.4012\",\"194819.4\"],[\"1.4004\",\"58355.0\"],[\"1.3965\",\"51313.7\"]],\"a\":[[\"1.4044\",\"8663.2\"],[\"1.4046\",\"61883.8\"],[\"1.4049\",\"88665.7\"],[\"1.4050\",\"87565.0\"],[\"1.4053\",\"62997.6\"],[\"1.4054\",\"64734.4\"],[\"1.4056\",\"59920.0\"],[\"1.4058\",\"61272.1\"],[\"1.4059\",\"65121.3\"],[\"1.4082\",\"57904.3\"],[\"1.4119\",\"63987.3\"],[\"1.4127\",\"17295.4\"],[\"1.4873\",\"8068.7\"]],\"u\":9831537,\"seq\":241267346181},\"cts\":1778927750301}"}
{"ts":1778927750627,"data":"{\"topic\":\"orderbook.1000.XRPUSDT\",\"type\":\"delta\",\"ts\":1778927750503,\"data\":{\"s\":\"XRPUSDT\",\"b\":[[\"1.4043\",\"33518.3\"],[\"1.4021\",\"36917.9\"],[\"1.4009\",\"53452.2\"],[\"1.3999\",\"21821.4\"],[\"1.3985\",\"39030.6\"],[\"1.3984\",\"667253.8\"]],\"a\":[[\"1.4061\",\"58261.9\"],[\"1.4072\",\"99042.8\"],[\"1.4073\",\"131271.1\"],[\"1.4077\",\"55807.4\"],[\"1.4091\",\"260863.7\"],[\"1.4092\",\"62480.5\"]],\"u\":9831538,\"seq\":241267346319},\"cts\":1778927750487}"}
{"ts":1778927750828,"data":"{\"topic\":\"orderbook.1000.XRPUSDT\",\"type\":\"delta\",\"ts\":1778927750704,\"data\":{\"s\":\"XRPUSDT\",\"b\":[[\"1.4043\",\"33516.7\"],[\"1.4042\",\"23290.3\"],[\"1.4040\",\"44589.3\"],[\"1.4039\",\"42824.2\"],[\"1.4036\",\"38564.8\"],[\"1.4035\",\"40153.5\"],[\"1.4033\",\"47875.0\"],[\"1.4029\",\"40830.7\"],[\"1.4025\",\"41602.3\"],[\"1.4021\",\"36921.5\"]],\"a\":[[\"1.4044\",\"9047.3\"],[\"1.4045\",\"22038.2\"],[\"1.4054\",\"70931.2\"],[\"1.4059\",\"64956.3\"],[\"1.4071\",\"71209.3\"],[\"1.4072\",\"99038.3\"],[\"1.4077\",\"49253.3\"],[\"1.4079\",\"42355.3\"],[\"1.4080\",\"63643.3\"],[\"1.4082\",\"34116.8\"],[\"1.4091\",\"260868.2\"],[\"1.4092\",\"62476.0\"],[\"1.4116\",\"50744.1\"],[\"1.4119\",\"40199.8\"]],\"u\":9831539,\"seq\":241267346428},\"cts\":1778927750690}"}
{"ts":1778927751028,"data":"{\"topic\":\"orderbook.1000.XRPUSDT\",\"type\":\"delta\",\"ts\":1778927750903,\"data\":{\"s\":\"XRPUSDT\",\"b\":[[\"1.4043\",\"36392.3\"],[\"1.4042\",\"37997.9\"],[\"1.4040\",\"44589.4\"],[\"1.4036\",\"38921.0\"],[\"1.4035\",\"39797.3\"],[\"1.4026\",\"61459.5\"],[\"1.4025\",\"41605.9\"],[\"1.4009\",\"48132.5\"],[\"1.3980\",\"30311.5\"]],\"a\":[[\"1.4044\",\"9325.8\"],[\"1.4049\",\"88665.8\"],[\"1.4054\",\"64734.4\"],[\"1.4055\",\"60862.2\"],[\"1.4069\",\"111488.6\"],[\"1.4077\",\"55435.8\"],[\"1.4080\",\"39855.8\"],[\"1.4082\",\"57904.3\"],[\"1.4116\",\"26956.6\"],[\"1.4119\",\"63987.3\"]],\"u\":9831540,\"seq\":241267346532},\"cts\":1778927750893}"}
{"ts":1778927751228,"data":"{\"topic\":\"orderbook.1000.XRPUSDT\",\"type\":\"delta\",\"ts\":1778927751104,\"data\":{\"s\":\"XRPUSDT\",\"b\":[[\"1.4042\",\"49197.9\"],[\"1.4026\",\"56396.0\"],[\"1.4025\",\"46667.9\"],[\"1.4021\",\"36917.9\"],[\"1.4013\",\"155166.9\"],[\"1.4012\",\"239791.5\"],[\"1.4009\",\"54470.6\"],[\"1.3975\",\"62835.7\"],[\"1.3970\",\"198536.4\"],[\"1.3961\",\"7147.2\"],[\"1.3818\",\"1114.9\"],[\"1.3817\",\"3226.0\"]],\"a\":[[\"1.4044\",\"9336.3\"],[\"1.4048\",\"79755.0\"],[\"1.4049\",\"87953.3\"],[\"1.4050\",\"81157.4\"],[\"1.4111\",\"218250.7\"],[\"1.4266\",\"43631.7\"],[\"1.4267\",\"26261.8\"],[\"1.4377\",\"17746.3\"]],\"u\":9831541,\"seq\":241267346715},\"cts\":1778927751099}"}
{"ts":1778927751427,"data":"{\"topic\":\"orderbook.1000.XRPUSDT\",\"type\":\"delta\",\"ts\":1778927751303,\"data\":{\"s\":\"XRPUSDT\",\"b\":[[\"1.4021\",\"36921.5\"],[\"1.4009\",\"48132.5\"],[\"1.3976\",\"28065.4\"],[\"1.3975\",\"62832.1\"],[\"1.3865\",\"8616.2\"],[\"1.3850\",\"130063.8\"]],\"a\":[[\"1.4044\",\"8305.2\"],[\"1.4050\",\"81313.2\"],[\"1.4127\",\"13720.8\"],[\"1.4216\",\"96.1\"],[\"1.4234\",\"775.8\"],[\"1.4236\",\"1409.4\"],[\"1.4376\",\"25913.5\"]],\"u\":9831542,\"seq\":241267346863},\"cts\":1778927751299}"}
{"ts":1778927751627,"data":"{\"topic\":\"orderbook.1000.XRPUSDT\",\"type\":\"delta\",\"ts\":1778927751503,\"data\":{\"s\":\"XRPUSDT\",\"b\":[[\"1.4032\",\"40708.0\"],[\"1.4026\",\"61462.8\"],[\"1.4025\",\"41602.3\"],[\"1.4021\",\"36925.1\"],[\"1.4016\",\"73168.8\"],[\"1.4015\",\"88531.5\"],[\"1.4013\",\"200150.4\"],[\"1.4012\",\"194819.4\"],[\"1.3964\",\"110032.1\"],[\"1.3875\",\"265726.5\"],[\"1.3848\",\"2059.3\"]],\"a\":[[\"1.4049\",\"80411.4\"],[\"1.4050\",\"87720.9\"],[\"1.4052\",\"67772.5\"],[\"1.4055\",\"60697.2\"],[\"1.4063\",\"151213.8\"],[\"1.4071\",\"71640.7\"],[\"1.4127\",\"4223.2\"],[\"1.4224\",\"7693.0\"],[\"1.4239\",\"1289.8\"]],\"u\":9831543,\"seq\":241267346937},\"cts\":1778927751494}"}
{"ts":1778927751828,"data":"{\"topic\":\"orderbook.1000.XRPUSDT\",\"type\":\"delta\",\"ts\":1778927751704,\"data\":{\"s\":\"XRPUSDT\",\"b\":[[\"1.4043\",\"36414.9\"],[\"1.4027\",\"32994.5\"],[\"1.3976\",\"28061.8\"],[\"1.3975\",\"62835.7\"]],\"a\":[[\"1.4044\",\"9039.0\"],[\"1.4046\",\"45285.8\"],[\"1.4048\",\"72634.6\"],[\"1.4049\",\"87531.8\"],[\"1.4052\",\"66638.5\"],[\"1.4059\",\"64887.6\"],[\"1.4071\",\"71636.2\"],[\"1.4072\",\"99042.8\"],[\"1.4080\",\"63643.3\"],[\"1.4082\",\"34116.8\"],[\"1.4091\",\"260863.7\"],[\"1.4092\",\"62480.5\"],[\"1.4116\",\"50744.1\"],[\"1.4119\",\"40199.8\"]],\"u\":9831544,\"seq\":241267347044},\"cts\":1778927751699}"}
{"ts":1778927752027,"data":"{\"topic\":\"orderbook.1000.XRPUSDT\",\"type\":\"delta\",\"ts\":1778927751903,\"data\":{\"s\":\"XRPUSDT\",\"b\":[[\"1.4043\",\"47609.1\"],[\"1.4041\",\"59058.7\"],[\"1.4039\",\"42804.7\"],[\"1.4023\",\"80834.2\"],[\"1.4009\",\"54224.6\"],[\"1.3989\",\"37784.2\"],[\"1.3988\",\"34825.8\"],[\"1.3976\",\"28065.4\"],[\"1.3975\",\"62832.1\"]],\"a\":[[\"1.4044\",\"8779.2\"],[\"1.4046\",\"61886.8\"],[\"1.4055\",\"60862.2\"],[\"1.4058\",\"61243.6\"],[\"1.4063\",\"151048.8\"],[\"1.4069\",\"111477.7\"],[\"1.4071\",\"71204.8\"],[\"1.4091\",\"260868.2\"],[\"1.4092\",\"62476.0\"],[\"1.4327\",\"2499.8\"],[\"1.4511\",\"350.3\"]],\"u\":9831545,\"seq\":241267347235},\"cts\":1778927751892}"}
{"ts":1778927752227,"data":"{\"topic\":\"orderbook.1000.XRPUSDT\",\"type\":\"delta\",\"ts\":1778927752103,\"data\":{\"s\":\"XRPUSDT\",\"b\":[[\"1.4043\",\"47614.9\"],[\"1.4040\",\"44353.8\"],[\"1.4035\",\"50620.2\"],[\"1.4009\",\"48132.5\"]],\"a\":[[\"1.4044\",\"1125.2\"],[\"1.4048\",\"79755.0\"],[\"1.4049\",\"80411.4\"],[\"1.4054\",\"61174.0\"],[\"1.4056\",\"53018.2\"],[\"1.4057\",\"50049.6\"],[\"1.4071\",\"71209.3\"],[\"1.4072\",\"99038.3\"],[\"1.4080\",\"39855.8\"],[\"1.4082\",\"57904.3\"],[\"1.4116\",\"26956.6\"],[\"1.4119\",\"63987.3\"],[\"1.4127\",\"14629.0\"]],\"u\":9831546,\"seq\":241267347388},\"cts\":1778927752101}"}
{"ts":1778927752427,"data":"{\"topic\":\"orderbook.1000.XRPUSDT\",\"type\":\"delta\",\"ts\":1778927752303,\"data\":{\"s\":\"XRPUSDT\",\"b\":[[\"1.4040\",\"44589.5\"],[\"1.4035\",\"39797.3\"],[\"1.4027\",\"32998.1\"],[\"1.4026\",\"61459.2\"],[\"1.4021\",\"36936.0\"],[\"1.3851\",\"21289.8\"]],\"a\":[[\"1.4044\",\"1151.4\"],[\"1.4048\",\"72634.6\"],[\"1.4049\",\"87531.7\"],[\"1.4054\",\"64734.4\"],[\"1.4055\",\"60697.2\"],[\"1.4056\",\"63841.1\"],[\"1.4063\",\"151213.8\"],[\"1.4067\",\"78445.9\"],[\"1.4071\",\"71204.8\"],[\"1.4072\",\"99042.8\"],[\"1.4091\",\"260863.7\"],[\"1.4092\",\"62480.5\"],[\"1.4127\",\"13018.9\"],[\"1.4223\",\"18401.4\"]],\"u\":9831547,\"seq\":241267347504},\"cts\":1778927752298}"}
{"ts":1778927752627,"data":"{\"topic\":\"orderbook.1000.XRPUSDT\",\"type\":\"delta\",\"ts\":1778927752503,\"data\":{\"s\":\"XRPUSDT\",\"b\":[[\"1.4043\",\"47745.4\"],[\"1.4027\",\"32994.5\"],[\"1.4026\",\"61462.8\"],[\"1.3892\",\"1781.2\"]],\"a\":[[\"1.4044\",\"1144.7\"],[\"1.4055\",\"60862.2\"],[\"1.4063\",\"151048.8\"],[\"1.4071\",\"71209.3\"],[\"1.4072\",\"99038.3\"],[\"1.4222\",\"8658.3\"]],\"u\":9831548,\"seq\":241267347604},\"cts\":1778927752501}"}
{"ts":1778927752827,"data":"{\"topic\":\"orderbook.1000.XRPUSDT\",\"type\":\"delta\",\"ts\":1778927752703,\"data\":{\"s\":\"XRPUSDT\",\"b\":[[\"1.4043\",\"47739.6\"],[\"1.4011\",\"259608.9\"],[\"1.4010\",\"80906.5\"],[\"1.4009\",\"53810.0\"],[\"1.3805\",\"1989.8\"]],\"a\":[[\"1.4044\",\"9248.8\"],[\"1.4054\",\"71025.9\"],[\"1.4091\",\"260868.2\"],[\"1.4092\",\"62476.0\"],[\"1.4127\",\"4223.2\"]],\"u\":9831549,\"seq\":241267347674},\"cts\":1778927752687}"}
{"ts":1778927753027,"data":"{\"topic\":\"orderbook.1000.XRPUSDT\",\"type\":\"delta\",\"ts\":1778927752903,\"data\":{\"s\":\"XRPUSDT\",\"b\":[[\"1.4043\",\"47745.4\"],[\"1.4041\",\"59040.3\"],[\"1.4040\",\"44583.8\"],[\"1.4039\",\"42828.5\"],[\"1.4015\",\"88524.4\"],[\"1.4009\",\"48132.5\"],[\"1.3968\",\"40015.4\"]],\"a\":[[\"1.4044\",\"8666.0\"],[\"1.4054\",\"64734.4\"],[\"1.4127\",\"14060.8\"]],\"u\":9831550,\"seq\":241267347855},\"cts\":1778927752890}"}
{"ts":1778927753228,"data":"{\"topic\":\"orderbook.1000.XRPUSDT\",\"type\":\"delta\",\"ts\":1778927753104,\"data\":{\"s\":\"XRPUSDT\",\"b\":[[\"1.4040\",\"42924.0\"],[\"1.4032\",\"40640.6\"],[\"1.3989\",\"37780.6\"],[\"1.3988\",\"34829.4\"]],\"a\":[[\"1.4106\",\"31033.1\"],[\"1.4127\",\"4223.2\"]],\"u\":9831551,\"seq\":241267347946},\"cts\":1778927753096}"}
{"ts":1778927753428,"data":"{\"topic\":\"orderbook.1000.XRPUSDT\",\"type\":\"delta\",\"ts\":1778927753303,\"data\":{\"s\":\"XRPUSDT\",\"b\":[[\"1.4043\",\"47795.8\"],[\"1.4040\",\"44583.9\"],[\"1.4013\",\"202241.4\"],[\"1.3989\",\"37784.2\"],[\"1.3988\",\"34825.8\"],[\"1.3883\",\"2542.5\"],[\"1.3855\",\"7809.2\"],[\"1.3829\",\"7806.1\"],[\"1.3810\",\"27896.5\"],[\"1.3803\",\"8293.7\"],[\"1.3798\",\"7213.4\"]],\"a\":[[\"1.4044\",\"8639.8\"],[\"1.4071\",\"71656.4\"],[\"1.4081\",\"74436.6\"],[\"1.4082\",\"34116.8\"],[\"1.4106\",\"31040.2\"],[\"1.4117\",\"51426.1\"],[\"1.4119\",\"40199.8\"],[\"1.4125\",\"56720.1\"],[\"1.4127\",\"18827.3\"],[\"1.4234\",\"1056.8\"],[\"1.4239\",\"1553.1\"],[\"1.4248\",\"39228.0\"],[\"1.4249\",\"276.9\"],[\"1.4273\",\"28464.1\"],[\"1.4274\",\"686.8\"],[\"1.4328\",\"519.3\"]],\"u\":9831552,\"seq\":241267348028},\"cts\":1778927753296}"}
{"ts":1778927753627,"data":"{\"topic\":\"orderbook.1000.XRPUSDT\",\"type\":\"delta\",\"ts\":1778927753503,\"data\":{\"s\":\"XRPUSDT\",\"b\":[[\"1.4043\",\"47832.3\"]],\"a\":[[\"1.4044\",\"7618.2\"],[\"1.4045\",\"22940.8\"],[\"1.4054\",\"61174.0\"],[\"1.4071\",\"71209.3\"]],\"u\":9831553,\"seq\":241267348103},\"cts\":1778927753500}"}
{"ts":1778927753828,"data":"{\"topic\":\"orderbook.1000.XRPUSDT\",\"type\":\"delta\",\"ts\":1778927753703,\"data\":{\"s\":\"XRPUSDT\",\"b\":[[\"1.4043\",\"47905.9\"],[\"1.4013\",\"202208.3\"]],\"a\":[[\"1.4125\",\"26999.1\"],[\"1.4127\",\"4223.2\"]],\"u\":9831554,\"seq\":241267348189},\"cts\":1778927753702}"}
{"ts":1778927754027,"data":"{\"topic\":\"orderbook.1000.XRPUSDT\",\"type\":\"delta\",\"ts\":1778927753903,\"data\":{\"s\":\"XRPUSDT\",\"b\":[[\"1.4040\",\"44584.3\"],[\"1.3947\",\"5706.1\"]],\"a\":[[\"1.4044\",\"7614.1\"],[\"1.4054\",\"64734.4\"]],\"u\":9831555,\"seq\":241267348372},\"cts\":1778927753889}"}
{"ts":1778927754228,"data":"{\"topic\":\"orderbook.1000.XRPUSDT\",\"type\":\"delta\",\"ts\":1778927754104,\"data\":{\"s\":\"XRPUSDT\",\"b\":[[\"1.4002\",\"43057.6\"],[\"1.4001\",\"24408.2\"]],\"a\":[[\"1.4377\",\"17743.6\"]],\"u\":9831556,\"seq\":241267348570},\"cts\":1778927754092}"}
{"ts":1778927754428,"data":"{\"topic\":\"orderbook.1000.XRPUSDT\",\"type\":\"delta\",\"ts\":1778927754304,\"data\":{\"s\":\"XRPUSDT\",\"b\":[[\"1.4043\",\"47923.4\"],[\"1.4018\",\"86160.6\"],[\"1.3869\",\"1835.7\"],[\"1.3865\",\"8265.6\"],[\"1.3850\",\"129662.7\"]],\"a\":[[\"1.4059\",\"73833.2\"],[\"1.4068\",\"79527.1\"],[\"1.4125\",\"56807.7\"],[\"1.4127\",\"18751.3\"],[\"1.4220\",\"12561.7\"],[\"1.4234\",\"715.3\"],[\"1.4236\",\"1019.2\"],[\"1.4376\",\"25916.2\"]],\"u\":9831557,\"seq\":241267348685},\"cts\":1778927754298}"}
{"ts":1778927754630,"data":"{\"topic\":\"orderbook.1000.XRPUSDT\",\"type\":\"delta\",\"ts\":1778927754504,\"data\":{\"s\":\"XRPUSDT\",\"b\":[[\"1.4021\",\"36939.6\"],[\"1.3884\",\"1475.2\"],[\"1.3867\",\"1011.4\"],[\"1.3848\",\"1658.2\"]],\"a\":[[\"1.4125\",\"26999.1\"],[\"1.4127\",\"4223.2\"],[\"1.4208\",\"603.0\"],[\"1.4218\",\"7564.2\"],[\"1.4224\",\"7302.5\"]],\"u\":9831558,\"seq\":241267348796},\"cts\":1778927754498}"}
{"ts":1778927754827,"data":"{\"topic\":\"orderbook.1000.XRPUSDT\",\"type\":\"delta\",\"ts\":1778927754703,\"data\":{\"s\":\"XRPUSDT\",\"b\":[[\"1.4043\",\"36700.1\"],[\"1.4042\",\"34490.3\"],[\"1.4036\",\"38564.8\"],[\"1.4035\",\"40153.5\"],[\"1.4021\",\"36928.8\"],[\"1.4016\",\"73153.2\"],[\"1.4009\",\"54741.3\"],[\"1.3941\",\"2092.1\"]],\"a\":[[\"1.4044\",\"8003.7\"],[\"1.4048\",\"79754.9\"],[\"1.4049\",\"80411.4\"],[\"1.4054\",\"69691.0\"],[\"1.4070\",\"335513.4\"],[\"1.4077\",\"49253.3\"],[\"1.4272\",\"8137.4\"]],\"u\":9831559,\"seq\":241267348960},\"cts\":1778927754701}"}
{"ts":1778927755027,"data":"{\"topic\":\"orderbook.1000.XRPUSDT\",\"type\":\"delta\",\"ts\":1778927754903,\"data\":{\"s\":\"XRPUSDT\",\"b\":[[\"1.4043\",\"36649.7\"],[\"1.4041\",\"59066.2\"],[\"1.4040\",\"42782.0\"],[\"1.4039\",\"42804.7\"],[\"1.4029\",\"40995.7\"],[\"1.4025\",\"41437.3\"],[\"1.4021\",\"36932.4\"],[\"1.4013\",\"157257.9\"],[\"1.4012\",\"239764.6\"]],\"a\":[[\"1.4044\",\"8101.4\"],[\"1.4049\",\"86819.2\"],[\"1.4050\",\"82025.1\"],[\"1.4051\",\"74183.6\"],[\"1.4054\",\"64734.4\"],[\"1.4055\",\"60697.2\"],[\"1.4061\",\"47075.1\"],[\"1.4070\",\"335063.9\"],[\"1.4080\",\"63643.3\"],[\"1.4081\",\"50649.1\"]],\"u\":9831560,\"seq\":241267349133},\"cts\":1778927754896}"}
{"ts":1778927755227,"data":"{\"topic\":\"orderbook.1000.XRPUSDT\",\"type\":\"delta\",\"ts\":1778927755103,\"data\":{\"s\":\"XRPUSDT\",\"b\":[[\"1.4021\",\"36936.0\"],[\"1.4011\",\"257516.9\"],[\"1.3989\",\"37780.6\"],[\"1.3988\",\"34829.4\"],[\"1.3976\",\"28061.8\"],[\"1.3975\",\"62835.7\"]],\"a\":[[\"1.4045\",\"34722.0\"],[\"1.4049\",\"80411.4\"],[\"1.4050\",\"88432.9\"],[\"1.4051\",\"72990.2\"],[\"1.4052\",\"70963.8\"],[\"1.4053\",\"59438.2\"],[\"1.4061\",\"75565.6\"],[\"1.4062\",\"73029.6\"],[\"1.4091\",\"260863.7\"],[\"1.4092\",\"62480.5\"]],\"u\":9831561,\"seq\":241267349202},\"cts\":1778927755094}"}
{"ts":1778927755428,"data":"{\"topic\":\"orderbook.1000.XRPUSDT\",\"type\":\"delta\",\"ts\":1778927755303,\"data\":{\"s\":\"XRPUSDT\",\"b\":[[\"1.4029\",\"40995.8\"],[\"1.4021\",\"36939.6\"],[\"1.3880\",\"8481.0\"],[\"1.3864\",\"3580.1\"],[\"1.3863\",\"7917.7\"],[\"1.3845\",\"15903.1\"],[\"1.3789\",\"9340.6\"]],\"a\":[[\"1.4044\",\"7718.7\"],[\"1.4051\",\"72990.3\"],[\"1.4052\",\"67404.1\"],[\"1.4053\",\"62997.8\"],[\"1.4091\",\"260868.2\"],[\"1.4092\",\"62476.0\"],[\"1.4126\",\"21926.7\"],[\"1.4215\",\"2866.8\"],[\"1.4251\",\"42063.4\"],[\"1.4252\",\"23527.3\"],[\"1.4253\",\"713.6\"],[\"1.4286\",\"8255.9\"]],\"u\":9831562,\"seq\":241267349309},\"cts\":1778927755301}"}
{"ts":1778927755627,"data":"{\"topic\":\"orderbook.1000.XRPUSDT\",\"type\":\"delta\",\"ts\":1778927755503,\"data\":{\"s\":\"XRPUSDT\",\"b\":[[\"1.4042\",\"49205.6\"],[\"1.4040\",\"44655.6\"],[\"1.4036\",\"38921.0\"],[\"1.4035\",\"39797.3\"],[\"1.4026\",\"56396.0\"],[\"1.4025\",\"46499.3\"],[\"1.4021\",\"36928.8\"],[\"1.3976\",\"28065.4\"],[\"1.3975\",\"62832.1\"],[\"1.3884\",\"1835.3\"],[\"1.3866\",\"20398.3\"]],\"a\":[[\"1.4044\",\"7726.2\"],[\"1.4049\",\"86819.4\"],[\"1.4050\",\"82025.1\"],[\"1.4077\",\"55499.9\"],[\"1.4126\",\"8035.5\"],[\"1.4236\",\"1370.4\"],[\"1.4261\",\"473.9\"],[\"1.4290\",\"6014.7\"]],\"u\":9831563,\"seq\":241267349399},\"cts\":1778927755502}"}
{"ts":1778927755827,"data":"{\"topic\":\"orderbook.1000.XRPUSDT\",\"type\":\"delta\",\"ts\":1778927755703,\"data\":{\"s\":\"XRPUSDT\",\"b\":[[\"1.4043\",\"43249.7\"],[\"1.4026\",\"61458.8\"],[\"1.4025\",\"41437.3\"],[\"1.4021\",\"36932.4\"],[\"1.3989\",\"37784.2\"],[\"1.3988\",\"34825.8\"],[\"1.3985\",\"41126.6\"]],\"a\":[[\"1.4044\",\"7718.0\"],[\"1.4049\",\"80411.4\"],[\"1.4050\",\"88432.9\"],[\"1.4061\",\"47075.1\"],[\"1.4062\",\"101520.1\"]],\"u\":9831564,\"seq\":241267349540},\"cts\":1778927755700}"}
{"ts":1778927756030,"data":"{\"topic\":\"orderbook.1000.XRPUSDT\",\"type\":\"delta\",\"ts\":1778927755903,\"data\":{\"s\":\"XRPUSDT\",\"b\":[[\"1.4041\",\"59058.4\"],[\"1.4029\",\"40995.9\"]],\"a\":[[\"1.4044\",\"7723.5\"],[\"1.4051\",\"72990.4\"],[\"1.4061\",\"75565.6\"],[\"1.4062\",\"73029.6\"],[\"1.4309\",\"8771.2\"]],\"u\":9831565,\"seq\":241267349756},\"cts\":1778927755886}"}
{"ts":1778927756227,"data":"{\"topic\":\"orderbook.1000.XRPUSDT\",\"type\":\"delta\",\"ts\":1778927756103,\"data\":{\"s\":\"XRPUSDT\",\"b\":[[\"1.4043\",\"36644.4\"],[\"1.4042\",\"34490.3\"],[\"1.4040\",\"42782.0\"],[\"1.4036\",\"38564.8\"],[\"1.4035\",\"40153.5\"],[\"1.4026\",\"56396.0\"],[\"1.4025\",\"46499.3\"],[\"1.3999\",\"21825.0\"],[\"1.3819\",\"901.0\"],[\"1.3818\",\"907.3\"]],\"a\":[[\"1.4044\",\"13765.4\"],[\"1.4049\",\"86819.4\"],[\"1.4050\",\"82025.1\"],[\"1.4054\",\"61174.0\"],[\"1.4077\",\"49253.3\"],[\"1.4267\",\"26054.2\"],[\"1.4268\",\"604.5\"]],\"u\":9831566,\"seq\":241267350034},\"cts\":1778927756091}"}
{"ts":1778927756431,"data":"{\"topic\":\"orderbook.1000.XRPUSDT\",\"type\":\"delta\",\"ts\":1778927756303,\"data\":{\"s\":\"XRPUSDT\",\"b\":[[\"1.4026\",\"54899.4\"],[\"1.4025\",\"47897.8\"],[\"1.3999\",\"21821.4\"],[\"1.3901\",\"3005.8\"],[\"1.3899\",\"5990.0\"],[\"1.3875\",\"265337.4\"]],\"a\":[[\"1.4044\",\"13709.6\"],[\"1.4052\",\"70963.8\"],[\"1.4053\",\"59438.2\"],[\"1.4054\",\"70526.7\"],[\"1.4217\",\"9047.5\"],[\"1.4231\",\"100.4\"],[\"1.4239\",\"1173.9\"]],\"u\":9831567,\"seq\":241267350254},\"cts\":1778927756292}"}
{"ts":1778927756627,"data":"{\"topic\":\"orderbook.1000.XRPUSDT\",\"type\":\"delta\",\"ts\":1778927756504,\"data\":{\"s\":\"XRPUSDT\",\"b\":[[\"1.4043\",\"36648.6\"],[\"1.3989\",\"37780.6\"],[\"1.3988\",\"34829.4\"],[\"1.3976\",\"28061.8\"],[\"1.3975\",\"62835.7\"],[\"1.3759\",\"48424.5\"]],\"a\":[[\"1.4115\",\"77468.9\"],[\"1.4117\",\"27638.6\"]],\"u\":9831568,\"seq\":241267350337},\"cts\":1778927756496}"}
{"ts":1778927756827,"data":"{\"topic\":\"orderbook.1000.XRPUSDT\",\"type\":\"delta\",\"ts\":1778927756703,\"data\":{\"s\":\"XRPUSDT\",\"b\":[[\"1.4042\",\"49203.3\"],[\"1.4021\",\"36936.0\"],[\"1.3965\",\"27526.2\"]],\"a\":[[\"1.4044\",\"9949.0\"],[\"1.4054\",\"61174.0\"],[\"1.4060\",\"66758.8\"],[\"1.4115\",\"53681.4\"],[\"1.4116\",\"50744.1\"]],\"u\":9831569,\"seq\":241267350425},\"cts\":1778927756702}"}
{"ts":1778927757027,"data":"{\"topic\":\"orderbook.1000.XRPUSDT\",\"type\":\"delta\",\"ts\":1778927756903,\"data\":{\"s\":\"XRPUSDT\",\"b\":[[\"1.4042\",\"34490.3\"],[\"1.4041\",\"59040.3\"],[\"1.4040\",\"42780.4\"],[\"1.4039\",\"42829.0\"],[\"1.4029\",\"40996.0\"],[\"1.4026\",\"56299.1\"],[\"1.4025\",\"46499.3\"],[\"1.3965\",\"51313.7\"]],\"a\":[[\"1.4044\",\"9948.9\"],[\"1.4051\",\"72990.5\"],[\"1.4054\",\"64734.4\"],[\"1.4231\",\"110.4\"]],\"u\":9831570,\"seq\":241267350541},\"cts\":1778927756902}"}
{"ts":1778927757228,"data":"{\"topic\":\"orderbook.1000.XRPUSDT\",\"type\":\"delta\",\"ts\":1778927757104,\"data\":{\"s\":\"XRPUSDT\",\"b\":[[\"1.4043\",\"36659.2\"],[\"1.4042\",\"49197.9\"],[\"1.4040\",\"44561.0\"],[\"1.4027\",\"32954.5\"],[\"1.4026\",\"54899.4\"],[\"1.4025\",\"47897.8\"],[\"1.4013\",\"80834.0\"],[\"1.4009\",\"48132.5\"]],\"a\":[[\"1.4044\",\"7698.9\"],[\"1.4073\",\"57215.1\"],[\"1.4077\",\"55240.0\"],[\"1.4106\",\"31033.1\"],[\"1.4194\",\"110.2\"]],\"u\":9831571,\"seq\":241267350662},\"cts\":1778927757095}"}
{"ts":1778927757427,"data":"{\"topic\":\"orderbook.1000.XRPUSDT\",\"type\":\"delta\",\"ts\":1778927757303,\"data\":{\"s\":\"XRPUSDT\",\"b\":[[\"1.4043\",\"36653.4\"],[\"1.4040\",\"46293.3\"],[\"1.4033\",\"41800.7\"],[\"1.4026\",\"61346.2\"],[\"1.4025\",\"41437.3\"],[\"1.4015\",\"109872.6\"],[\"1.4014\",\"267460.1\"],[\"1.4011\",\"257513.3\"],[\"1.4010\",\"80910.1\"],[\"1.4009\",\"56512.9\"],[\"1.4001\",\"163682.6\"],[\"1.4000\",\"285520.7\"],[\"1.3988\",\"34825.8\"],[\"1.3986\",\"28040.3\"],[\"1.3979\",\"421795.8\"],[\"1.3978\",\"413006.3\"],[\"1.3975\",\"62832.1\"],[\"1.3973\",\"34867.7\"],[\"1.3850\",\"130009.2\"],[\"1.3829\",\"7459.1\"]],\"a\":[[\"1.4044\",\"19490.4\"],[\"1.4049\",\"80411.4\"],[\"1.4050\",\"88432.9\"],[\"1.4054\",\"72659.8\"],[\"1.4056\",\"59658.0\"],[\"1.4072\",\"99187.5\"],[\"1.4073\",\"131770.9\"],[\"1.4077\",\"49253.3\"],[\"1.4085\",\"38108.0\"],[\"1.4086\",\"210581.0\"],[\"1.4091\",\"260863.7\"],[\"1.4092\",\"62480.5\"],[\"1.4106\",\"31040.2\"],[\"1.4108\",\"496947.5\"],[\"1.4218\",\"7954.9\"],[\"1.4220\",\"12171.1\"],[\"1.4251\",\"42400.2\"],[\"1.4273\",\"28127.9\"]],\"u\":9831572,\"seq\":241267350823},\"cts\":1778927757291}"}
{"ts":1778927757628,"data":"{\"topic\":\"orderbook.1000.XRPUSDT\",\"type\":\"delta\",\"ts\":1778927757503,\"data\":{\"s\":\"XRPUSDT\",\"b\":[[\"1.4040\",\"43277.3\"],[\"1.4036\",\"38921.0\"],[\"1.4035\",\"39797.3\"],[\"1.4033\",\"52623.6\"],[\"1.4026\",\"56283.3\"],[\"1.4025\",\"46499.3\"],[\"1.4011\",\"257516.9\"],[\"1.4010\",\"80906.5\"],[\"1.4009\",\"53925.7\"],[\"1.3988\",\"34829.4\"],[\"1.3986\",\"28036.7\"],[\"1.3975\",\"62835.7\"],[\"1.3973\",\"34864.1\"],[\"1.3850\",\"130334.1\"],[\"1.3829\",\"7133.7\"]],\"a\":[[\"1.4044\",\"8748.9\"],[\"1.4048\",\"79755.3\"],[\"1.4049\",\"86819.4\"],[\"1.4050\",\"82025.1\"],[\"1.4054\",\"61174.0\"],[\"1.4077\",\"55346.8\"],[\"1.4091\",\"260868.2\"],[\"1.4092\",\"62476.0\"],[\"1.4206\",\"1140.1\"],[\"1.4208\",\"212.0\"],[\"1.4217\",\"9389.4\"],[\"1.4218\",\"7613.1\"],[\"1.4251\",\"42715.9\"],[\"1.4274\",\"371.6\"]],\"u\":9831573,\"seq\":241267350983},\"cts\":1778927757494}"}
{"ts":1778927757827,"data":"{\"topic\":\"orderbook.1000.XRPUSDT\",\"type\":\"delta\",\"ts\":1778927757703,\"data\":{\"s\":\"XRPUSDT\",\"b\":[[\"1.4043\",\"41453.4\"],[\"1.4033\",\"52298.5\"],[\"1.4026\",\"56283.4\"],[\"1.3976\",\"28065.4\"],[\"1.3975\",\"62832.1\"]],\"a\":[[\"1.4044\",\"13233.6\"],[\"1.4045\",\"34650.8\"],[\"1.4054\",\"64734.4\"],[\"1.4055\",\"60701.7\"],[\"1.4056\",\"59653.5\"],[\"1.4077\",\"54697.1\"],[\"1.4194\",\"125.2\"]],\"u\":9831574,\"seq\":241267351100},\"cts\":1778927757702}"}
{"ts":1778927758027,"data":"{\"topic\":\"orderbook.1000.XRPUSDT\",\"type\":\"delta\",\"ts\":1778927757903,\"data\":{\"s\":\"XRPUSDT\",\"b\":[[\"1.4043\",\"41455.1\"],[\"1.4040\",\"43279.4\"],[\"1.4029\",\"40830.7\"],[\"1.4026\",\"56283.2\"],[\"1.4025\",\"46664.6\"],[\"1.3976\",\"28061.8\"],[\"1.3975\",\"62835.7\"]],\"a\":[[\"1.4045\",\"34722.0\"],[\"1.4055\",\"60697.2\"],[\"1.4056\",\"59658.0\"],[\"1.4079\",\"66142.8\"],[\"1.4080\",\"39855.8\"],[\"1.4114\",\"59304.5\"],[\"1.4116\",\"26956.6\"],[\"1.4371\",\"2378.5\"],[\"1.4545\",\"186.2\"]],\"u\":9831575,\"seq\":241267351215},\"cts\":1778927757900}"}
{"ts":1778927758227,"data":"{\"topic\":\"orderbook.1000.XRPUSDT\",\"type\":\"delta\",\"ts\":1778927758103,\"data\":{\"s\":\"XRPUSDT\",\"b\":[[\"1.4043\",\"41446.3\"],[\"1.4040\",\"43137.0\"],[\"1.4029\",\"40996.0\"],[\"1.4026\",\"56268.0\"],[\"1.4025\",\"46499.3\"],[\"1.3989\",\"37784.2\"],[\"1.3988\",\"34825.8\"],[\"1.3976\",\"28065.4\"],[\"1.3975\",\"62832.1\"]],\"a\":[[\"1.4050\",\"81313.2\"],[\"1.4051\",\"73702.4\"],[\"1.4079\",\"42355.3\"],[\"1.4080\",\"63643.3\"],[\"1.4114\",\"35517.0\"],[\"1.4116\",\"50744.1\"]],\"u\":9831576,\"seq\":241267351350},\"cts\":1778927758087}"}
{"ts":1778927758428,"data":"{\"topic\":\"orderbook.1000.XRPUSDT\",\"type\":\"delta\",\"ts\":1778927758304,\"data\":{\"s\":\"XRPUSDT\",\"b\":[[\"1.4043\",\"36641.1\"],[\"1.4040\",\"43279.4\"],[\"1.4033\",\"41800.7\"],[\"1.4009\",\"53390.0\"]],\"a\":[[\"1.4044\",\"23908.2\"],[\"1.4046\",\"61901.1\"],[\"1.4054\",\"71807.7\"],[\"1.4060\",\"58694.0\"],[\"1.4061\",\"58261.9\"],[\"1.4062\",\"101520.1\"],[\"1.4071\",\"71204.8\"],[\"1.4072\",\"99192.0\"],[\"1.4077\",\"49253.3\"]],\"u\":9831577,\"seq\":241267351484},\"cts\":1778927758300}"}
{"ts":1778927758627,"data":"{\"topic\":\"orderbook.1000.XRPUSDT\",\"type\":\"delta\",\"ts\":1778927758503,\"data\":{\"s\":\"XRPUSDT\",\"b\":[[\"1.4040\",\"43137.0\"],[\"1.4029\",\"40996.1\"],[\"1.4026\",\"54899.4\"],[\"1.4025\",\"47866.6\"],[\"1.3989\",\"37780.6\"],[\"1.3988\",\"34829.4\"],[\"1.3976\",\"28061.8\"],[\"1.3975\",\"62835.7\"]],\"a\":[[\"1.4050\",\"82025.1\"],[\"1.4051\",\"72990.6\"],[\"1.4054\",\"68247.3\"],[\"1.4055\",\"60701.7\"],[\"1.4056\",\"59653.5\"],[\"1.4061\",\"75565.6\"],[\"1.4062\",\"73029.6\"],[\"1.4071\",\"71209.3\"],[\"1.4072\",\"99187.5\"],[\"1.4091\",\"260863.7\"],[\"1.4092\",\"62480.5\"]],\"u\":9831578,\"seq\":241267351610},\"cts\":1778927758493}"}
{"ts":1778927758827,"data":"{\"topic\":\"orderbook.1000.XRPUSDT\",\"type\":\"delta\",\"ts\":1778927758703,\"data\":{\"s\":\"XRPUSDT\",\"b\":[[\"1.4040\",\"43279.4\"],[\"1.4033\",\"48519.9\"],[\"1.4026\",\"61329.8\"],[\"1.4025\",\"41437.3\"],[\"1.3753\",\"558.5\"]],\"a\":[[\"1.4044\",\"10908.2\"],[\"1.4054\",\"64734.4\"],[\"1.4055\",\"60697.2\"],[\"1.4056\",\"59658.0\"],[\"1.4077\",\"56590.4\"],[\"1.4091\",\"260868.2\"],[\"1.4092\",\"62476.0\"]],\"u\":9831579,\"seq\":241267351685},\"cts\":1778927758695}"}
{"ts":1778927759027,"data":"{\"topic\":\"orderbook.1000.XRPUSDT\",\"type\":\"delta\",\"ts\":1778927758903,\"data\":{\"s\":\"XRPUSDT\",\"b\":[[\"1.4040\",\"43284.1\"],[\"1.3976\",\"28065.4\"],[\"1.3975\",\"62832.1\"]],\"a\":[[\"1.4044\",\"23861.0\"],[\"1.4054\",\"66876.1\"],[\"1.4077\",\"49253.3\"]],\"u\":9831580,\"seq\":241267351758},\"cts\":1778927758899}"}
{"ts":1778927759227,"data":"{\"topic\":\"orderbook.1000.XRPUSDT\",\"type\":\"delta\",\"ts\":1778927759103,\"data\":{\"s\":\"XRPUSDT\",\"b\":[[\"1.4040\",\"43141.7\"],[\"1.4026\",\"54899.4\"],[\"1.4025\",\"47866.2\"]],\"a\":[[\"1.4054\",\"70436.5\"],[\"1.4055\",\"60701.7\"],[\"1.4056\",\"59653.5\"],[\"1.4063\",\"178382.7\"],[\"1.4071\",\"65234.8\"],[\"1.4072\",\"71849.2\"],[\"1.4200\",\"22088.1\"]],\"u\":9831581,\"seq\":241267351809},\"cts\":1778927759101}"}
{"ts":1778927759427,"data":"{\"topic\":\"orderbook.1000.XRPUSDT\",\"type\":\"delta\",\"ts\":1778927759303,\"data\":{\"s\":\"XRPUSDT\",\"b\":[[\"1.4042\",\"34490.3\"],[\"1.4026\",\"61314.0\"],[\"1.4025\",\"41437.3\"]],\"a\":[[\"1.4044\",\"23864.8\"],[\"1.4079\",\"66142.8\"],[\"1.4080\",\"39855.8\"],[\"1.4113\",\"62084.6\"],[\"1.4116\",\"26956.6\"]],\"u\":9831582,\"seq\":241267351974},\"cts\":1778927759288}"}
{"ts":1778927759628,"data":"{\"topic\":\"orderbook.1000.XRPUSDT\",\"type\":\"delta\",\"ts\":1778927759504,\"data\":{\"s\":\"XRPUSDT\",\"b\":[[\"1.4042\",\"49197.9\"],[\"1.4026\",\"56251.7\"],[\"1.4025\",\"46499.3\"],[\"1.4021\",\"36939.6\"],[\"1.3976\",\"28061.8\"],[\"1.3975\",\"62835.7\"]],\"a\":[],\"u\":9831583,\"seq\":241267352150},\"cts\":1778927759491}"}
{"ts":1778927759827,"data":"{\"topic\":\"orderbook.1000.XRPUSDT\",\"type\":\"delta\",\"ts\":1778927759703,\"data\":{\"s\":\"XRPUSDT\",\"b\":[[\"1.4043\",\"36781.3\"],[\"1.4026\",\"61314.0\"],[\"1.4025\",\"41437.3\"],[\"1.4021\",\"36928.8\"],[\"1.3977\",\"418128.9\"],[\"1.3976\",\"28065.4\"],[\"1.3975\",\"62832.1\"]],\"a\":[[\"1.4068\",\"79527.0\"],[\"1.4126\",\"18466.3\"]],\"u\":9831584,\"seq\":241267352240},\"cts\":1778927759699}"}
{"ts":1778927760028,"data":"{\"topic\":\"orderbook.1000.XRPUSDT\",\"type\":\"delta\",\"ts\":1778927759903,\"data\":{\"s\":\"XRPUSDT\",\"b\":[[\"1.4043\",\"36776.0\"],[\"1.4042\",\"34490.3\"],[\"1.4040\",\"43128.3\"],[\"1.4036\",\"38564.8\"],[\"1.4035\",\"40153.5\"],[\"1.4033\",\"41800.7\"],[\"1.4029\",\"40830.7\"],[\"1.4028\",\"48921.0\"],[\"1.4026\",\"59961.7\"],[\"1.4025\",\"42788.7\"],[\"1.4021\",\"36932.4\"],[\"1.4017\",\"48800.2\"],[\"1.4009\",\"58553.4\"]],\"a\":[[\"1.4062\",\"90271.5\"],[\"1.4069\",\"110124.2\"],[\"1.4070\",\"336422.3\"]],\"u\":9831585,\"seq\":241267352629},\"cts\":1778927759900}"}
{"ts":1778927760228,"data":"{\"topic\":\"orderbook.1000.XRPUSDT\",\"type\":\"delta\",\"ts\":1778927760104,\"data\":{\"s\":\"XRPUSDT\",\"b\":[[\"1.4043\",\"36751.2\"],[\"1.4033\",\"49136.6\"],[\"1.4029\",\"40996.1\"],[\"1.4026\",\"54895.8\"],[\"1.4025\",\"47854.3\"],[\"1.4021\",\"36936.0\"],[\"1.3976\",\"28061.8\"],[\"1.3975\",\"62835.7\"],[\"1.3843\",\"23746.1\"]],\"a\":[[\"1.4060\",\"58764.9\"],[\"1.4126\",\"17610.7\"]],\"u\":9831586,\"seq\":241267353135},\"cts\":1778927760101}"}
